Workbook

Sheet # log2(N) 및 결과 정리
A1: 노드수 | B1: log2(N) | L1: 노드수(N) | M1: 전체 Hop 수 | N1: 평균 Hop 수 | P1: 최대 Hop 수 | Q1: log2(N)
A2: 4 | B2: =LOG(A2,2) -> 2 | L2: 4 | Q2: =VLOOKUP(L2,$A$2:$B$15,2,TRUE) -> 2
A3: 6 | B3: =LOG(A3,2) -> 2.5849625 | C3: =B3-B2 -> 0.5849625 | D3: =C3/(A3-A2) -> 0.29248125 | L3: 6 | Q3: =VLOOKUP(L3,$A$2:$B$15,2,TRUE) -> 2.5849625
A4: 8 | B4: =LOG(A4,2) -> 3 | C4: =B4-B3 -> 0.4150375 | D4: =C4/(A4-A3) -> 0.20751875 | L4: 8 | M4: 140 | N4: =M4/49 -> 2.8571429 | Q4: =VLOOKUP(L4,$A$2:$B$15,2,TRUE) -> 3
A5: 10 | B5: =LOG(A5,2) -> 3.3219281 | C5: =B5-B4 -> 0.32192809 | D5: =C5/(A5-A4) -> 0.16096405 | L5: 10 | Q5: =VLOOKUP(L5,$A$2:$B$15,2,TRUE) -> 3.3219281
A6: 16 | B6: =LOG(A6,2) -> 4 | C6: =B6-B5 -> 0.67807191 | D6: =C6/(A6-A5) -> 0.11301198 | L6: 12 | Q6: =VLOOKUP(L6,$A$2:$B$15,2,TRUE) -> 3.3219281
A7: 20 | B7: =LOG(A7,2) -> 4.3219281 | C7: =B7-B6 -> 0.32192809 | D7: =C7/(A7-A6) -> 0.080482024 | L7: 14 | Q7: =VLOOKUP(L7,$A$2:$B$15,2,TRUE) -> 3.3219281
A8: 32 | B8: =LOG(A8,2) -> 5 | C8: =B8-B7 -> 0.67807191 | D8: =C8/(A8-A7) -> 0.056505992 | L8: 16 | Q8: =VLOOKUP(L8,$A$2:$B$15,2,TRUE) -> 4
A9: 40 | B9: =LOG(A9,2) -> 5.3219281 | C9: =B9-B8 -> 0.32192809 | D9: =C9/(A9-A8) -> 0.040241012 | L9: 32 | Q9: =VLOOKUP(L9,$A$2:$B$15,2,TRUE) -> 5
A10: 48 | B10: =LOG(A10,2) -> 5.5849625 | C10: =B10-B9 -> 0.26303441 | D10: =C10/(A10-A9) -> 0.032879301
A11: 56 | B11: =LOG(A11,2) -> 5.8073549 | C11: =B11-B10 -> 0.22239242 | D11: =C11/(A11-A10) -> 0.027799053
A12: 64 | B12: =LOG(A12,2) -> 6 | C12: =B12-B11 -> 0.19264508 | D12: =C12/(A12-A11) -> 0.024080635
A13: 72 | B13: =LOG(A13,2) -> 6.169925 | C13: =B13-B12 -> 0.169925 | D13: =C13/(A13-A12) -> 0.021240625
A14: 80 | B14: =LOG(A14,2) -> 6.3219281 | C14: =B14-B13 -> 0.15200309 | D14: =C14/(A14-A13) -> 0.019000387
A15: 90 | B15: =LOG(A15,2) -> 6.4918531 | C15: =B15-B14 -> 0.169925 | D15: =C15/(A15-A14) -> 0.0169925
A16: 100 | B16: =LOG(A16,2) -> 6.6438562 | C16: =B16-B15 -> 0.15200309 | D16: =C16/(A16-A15) -> 0.015200309 | E16: 노드수 | F16: log2(N)
A17: 110 | B17: =LOG(A17,2) -> 6.7813597 | C17: =B17-B16 -> 0.13750352 | D17: =C17/(A17-A16) -> 0.013750352 | E17: 4 | F17: =LOG(E17,2) -> 2
A18: 128 | B18: =LOG(A18,2) -> 7 | C18: =B18-B17 -> 0.21864029 | D18: =C18/(A18-A17) -> 0.012146683 | E18: 6 | F18: =LOG(E18,2) -> 2.5849625
E19: 6 | F19: =LOG(E19,2) -> 2.5849625
E20: 7 | F20: =LOG(E20,2) -> 2.8073549
E21: 8 | F21: =LOG(E21,2) -> 3
E22: 9 | F22: =LOG(E22,2) -> 3.169925
E23: 10 | F23: =LOG(E23,2) -> 3.3219281
E24: 11 | F24: =LOG(E24,2) -> 3.4594316
E25: 12 | F25: =LOG(E25,2) -> 3.5849625
E26: 13 | F26: =LOG(E26,2) -> 3.7004397
E27: 14 | F27: =LOG(E27,2) -> 3.8073549
E28: 15 | F28: =LOG(E28,2) -> 3.9068906
E29: 16 | F29: =LOG(E29,2) -> 4
E30: 17 | F30: =LOG(E30,2) -> 4.0874628
... E144: 131 | F144: =LOG(E144,2) -> 7.033423

Sheet # Sheet1
L9: 2 | M9: 4 | N9: 6 | O9: 8 | P9: 10 | Q9: 12 | R9: 14
L10: =2^L9 -> 4 | M10: =2^M9 -> 16 | N10: =2^N9 -> 64 | O10: =2^O9 -> 256 | P10: =2^P9 -> 1024 | Q10: =2^Q9 -> 4096 | R10: =2^R9 -> 16384
B17: 노드 수 (N) | C17: 평균 Hop 수 | D17: 최대 Hop 수 | E17: log2(N)
B18: 128 | C18: 7.14 | D18: 9.5 | E18: 7
B19: 256 | C19: 8.69 | D19: 12.75 | E19: 8
B20: 512 | C20: 9.37 | D20: 13.95 | E20: 9
B21: 1024 | C21: 10.18 | D21: 13.39 | E21: 10
B22: 2048 | C22: 10.66 | D22: 15.33 | E22: 11
B23: 4096 | C23: 12.7 | D23: 17.26 | E23: 12

Sheet 1. FingerTable(기본)
B1: (127.0.0.1:6000) ID: 876 | G1: (127.0.0.1 : 6001) ID: 481 | L1: (127.0.0.1 : 6002) ID: 621 | Q1: (127.0.0.1 : 6003) ID: 906 | V1: (127.0.0.1 : 6004) ID: 60
B2: Node | C2: Finger(k) | D2: Start | E2: Succ | G2: Node | H2: Finger(k) | I2: Start | J2: Succ | L2: Node | M2: Finger(k) | N2: Start | O2: Succ | Q2: Node | R2: Finger(k) | S2: Start | T2: Succ | V2: Node | W2: Finger(k) | X2: Start | Y2: Succ
B3: 876 | C3: 1 | D3: 877 | E3: 906 | G3: 481 | H3: 1 | I3: 482 | J3: 621 | L3: 621 | M3: 1 | N3: 622 | O3: 772 | Q3: 906 | R3: 1 | S3: 907 | T3: 60 | V3: 60 | W3: 1 | X3: 61 | Y3: 112
C4: 2 | D4: 878 | E4: 906 | H4: 2 | I4: 483 | J4: 621 | M4: 2 | N4: 623 | O4: 772 | R4: 2 | S4: 908 | T4: 60 | W4: 2 | X4: 62 | Y4: 112
C5: 3 | D5: 880 | E5: 906 | H5: 3 | I5: 485 | J5: 621 | M5: 3 | N5: 625 | O5: 772 | R5: 3 | S5: 910 | T5: 60 | W5: 3 | X5: 64 | Y5: 112
C6: 4 | D6: 884 | E6: 906 | H6: 4 | I6: 489 | J6: 621 | M6: 4 | N6: 629 | O6: 772 | R6: 4 | S6: 914 | T6: 60 | W6: 4 | X6: 68 | Y6: 112
C7: 5 | D7: 892 | E7: 906 | H7: 5 | I7: 497 | J7: 621 | M7: 5 | N7: 637 | O7: 772 | R7: 5 | S7: 922 | T7: 60 | W7: 5 | X7: 76 | Y7: 112
C8: 6 | D8: 908 | E8: 60 | H8: 6 | I8: 513 | J8: 621 | M8: 6 | N8: 653 | O8: 772 | R8: 6 | S8: 938 | T8: 60 | W8: 6 | X8: 92 | Y8: 112
C9: 7 | D9: 940 | E9: 60 | H9: 7 | I9: 545 | J9: 621 | M9: 7 | N9: 685 | O9: 772 | R9: 7 | S9: 970 | T9: 60 | W9: 7 | X9: 124 | Y9: 377
C10: 8 | D10: 1004 | E10: 60 | H10: 8 | I10: 609 | J10: 621 | M10: 8 | N10: 749 | O10: 772 | R10: 8 | S10: 10* | T10: 60 | W10: 8 | X10: 188 | Y10: 377
C11: 9 | D11: 108* | E11: 112 | H11: 9 | I11: 737 | J11: 772 | M11: 9 | N11: 877 | O11: 906 | R11: 9 | S11: 138* | T11: 377 | W11: 9 | X11: 316 | Y11: 377
C12: 10 | D12: 364* | E12: 377 | H12: 10 | I12: 993 | J12: 60 | M12: 10 | N12: 109* | O12: 112 | R12: 10 | S12: 394* | T12: 477 | W12: 10 | X12: 572 | Y12: 621
B14: (127.0.0.1 : 6005) ID: 112 | G14: (127.0.0.1 : 6006) ID: 477 | L14: (127.0.0.1 : 6007) ID: 377 | Q14: (127.0.0.1 : 6008) ID: 864 | V14: 127.0.0.1 : 6009) ID: 772
B15: Node | C15: Finger(k) | D15: Start | E15: Succ | G15: Node | H15: Finger(k) | I15: Start | J15: Succ | L15: Node | M15: Finger(k) | N15: Start | O15: Succ | Q15: Node | R15: Finger(k) | S15: Start | T15: Succ | V15: Node | W15: Finger(k) | X15: Start | Y15: Succ
B16: 112 | C16: 1 | D16: 113 | E16: 377 | G16: 477 | H16: 1 | I16: 478 | J16: 481 | L16: 377 | M16: 1 | N16: 378 | O16: 477 | Q16: 864 | R16: 1 | S16: 865 | T16: 876 | V16: 772 | W16: 1 | X16: 773 | Y16: 864
C17: 2 | D17: 114 | E17: 377 | H17: 2 | I17: 479 | J17: 481 | M17: 2 | N17: 379 | O17: 477 | R17: 2 | S17: 866 | T17: 876 | W17: 2 | X17: 774 | Y17: 864
C18: 3 | D18: 116 | E18: 377 | H18: 3 | I18: 481 | J18: 481 | M18: 3 | N18: 381 | O18: 477 | R18: 3 | S18: 868 | T18: 876 | W18: 3 | X18: 776 | Y18: 864
C19: 4 | D19: 120 | E19: 377 | H19: 4 | I19: 485 | J19: 621 | M19: 4 | N19: 385 | O19: 477 | R19: 4 | S19: 872 | T19: 876 | W19: 4 | X19: 780 | Y19: 864
C20: 5 | D20: 128 | E20: 377 | H20: 5 | I20: 493 | J20: 621 | M20: 5 | N20: 393 | O20: 477 | R20: 5 | S20: 880 | T20: 906 | W20: 5 | X20: 788 | Y20: 864
C21: 6 | D21: 144 | E21: 377 | H21: 6 | I21: 509 | J21: 621 | M21: 6 | N21: 409 | O21: 477 | R21: 6 | S21: 896 | T21: 906 | W21: 6 | X21: 804 | Y21: 864
C22: 7 | D22: 176 | E22: 377 | H22: 7 | I22: 541 | J22: 621 | M22: 7 | N22: 441 | O22: 477 | R22: 7 | S22: 928 | T22: 60 | W22: 7 | X22: 836 | Y22: 864
C23: 8 | D23: 240 | E23: 377 | H23: 8 | I23: 605 | J23: 621 | M23: 8 | N23: 505 | O23: 621 | R23: 8 | S23: 992 | T23: 60 | W23: 8 | X23: 900 | Y23: 906
C24: 9 | D24: 368 | E24: 377 | H24: 9 | I24: 733 | J24: 772 | M24: 9 | N24: 633 | O24: 772 | R24: 9 | S24: 96* | T24: 112 | W24: 9 | X24: 4* | Y24: 60
C25: 10 | D25: 624 | E25: 772 | H25: 10 | I25: 989 | J25: 60 | M25: 10 | N25: 889 | O25: 906 | R25: 10 | S25: 352* | T25: 377 | W25: 10 | X25: 260* | Y25: 377

Sheet 2. 기본(4~128)
B1: 251110_SEQ_RESULT_1차테스트
B2: 노드수(N) | C2: 전체 Hop 수 | D2: 평균 Hop 수 | E2: 최대 Hop 수 | F2: log2(N) | G2: 증가 | H2: log2(N)/2
B3: =COUNTA('260110_SEQ_RESULT_1차테스트'!A3:A6) -> 4 | C3: =SUM('260110_SEQ_RESULT_1차테스트'!A3:A6) -> 9 | D3: =C3/B3 -> 2.25 | E3: =MAX('260110_SEQ_RESULT_1차테스트'!A3:A6) -> 3 | F3: =LOG(B3,2) -> 2 | H3: =F3/2 -> 1
B4: =COUNTA('260110_SEQ_RESULT_1차테스트'!A8:A13) -> 6 | C4: =SUM('260110_SEQ_RESULT_1차테스트'!A8:A13) -> 16 | D4: =C4/B4 -> 2.6666667 | E4: =MAX('260110_SEQ_RESULT_1차테스트'!A8:A13) -> 4 | F4: =LOG(B4,2) -> 2.5849625 | G4: =D4-D3 -> 0.41666667 | H4: =F4/2 -> 1.2924813
B5: =COUNTA('260110_SEQ_RESULT_1차테스트'!A15:A22) -> 8 | C5: =SUM('260110_SEQ_RESULT_1차테스트'!A15:A22) -> 22 | D5: =C5/B5 -> 2.75 | E5: =MAX('260110_SEQ_RESULT_1차테스트'!A15:A22) -> 4 | F5: =LOG(B5,2) -> 3 | G5: =D5-D4 -> 0.083333333 | H5: =F5/2 -> 1.5
B6: =COUNTA('260110_SEQ_RESULT_1차테스트'!A24:A33) -> 10 | C6: =SUM('260110_SEQ_RESULT_1차테스트'!A24:A33) -> 32 | D6: =C6/B6 -> 3.2 | E6: =MAX('260110_SEQ_RESULT_1차테스트'!A24:A33) -> 5 | F6: =LOG(B6,2) -> 3.3219281 | G6: =D6-D5 -> 0.45 | H6: =F6/2 -> 1.660964
B7: =COUNTA('260110_SEQ_RESULT_1차테스트'!A35:A50) -> 16 | C7: =SUM('260110_SEQ_RESULT_1차테스트'!A35:A50) -> 58 | D7: =C7/B7 -> 3.625 | E7: =MAX('260110_SEQ_RESULT_1차테스트'!A35:A50) -> 5 | F7: =LOG(B7,2) -> 4 | G7: =D7-D6 -> 0.425 | H7: =F7/2 -> 2
B8: =COUNTA('260110_SEQ_RESULT_1차테스트'!A52:A71) -> 20 | C8: =SUM('260110_SEQ_RESULT_1차테스트'!A52:A71) -> 79 | D8: =C8/B8 -> 3.95 | E8: =MAX('260110_SEQ_RESULT_1차테스트'!A52:A71) -> 5 | F8: =LOG(B8,2) -> 4.3219281 | G8: =D8-D7 -> 0.325 | H8: =F8/2 -> 2.160964
B9: =COUNTA('260110_SEQ_RESULT_1차테스트'!A73:A104) -> 32 | C9: =SUM('260110_SEQ_RESULT_1차테스트'!A73:A104) -> 130 | D9: =C9/B9 -> 4.0625 | E9: =MAX('260110_SEQ_RESULT_1차테스트'!A73:A104) -> 6 | F9: =LOG(B9,2) -> 5 | G9: =D9-D8 -> 0.1125 | H9: =F9/2 -> 2.5
B10: =COUNTA('260110_SEQ_RESULT_1차테스트'!A106:A145) -> 40 | C10: =SUM('260110_SEQ_RESULT_1차테스트'!A106:A145) -> 170 | D10: =C10/B10 -> 4.25 | E10: =MAX('260110_SEQ_RESULT_1차테스트'!A106:A145) -> 6 | F10: =LOG(B10,2) -> 5.3219281 | G10: =D10-D9 -> 0.1875 | H10: =F10/2 -> 2.660964
B11: =COUNTA('260110_SEQ_RESULT_1차테스트'!A147:A194) -> 48 | C11: =SUM('260110_SEQ_RESULT_1차테스트'!A147:A194) -> 215 | D11: =C11/B11 -> 4.4791667 | E11: =MAX('260110_SEQ_RESULT_1차테스트'!A147:A194) -> 7 | F11: =LOG(B11,2) -> 5.5849625 | G11: =D11-D10 -> 0.22916667 | H11: =F11/2 -> 2.7924813
B12: =COUNTA('260110_SEQ_RESULT_1차테스트'!A196:A251) -> 56 | C12: =SUM('260110_SEQ_RESULT_1차테스트'!A196:A251) -> 260 | D12: =C12/B12 -> 4.6428571 | E12: =MAX('260110_SEQ_RESULT_1차테스트'!A196:A251) -> 7 | F12: =LOG(B12,2) -> 5.8073549 | G12: =D12-D11 -> 0.16369048 | H12: =F12/2 -> 2.9036775
B13: =COUNTA('260110_SEQ_RESULT_1차테스트'!A253:A316) -> 64 | C13: =SUM('260110_SEQ_RESULT_1차테스트'!A253:A316) -> 301 | D13: =C13/B13 -> 4.703125 | E13: =MAX('260110_SEQ_RESULT_1차테스트'!A253:A316) -> 7 | F13: =LOG(B13,2) -> 6 | G13: =D13-D12 -> 0.060267857 | H13: =F13/2 -> 3
B14: =COUNTA('260110_SEQ_RESULT_1차테스트'!A318:A389) -> 72 | C14: =SUM('260110_SEQ_RESULT_1차테스트'!A318:A389) -> 344 | D14: =C14/B14 -> 4.7777778 | E14: =MAX('260110_SEQ_RESULT_1차테스트'!A318:A389) -> 8 | F14: =LOG(B14,2) -> 6.169925 | G14: =D14-D13 -> 0.074652778 | H14: =F14/2 -> 3.0849625
B15: =COUNTA('260110_SEQ_RESULT_1차테스트'!A391:A470) -> 80 | C15: =SUM('260110_SEQ_RESULT_1차테스트'!A391:A470) -> 389 | D15: =C15/B15 -> 4.8625 | E15: =MAX('260110_SEQ_RESULT_1차테스트'!A391:A470) -> 8 | F15: =LOG(B15,2) -> 6.3219281 | G15: =D15-D14 -> 0.084722222 | H15: =F15/2 -> 3.160964
B16: =COUNTA('260110_SEQ_RESULT_1차테스트'!A472:A561) -> 90 | C16: =SUM('260110_SEQ_RESULT_1차테스트'!A472:A561) -> 447 | D16: =C16/B16 -> 4.9666667 | E16: =MAX('260110_SEQ_RESULT_1차테스트'!A472:A561) -> 8 | F16: =LOG(B16,2) -> 6.4918531 | G16: =D16-D15 -> 0.10416667 | H16: =F16/2 -> 3.2459265
B17: =COUNTA('260110_SEQ_RESULT_1차테스트'!A563:A662) -> 100 | C17: =SUM('260110_SEQ_RESULT_1차테스트'!A563:A662) -> 505 | D17: =C17/B17 -> 5.05 | E17: =MAX('260110_SEQ_RESULT_1차테스트'!A563:A662) -> 8 | F17: =LOG(B17,2) -> 6.6438562 | G17: =D17-D16 -> 0.083333333 | H17: =F17/2 -> 3.3219281
B18: =COUNTA('260110_SEQ_RESULT_1차테스트'!A664:A773) -> 110 | C18: =SUM('260110_SEQ_RESULT_1차테스트'!A664:A773) -> 561 | D18: =C18/B18 -> 5.1 | E18: =MAX('260110_SEQ_RESULT_1차테스트'!A664:A773) -> 8 | F18: =LOG(B18,2) -> 6.7813597 | G18: =D18-D17 -> 0.05 | H18: =F18/2 -> 3.3906799
B19: =COUNTA('260110_SEQ_RESULT_1차테스트'!A775:A902) -> 128 | C19: =SUM('260110_SEQ_RESULT_1차테스트'!A775:A902) -> 676 | D19: =C19/B19 -> 5.28125 | E19: =MAX('260110_SEQ_RESULT_1차테스트'!A775:A902) -> 8 | F19: =LOG(B19,2) -> 7 | G19: =D19-D18 -> 0.18125 | H19: =F19/2 -> 3.5
B21: 250205_SQL_RESULT_2차테스트(FingerTable에서 비교검색)
B22: 불필요한 네트워크 통신(Hop)을 1회 줄여주는 최적화(Optimization)
B23: Chord 알고리즘의 SearchNodeAtFingerTable (보통 closest_preceding_node라고 부름) 함수는 원래 "Target 바로 앞의 노드"를 찾아서 그 노드에게 길을 물어보는 역할
B24: 내 Finger Table에 찾는 Target(목적지)이 이미 명확히 적혀 있다
B26: 노드수(N) | C26: 전체 Hop 수 | D26: 평균 Hop 수 | E26: 최대 Hop 수 | F26: log2(N) | G26: 증가 | H26: log2(N)/2
B27: =COUNTA('260206_SQL_RESULT_2차테스트'!A3:A6) -> 4 | C27: =SUM('260206_SQL_RESULT_2차테스트'!A3:A6) -> 7 | D27: =C27/B27 -> 1.75 | E27: =MAX('260206_SQL_RESULT_2차테스트'!A3:A6) -> 2 | F27: =LOG(B27,2) -> 2 | H27: =F27/2 -> 1
B28: =COUNTA('260206_SQL_RESULT_2차테스트'!A8:A13) -> 6 | C28: =SUM('260206_SQL_RESULT_2차테스트'!A8:A13) -> 12 | D28: =C28/B28 -> 2 | E28: =MAX('260206_SQL_RESULT_2차테스트'!A8:A13) -> 3 | F28: =LOG(B28,2) -> 2.5849625 | G28: =D28-D27 -> 0.25 | H28: =F28/2 -> 1.2924813 | J28: =D28-D27 -> 0.25
B29: =COUNTA('260206_SQL_RESULT_2차테스트'!A15:A22) -> 8 | C29: =SUM('260206_SQL_RESULT_2차테스트'!A15:A22) -> 16 | D29: =C29/B29 -> 2 | E29: =MAX('260206_SQL_RESULT_2차테스트'!A15:A22) -> 3 | F29: =LOG(B29,2) -> 3 | G29: =D29-D28 -> 0 | H29: =F29/2 -> 1.5
B30: =COUNTA('260206_SQL_RESULT_2차테스트'!A24:A33) -> 10 | C30: =SUM('260206_SQL_RESULT_2차테스트'!A24:A33) -> 26 | D30: =C30/B30 -> 2.6 | E30: =MAX('260206_SQL_RESULT_2차테스트'!A24:A33) -> 4 | F30: =LOG(B30,2) -> 3.3219281 | G30: =D30-D29 -> 0.6 | H30: =F30/2 -> 1.660964
B31: =COUNTA('260206_SQL_RESULT_2차테스트'!A35:A50) -> 16 | C31: =SUM('260206_SQL_RESULT_2차테스트'!A35:A50) -> 46 | D31: =C31/B31 -> 2.875 | E31: =MAX('260206_SQL_RESULT_2차테스트'!A35:A50) -> 4 | F31: =LOG(B31,2) -> 4 | G31: =D31-D30 -> 0.275 | H31: =F31/2 -> 2
B32: =COUNTA('260206_SQL_RESULT_2차테스트'!A52:A71) -> 20 | C32: =SUM('260206_SQL_RESULT_2차테스트'!A52:A71) -> 63 | D32: =C32/B32 -> 3.15 | E32: =MAX('260206_SQL_RESULT_2차테스트'!A52:A71) -> 4 | F32: =LOG(B32,2) -> 4.3219281 | G32: =D32-D31 -> 0.275 | H32: =F32/2 -> 2.160964
B33: =COUNTA('260206_SQL_RESULT_2차테스트'!A73:A104) -> 32 | C33: =SUM('260206_SQL_RESULT_2차테스트'!A73:A104) -> 102 | D33: =C33/B33 -> 3.1875 | E33: =MAX('260206_SQL_RESULT_2차테스트'!A73:A104) -> 5 | F33: =LOG(B33,2) -> 5 | G33: =D33-D32 -> 0.0375 | H33: =F33/2 -> 2.5
B34: =COUNTA('260206_SQL_RESULT_2차테스트'!A106:A145) -> 40 | C34: =SUM('260206_SQL_RESULT_2차테스트'!A106:A145) -> 135 | D34: =C34/B34 -> 3.375 | E34: =MAX('260206_SQL_RESULT_2차테스트'!A106:A145) -> 5 | F34: =LOG(B34,2) -> 5.3219281 | G34: =D34-D33 -> 0.1875 | H34: =F34/2 -> 2.660964
B35: =COUNTA('260206_SQL_RESULT_2차테스트'!A147:A194) -> 48 | C35: =SUM('260206_SQL_RESULT_2차테스트'!A147:A194) -> 173 | D35: =C35/B35 -> 3.6041667 | E35: =MAX('260206_SQL_RESULT_2차테스트'!A147:A194) -> 6 | F35: =LOG(B35,2) -> 5.5849625 | G35: =D35-D34 -> 0.22916667 | H35: =F35/2 -> 2.7924813
B36: =COUNTA('260206_SQL_RESULT_2차테스트'!A196:A251) -> 56 | C36: =SUM('260206_SQL_RESULT_2차테스트'!A196:A251) -> 210 | D36: =C36/B36 -> 3.75 | E36: =MAX('260206_SQL_RESULT_2차테스트'!A196:A251) -> 6 | F36: =LOG(B36,2) -> 5.8073549 | G36: =D36-D35 -> 0.14583333 | H36: =F36/2 -> 2.9036775
B37: =COUNTA('260206_SQL_RESULT_2차테스트'!A253:A316) -> 64 | C37: =SUM('260206_SQL_RESULT_2차테스트'!A253:A316) -> 243 | D37: =C37/B37 -> 3.796875 | E37: =MAX('260206_SQL_RESULT_2차테스트'!A253:A316) -> 6 | F37: =LOG(B37,2) -> 6 | G37: =D37-D36 -> 0.046875 | H37: =F37/2 -> 3
B38: =COUNTA('260206_SQL_RESULT_2차테스트'!A318:A389) -> 72 | C38: =SUM('260206_SQL_RESULT_2차테스트'!A318:A389) -> 278 | D38: =C38/B38 -> 3.8611111 | E38: =MAX('260206_SQL_RESULT_2차테스트'!A318:A389) -> 7 | F38: =LOG(B38,2) -> 6.169925 | G38: =D38-D37 -> 0.064236111 | H38: =F38/2 -> 3.0849625
B39: =COUNTA('260206_SQL_RESULT_2차테스트'!A391:A470) -> 80 | C39: =SUM('260206_SQL_RESULT_2차테스트'!A391:A470) -> 315 | D39: =C39/B39 -> 3.9375 | E39: =MAX('260206_SQL_RESULT_2차테스트'!A391:A470) -> 7 | F39: =LOG(B39,2) -> 6.3219281 | G39: =D39-D38 -> 0.076388889 | H39: =F39/2 -> 3.160964
B40: =COUNTA('260206_SQL_RESULT_2차테스트'!A472:A561) -> 90 | C40: =SUM('260206_SQL_RESULT_2차테스트'!A472:A561) -> 363 | D40: =C40/B40 -> 4.0333333 | E40: =MAX('260206_SQL_RESULT_2차테스트'!A472:A561) -> 7 | F40: =LOG(B40,2) -> 6.4918531 | G40: =D40-D39 -> 0.095833333 | H40: =F40/2 -> 3.2459265
B41: =COUNTA('260206_SQL_RESULT_2차테스트'!A563:A662) -> 100 | C41: =SUM('260206_SQL_RESULT_2차테스트'!A563:A662) -> 412 | D41: =C41/B41 -> 4.12 | E41: =MAX('260206_SQL_RESULT_2차테스트'!A563:A662) -> 7 | F41: =LOG(B41,2) -> 6.6438562 | G41: =D41-D40 -> 0.086666667 | H41: =F41/2 -> 3.3219281
B42: =COUNTA('260206_SQL_RESULT_2차테스트'!A664:A773) -> 110 | C42: =SUM('260206_SQL_RESULT_2차테스트'!A664:A773) -> 458 | D42: =C42/B42 -> 4.1636364 | E42: =MAX('260206_SQL_RESULT_2차테스트'!A664:A773) -> 7 | F42: =LOG(B42,2) -> 6.7813597 | G42: =D42-D41 -> 0.043636364 | H42: =F42/2 -> 3.3906799
...

Sheet 260110_SEQ_RESULT_1차테스트
A2: 홉수
A3: =IF(COUNTA(E3:AN3)>0, COUNTA(E3:AN3), "") -> 3 | B3: Node(4) | C3: 0 | D3: 127.0.0.1:6000 - 127.0.0.1:6001 | E3: 127.0.0.1:6000 | F3: 127.0.0.1:6002 | G3: 127.0.0.1:6001
A4: =IF(COUNTA(E4:AN4)>0, COUNTA(E4:AN4), "") -> 3 | B4: Node(4) | C4: 1 | D4: 127.0.0.1:6000 - 127.0.0.1:6003 | E4: 127.0.0.1:6000 | F4: 127.0.0.1:6001 | G4: 127.0.0.1:6003
A5: =IF(COUNTA(E5:AN5)>0, COUNTA(E5:AN5), "") -> 1 | B5: Node(4) | C5: 2 | D5: 127.0.0.1:6000 - 127.0.0.1:6000 | E5: 127.0.0.1:6000
A6: =IF(COUNTA(E6:AN6)>0, COUNTA(E6:AN6), "") -> 2 | B6: Node(4) | C6: 3 | D6: 127.0.0.1:6000 - 127.0.0.1:6002 | E6: 127.0.0.1:6000 | F6: 127.0.0.1:6002
A7: =IF(COUNTA(E7:AN7)>0, COUNTA(E7:AN7), "")
A8: =IF(COUNTA(E8:AN8)>0, COUNTA(E8:AN8), "") -> 3 | B8: Node(6) | C8: 0 | D8: 127.0.0.1:6000 - 127.0.0.1:6003 | E8: 127.0.0.1:6000 | F8: 127.0.0.1:6004 | G8: 127.0.0.1:6003
A9: =IF(COUNTA(E9:AN9)>0, COUNTA(E9:AN9), "") -> 4 | B9: Node(6) | C9: 1 | D9: 127.0.0.1:6000 - 127.0.0.1:6001 | E9: 127.0.0.1:6000 | F9: 127.0.0.1:6004 | G9: 127.0.0.1:6003 | H9: 127.0.0.1:6001
A10: =IF(COUNTA(E10:AN10)>0, COUNTA(E10:AN10), "") -> 1 | B10: Node(6) | C10: 2 | D10: 127.0.0.1:6000 - 127.0.0.1:6000 | E10: 127.0.0.1:6000
A11: =IF(COUNTA(E11:AN11)>0, COUNTA(E11:AN11), "") -> 2 | B11: Node(6) | C11: 3 | D11: 127.0.0.1:6000 - 127.0.0.1:6002 | E11: 127.0.0.1:6000 | F11: 127.0.0.1:6002
A12: =IF(COUNTA(E12:AN12)>0, COUNTA(E12:AN12), "") -> 3 | B12: Node(6) | C12: 4 | D12: 127.0.0.1:6000 - 127.0.0.1:6005 | E12: 127.0.0.1:6000 | F12: 127.0.0.1:6002 | G12: 127.0.0.1:6005
A13: =IF(COUNTA(E13:AN13)>0, COUNTA(E13:AN13), "") -> 3 | B13: Node(6) | C13: 5 | D13: 127.0.0.1:6000 - 127.0.0.1:6004 | E13: 127.0.0.1:6000 | F13: 127.0.0.1:6005 | G13: 127.0.0.1:6004
A14: =IF(COUNTA(E14:AN14)>0, COUNTA(E14:AN14), "")
A15: =IF(COUNTA(E15:AN15)>0, COUNTA(E15:AN15), "") -> 4 | B15: Node(8) | C15: 0 | D15: 127.0.0.1:6000 - 127.0.0.1:6004 | E15: 127.0.0.1:6000 | F15: 127.0.0.1:6006 | G15: 127.0.0.1:6001 | H15: 127.0.0.1:6004
A16: =IF(COUNTA(E16:AN16)>0, COUNTA(E16:AN16), "") -> 1 | B16: Node(8) | C16: 1 | D16: 127.0.0.1:6000 - 127.0.0.1:6000 | E16: 127.0.0.1:6000
A17: =IF(COUNTA(E17:AN17)>0, COUNTA(E17:AN17), "") -> 2 | B17: Node(8) | C17: 2 | D17: 127.0.0.1:6000 - 127.0.0.1:6002 | E17: 127.0.0.1:6000 | F17: 127.0.0.1:6002
A18: =IF(COUNTA(E18:AN18)>0, COUNTA(E18:AN18), "") -> 3 | B18: Node(8) | C18: 3 | D18: 127.0.0.1:6000 - 127.0.0.1:6005 | E18: 127.0.0.1:6000 | F18: 127.0.0.1:6002 | G18: 127.0.0.1:6005
A19: =IF(COUNTA(E19:AN19)>0, COUNTA(E19:AN19), "") -> 3 | B19: Node(8) | C19: 4 | D19: 127.0.0.1:6000 - 127.0.0.1:6007 | E19: 127.0.0.1:6000 | F19: 127.0.0.1:6005 | G19: 127.0.0.1:6007
A20: =IF(COUNTA(E20:AN20)>0, COUNTA(E20:AN20), "") -> 3 | B20: Node(8) | C20: 5 | D20: 127.0.0.1:6000 - 127.0.0.1:6003 | E20: 127.0.0.1:6000 | F20: 127.0.0.1:6007 | G20: 127.0.0.1:6003
A21: =IF(COUNTA(E21:AN21)>0, COUNTA(E21:AN21), "") -> 3 | B21: Node(8) | C21: 6 | D21: 127.0.0.1:6000 - 127.0.0.1:6006 | E21: 127.0.0.1:6000 | F21: 127.0.0.1:6003 | G21: 127.0.0.1:6006
A22: =IF(COUNTA(E22:AN22)>0, COUNTA(E22:AN22), "") -> 3 | B22: Node(8) | C22: 7 | D22: 127.0.0.1:6000 - 127.0.0.1:6001 | E22: 127.0.0.1:6000 | F22: 127.0.0.1:6006 | G22: 127.0.0.1:6001
A23: =IF(COUNTA(E23:AN23)>0, COUNTA(E23:AN23), "")
A24: =IF(COUNTA(E24:AN24)>0, COUNTA(E24:AN24), "") -> 3 | B24: Node(10) | C24: 0 | D24: 127.0.0.1:6000 - 127.0.0.1:6004 | E24: 127.0.0.1:6000 | F24: 127.0.0.1:6003 | G24: 127.0.0.1:6004
A25: =IF(COUNTA(E25:AN25)>0, COUNTA(E25:AN25), "") -> 3 | B25: Node(10) | C25: 1 | D25: 127.0.0.1:6000 - 127.0.0.1:6005 | E25: 127.0.0.1:6000 | F25: 127.0.0.1:6004 | G25: 127.0.0.1:6005
A26: =IF(COUNTA(E26:AN26)>0, COUNTA(E26:AN26), "") -> 3 | B26: Node(10) | C26: 2 | D26: 127.0.0.1:6000 - 127.0.0.1:6007 | E26: 127.0.0.1:6000 | F26: 127.0.0.1:6005 | G26: 127.0.0.1:6007
A27: =IF(COUNTA(E27:AN27)>0, COUNTA(E27:AN27), "") -> 3 | B27: Node(10) | C27: 3 | D27: 127.0.0.1:6000 - 127.0.0.1:6006 | E27: 127.0.0.1:6000 | F27: 127.0.0.1:6007 | G27: 127.0.0.1:6006
A28: =IF(COUNTA(E28:AN28)>0, COUNTA(E28:AN28), "") -> 4 | B28: Node(10) | C28: 4 | D28: 127.0.0.1:6000 - 127.0.0.1:6001 | E28: 127.0.0.1:6000 | F28: 127.0.0.1:6007 | G28: 127.0.0.1:6006 | H28: 127.0.0.1:6001
A29: =IF(COUNTA(E29:AN29)>0, COUNTA(E29:AN29), "") -> 5 | B29: Node(10) | C29: 5 | D29: 127.0.0.1:6000 - 127.0.0.1:6002 | E29: 127.0.0.1:6000 | F29: 127.0.0.1:6007 | G29: 127.0.0.1:6006 | H29: 127.0.0.1:6001 | I29: 127.0.0.1:6002
A30: =IF(COUNTA(E30:AN30)>0, COUNTA(E30:AN30), "") -> 4 | B30: Node(10) | C30: 6 | D30: 127.0.0.1:6000 - 127.0.0.1:6009 | E30: 127.0.0.1:6000 | F30: 127.0.0.1:6007 | G30: 127.0.0.1:6002 | H30: 127.0.0.1:6009
A31: =IF(COUNTA(E31:AN31)>0, COUNTA(E31:AN31), "") -> 4 | B31: Node(10) | C31: 7 | D31: 127.0.0.1:6000 - 127.0.0.1:6008 | E31: 127.0.0.1:6000 | F31: 127.0.0.1:6007 | G31: 127.0.0.1:6009 | H31: 127.0.0.1:6008
A32: =IF(COUNTA(E32:AN32)>0, COUNTA(E32:AN32), "") -> 1 | B32: Node(10) | C32: 8 | D32: 127.0.0.1:6000 - 127.0.0.1:6000 | E32: 127.0.0.1:6000
A33: =IF(COUNTA(E33:AN33)>0, COUNTA(E33:AN33), "") -> 2 | B33: Node(10) | C33: 9 | D33: 127.0.0.1:6000 - 127.0.0.1:6003 | E33: 127.0.0.1:6000 | F33: 127.0.0.1:6003
A34: =IF(COUNTA(E34:AN34)>0, COUNTA(E34:AN34), "")
A35: =IF(COUNTA(E35:AN35)>0, COUNTA(E35:AN35), "") -> 4 | B35: Node(16) | C35: 0 | D35: 127.0.0.1:6000 - 127.0.0.1:6008 | E35: 127.0.0.1:6000 | F35: 127.0.0.1:6001 | G35: 127.0.0.1:6013 | H35: 127.0.0.1:6008
A36: =IF(COUNTA(E36:AN36)>0, COUNTA(E36:AN36), "") -> 4 | B36: Node(16) | C36: 1 | D36: 127.0.0.1:6000 - 127.0.0.1:6015 | E36: 127.0.0.1:6000 | F36: 127.0.0.1:6001 | G36: 127.0.0.1:6008 | H36: 127.0.0.1:6015
A37: =IF(COUNTA(E37:AN37)>0, COUNTA(E37:AN37), "") -> 5 | B37: Node(16) | C37: 2 | D37: 127.0.0.1:6000 - 127.0.0.1:6002 | E37: 127.0.0.1:6000 | F37: 127.0.0.1:6001 | G37: 127.0.0.1:6008 | H37: 127.0.0.1:6015 | I37: 127.0.0.1:6002
A38: =IF(COUNTA(E38:AN38)>0, COUNTA(E38:AN38), "") -> 5 | B38: Node(16) | C38: 3 | D38: 127.0.0.1:6000 - 127.0.0.1:6006 | E38: 127.0.0.1:6000 | F38: 127.0.0.1:6001 | G38: 127.0.0.1:6008 | H38: 127.0.0.1:6002 | I38: 127.0.0.1:6006
A39: =IF(COUNTA(E39:AN39)>0, COUNTA(E39:AN39), "") -> 1 | B39: Node(16) | C39: 4 | D39: 127.0.0.1:6000 - 127.0.0.1:6000 | E39: 127.0.0.1:6000
A40: =IF(COUNTA(E40:AN40)>0, COUNTA(E40:AN40), "") -> 2 | B40: Node(16) | C40: 5 | D40: 127.0.0.1:6000 - 127.0.0.1:6012 | E40: 127.0.0.1:6000 | F40: 127.0.0.1:6012
A41: =IF(COUNTA(E41:AN41)>0, COUNTA(E41:AN41), "") -> 3 | B41: Node(16) | C41: 6 | D41: 127.0.0.1:6000 - 127.0.0.1:6009 | E41: 127.0.0.1:6000 | F41: 127.0.0.1:6012 | G41: 127.0.0.1:6009
...

Sheet 260206_SQL_RESULT_2차테스트
A2: 홉수 | H2: =COUNTA(F3:N902) -> 2530
A3: =IF(COUNTA(E3:AN3)>0, COUNTA(E3:AN3), "") -> 2 | B3: Node(4) | C3: 0 | D3: 127.0.0.1:6000 - 127.0.0.1:6001 | E3: 127.0.0.1:6000 | F3: 127.0.0.1:6001
A4: =IF(COUNTA(E4:AN4)>0, COUNTA(E4:AN4), "") -> 2 | B4: Node(4) | C4: 1 | D4: 127.0.0.1:6000 - 127.0.0.1:6003 | E4: 127.0.0.1:6000 | F4: 127.0.0.1:6003
A5: =IF(COUNTA(E5:AN5)>0, COUNTA(E5:AN5), "") -> 1 | B5: Node(4) | C5: 2 | D5: 127.0.0.1:6000 - 127.0.0.1:6000 | E5: 127.0.0.1:6000
A6: =IF(COUNTA(E6:AN6)>0, COUNTA(E6:AN6), "") -> 2 | B6: Node(4) | C6: 3 | D6: 127.0.0.1:6000 - 127.0.0.1:6002 | E6: 127.0.0.1:6000 | F6: 127.0.0.1:6002
A7: =IF(COUNTA(E7:AN7)>0, COUNTA(E7:AN7), "")
A8: =IF(COUNTA(E8:AN8)>0, COUNTA(E8:AN8), "") -> 3 | B8: Node(6) | C8: 0 | D8: 127.0.0.1:6000 - 127.0.0.1:6003 | E8: 127.0.0.1:6000 | F8: 127.0.0.1:6004 | G8: 127.0.0.1:6003
A9: =IF(COUNTA(E9:AN9)>0, COUNTA(E9:AN9), "") -> 2 | B9: Node(6) | C9: 1 | D9: 127.0.0.1:6000 - 127.0.0.1:6001 | E9: 127.0.0.1:6000 | F9: 127.0.0.1:6001
A10: =IF(COUNTA(E10:AN10)>0, COUNTA(E10:AN10), "") -> 1 | B10: Node(6) | C10: 2 | D10: 127.0.0.1:6000 - 127.0.0.1:6000 | E10: 127.0.0.1:6000
A11: =IF(COUNTA(E11:AN11)>0, COUNTA(E11:AN11), "") -> 2 | B11: Node(6) | C11: 3 | D11: 127.0.0.1:6000 - 127.0.0.1:6002 | E11: 127.0.0.1:6000 | F11: 127.0.0.1:6002
A12: =IF(COUNTA(E12:AN12)>0, COUNTA(E12:AN12), "") -> 2 | B12: Node(6) | C12: 4 | D12: 127.0.0.1:6000 - 127.0.0.1:6005 | E12: 127.0.0.1:6000 | F12: 127.0.0.1:6005
A13: =IF(COUNTA(E13:AN13)>0, COUNTA(E13:AN13), "") -> 2 | B13: Node(6) | C13: 5 | D13: 127.0.0.1:6000 - 127.0.0.1:6004 | E13: 127.0.0.1:6000 | F13: 127.0.0.1:6004
A14: =IF(COUNTA(E14:AN14)>0, COUNTA(E14:AN14), "")
A15: =IF(COUNTA(E15:AN15)>0, COUNTA(E15:AN15), "") -> 2 | B15: Node(8) | C15: 0 | D15: 127.0.0.1:6000 - 127.0.0.1:6004 | E15: 127.0.0.1:6000 | F15: 127.0.0.1:6004
A16: =IF(COUNTA(E16:AN16)>0, COUNTA(E16:AN16), "") -> 1 | B16: Node(8) | C16: 1 | D16: 127.0.0.1:6000 - 127.0.0.1:6000 | E16: 127.0.0.1:6000
A17: =IF(COUNTA(E17:AN17)>0, COUNTA(E17:AN17), "") -> 2 | B17: Node(8) | C17: 2 | D17: 127.0.0.1:6000 - 127.0.0.1:6002 | E17: 127.0.0.1:6000 | F17: 127.0.0.1:6002
A18: =IF(COUNTA(E18:AN18)>0, COUNTA(E18:AN18), "") -> 2 | B18: Node(8) | C18: 3 | D18: 127.0.0.1:6000 - 127.0.0.1:6005 | E18: 127.0.0.1:6000 | F18: 127.0.0.1:6005
A19: =IF(COUNTA(E19:AN19)>0, COUNTA(E19:AN19), "") -> 2 | B19: Node(8) | C19: 4 | D19: 127.0.0.1:6000 - 127.0.0.1:6007 | E19: 127.0.0.1:6000 | F19: 127.0.0.1:6007
A20: =IF(COUNTA(E20:AN20)>0, COUNTA(E20:AN20), "") -> 2 | B20: Node(8) | C20: 5 | D20: 127.0.0.1:6000 - 127.0.0.1:6003 | E20: 127.0.0.1:6000 | F20: 127.0.0.1:6003
A21: =IF(COUNTA(E21:AN21)>0, COUNTA(E21:AN21), "") -> 2 | B21: Node(8) | C21: 6 | D21: 127.0.0.1:6000 - 127.0.0.1:6006 | E21: 127.0.0.1:6000 | F21: 127.0.0.1:6006
A22: =IF(COUNTA(E22:AN22)>0, COUNTA(E22:AN22), "") -> 3 | B22: Node(8) | C22: 7 | D22: 127.0.0.1:6000 - 127.0.0.1:6001 | E22: 127.0.0.1:6000 | F22: 127.0.0.1:6006 | G22: 127.0.0.1:6001
A23: =IF(COUNTA(E23:AN23)>0, COUNTA(E23:AN23), "")
A24: =IF(COUNTA(E24:AN24)>0, COUNTA(E24:AN24), "") -> 2 | B24: Node(10) | C24: 0 | D24: 127.0.0.1:6000 - 127.0.0.1:6004 | E24: 127.0.0.1:6000 | F24: 127.0.0.1:6004
A25: =IF(COUNTA(E25:AN25)>0, COUNTA(E25:AN25), "") -> 2 | B25: Node(10) | C25: 1 | D25: 127.0.0.1:6000 - 127.0.0.1:6005 | E25: 127.0.0.1:6000 | F25: 127.0.0.1:6005
A26: =IF(COUNTA(E26:AN26)>0, COUNTA(E26:AN26), "") -> 2 | B26: Node(10) | C26: 2 | D26: 127.0.0.1:6000 - 127.0.0.1:6007 | E26: 127.0.0.1:6000 | F26: 127.0.0.1:6007
A27: =IF(COUNTA(E27:AN27)>0, COUNTA(E27:AN27), "") -> 3 | B27: Node(10) | C27: 3 | D27: 127.0.0.1:6000 - 127.0.0.1:6006 | E27: 127.0.0.1:6000 | F27: 127.0.0.1:6007 | G27: 127.0.0.1:6006
A28: =IF(COUNTA(E28:AN28)>0, COUNTA(E28:AN28), "") -> 4 | B28: Node(10) | C28: 4 | D28: 127.0.0.1:6000 - 127.0.0.1:6001 | E28: 127.0.0.1:6000 | F28: 127.0.0.1:6007 | G28: 127.0.0.1:6006 | H28: 127.0.0.1:6001
A29: =IF(COUNTA(E29:AN29)>0, COUNTA(E29:AN29), "") -> 3 | B29: Node(10) | C29: 5 | D29: 127.0.0.1:6000 - 127.0.0.1:6002 | E29: 127.0.0.1:6000 | F29: 127.0.0.1:6007 | G29: 127.0.0.1:6002
A30: =IF(COUNTA(E30:AN30)>0, COUNTA(E30:AN30), "") -> 3 | B30: Node(10) | C30: 6 | D30: 127.0.0.1:6000 - 127.0.0.1:6009 | E30: 127.0.0.1:6000 | F30: 127.0.0.1:6007 | G30: 127.0.0.1:6009
A31: =IF(COUNTA(E31:AN31)>0, COUNTA(E31:AN31), "") -> 4 | B31: Node(10) | C31: 7 | D31: 127.0.0.1:6000 - 127.0.0.1:6008 | E31: 127.0.0.1:6000 | F31: 127.0.0.1:6007 | G31: 127.0.0.1:6009 | H31: 127.0.0.1:6008
A32: =IF(COUNTA(E32:AN32)>0, COUNTA(E32:AN32), "") -> 1 | B32: Node(10) | C32: 8 | D32: 127.0.0.1:6000 - 127.0.0.1:6000 | E32: 127.0.0.1:6000
A33: =IF(COUNTA(E33:AN33)>0, COUNTA(E33:AN33), "") -> 2 | B33: Node(10) | C33: 9 | D33: 127.0.0.1:6000 - 127.0.0.1:6003 | E33: 127.0.0.1:6000 | F33: 127.0.0.1:6003
A34: =IF(COUNTA(E34:AN34)>0, COUNTA(E34:AN34), "")
A35: =IF(COUNTA(E35:AN35)>0, COUNTA(E35:AN35), "") -> 3 | B35: Node(16) | C35: 0 | D35: 127.0.0.1:6000 - 127.0.0.1:6008 | E35: 127.0.0.1:6000 | F35: 127.0.0.1:6001 | G35: 127.0.0.1:6008
A36: =IF(COUNTA(E36:AN36)>0, COUNTA(E36:AN36), "") -> 4 | B36: Node(16) | C36: 1 | D36: 127.0.0.1:6000 - 127.0.0.1:6015 | E36: 127.0.0.1:6000 | F36: 127.0.0.1:6001 | G36: 127.0.0.1:6008 | H36: 127.0.0.1:6015
A37: =IF(COUNTA(E37:AN37)>0, COUNTA(E37:AN37), "") -> 4 | B37: Node(16) | C37: 2 | D37: 127.0.0.1:6000 - 127.0.0.1:6002 | E37: 127.0.0.1:6000 | F37: 127.0.0.1:6001 | G37: 127.0.0.1:6008 | H37: 127.0.0.1:6002
A38: =IF(COUNTA(E38:AN38)>0, COUNTA(E38:AN38), "") -> 4 | B38: Node(16) | C38: 3 | D38: 127.0.0.1:6000 - 127.0.0.1:6006 | E38: 127.0.0.1:6000 | F38: 127.0.0.1:6001 | G38: 127.0.0.1:6008 | H38: 127.0.0.1:6006
A39: =IF(COUNTA(E39:AN39)>0, COUNTA(E39:AN39), "") -> 1 | B39: Node(16) | C39: 4 | D39: 127.0.0.1:6000 - 127.0.0.1:6000 | E39: 127.0.0.1:6000
A40: =IF(COUNTA(E40:AN40)>0, COUNTA(E40:AN40), "") -> 2 | B40: Node(16) | C40: 5 | D40: 127.0.0.1:6000 - 127.0.0.1:6012 | E40: 127.0.0.1:6000 | F40: 127.0.0.1:6012
A41: =IF(COUNTA(E41:AN41)>0, COUNTA(E41:AN41), "") -> 3 | B41: Node(16) | C41: 6 | D41: 127.0.0.1:6000 - 127.0.0.1:6009 | E41: 127.0.0.1:6000 | F41: 127.0.0.1:6012 | G41: 127.0.0.1:6009
...

Sheet 260212_PACKETCNT 테스트(10개노드)
A1: Node(10) | B1: 0 | C1: 127.0.0.1:6000 -127.0.0.1:6003 | D1: 127.0.0.1:6000 | E1: 127.0.0.1:6003
A2: Node(10) | B2: 1 | C2: 127.0.0.1:6000 -127.0.0.1:6003 | D2: 127.0.0.1:6000 | E2: 127.0.0.1:6004 | F2: 127.0.0.1:6002 | G2: 127.0.0.1:6003
A3: Node(10) | B3: 2 | C3: 127.0.0.1:6000 -127.0.0.1:6003 | D3: 127.0.0.1:6000 | E3: 127.0.0.1:6005 | F3: 127.0.0.1:6009 | G3: 127.0.0.1:6003
A4: Node(10) | B4: 3 | C4: 127.0.0.1:6000 -127.0.0.1:6003 | D4: 127.0.0.1:6000 | E4: 127.0.0.1:6007 | F4: 127.0.0.1:6003
A5: Node(10) | B5: 4 | C5: 127.0.0.1:6000 -127.0.0.1:6003 | D5: 127.0.0.1:6000 | E5: 127.0.0.1:6003
A6: Node(10) | B6: 5 | C6: 127.0.0.1:6000 -127.0.0.1:6003 | D6: 127.0.0.1:6000 | E6: 127.0.0.1:6004 | F6: 127.0.0.1:6005 | G6: 127.0.0.1:6007 | H6: 127.0.0.1:6006 | I6: 127.0.0.1:6009 | J6: 127.0.0.1:6004 | K6: 127.0.0.1:6007 | L6: 127.0.0.1:6002 | M6: 127.0.0.1:6005 | N6: 127.0.0.1:6009 | O6: 127.0.0.1:6007 | P6: 127.0.0.1:6009 | Q6: 127.0.0.1:6008 | R6: 127.0.0.1:6003
A7: Node(10) | B7: 6 | C7: 127.0.0.1:6000 -127.0.0.1:6003 | D7: 127.0.0.1:6000 | E7: 127.0.0.1:6005 | F7: 127.0.0.1:6007 | G7: 127.0.0.1:6003
A8: Node(10) | B8: 7 | C8: 127.0.0.1:6000 -127.0.0.1:6003 | D8: 127.0.0.1:6000 | E8: 127.0.0.1:6007 | F8: 127.0.0.1:6006 | G8: 127.0.0.1:6004 | H8: 127.0.0.1:6002 | I8: 127.0.0.1:6009 | J8: 127.0.0.1:6003
A9: Node(10) | B9: 8 | C9: 127.0.0.1:6000 -127.0.0.1:6003 | D9: 127.0.0.1:6000 | E9: 127.0.0.1:6003
A10: Node(10) | B10: 9 | C10: 127.0.0.1:6000 -127.0.0.1:6003 | D10: 127.0.0.1:6000 | E10: 127.0.0.1:6004 | F10: 127.0.0.1:6005 | G10: 127.0.0.1:6009 | H10: 127.0.0.1:6004 | I10: 127.0.0.1:6007 | J10: 127.0.0.1:6002 | K10: 127.0.0.1:6003
A11: Node(10) | B11: 10 | C11: 127.0.0.1:6000 -127.0.0.1:6003 | D11: 127.0.0.1:6000 | E11: 127.0.0.1:6005 | F11: 127.0.0.1:6007 | G11: 127.0.0.1:6009 | H11: 127.0.0.1:6007 | I11: 127.0.0.1:6003
A12: Node(10) | B12: 11 | C12: 127.0.0.1:6000 -127.0.0.1:6003 | D12: 127.0.0.1:6000 | E12: 127.0.0.1:6007 | F12: 127.0.0.1:6006 | G12: 127.0.0.1:6001 | H12: 127.0.0.1:6009 | I12: 127.0.0.1:6008 | J12: 127.0.0.1:6004 | K12: 127.0.0.1:6002 | L12: 127.0.0.1:6005 | M12: 127.0.0.1:6009 | N12: 127.0.0.1:6003
A13: Node(10) | B13: 12 | C13: 127.0.0.1:6000 -127.0.0.1:6003 | D13: 127.0.0.1:6000 | E13: 127.0.0.1:6003
A14: Node(10) | B14: 13 | C14: 127.0.0.1:6000 -127.0.0.1:6003 | D14: 127.0.0.1:6000 | E14: 127.0.0.1:6004 | F14: 127.0.0.1:6005 | G14: 127.0.0.1:6007 | H14: 127.0.0.1:6002 | I14: 127.0.0.1:6009 | J14: 127.0.0.1:6004 | K14: 127.0.0.1:6007 | L14: 127.0.0.1:6009 | M14: 127.0.0.1:6007 | N14: 127.0.0.1:6003
A15: Node(10) | B15: 14 | C15: 127.0.0.1:6000 -127.0.0.1:6003 | D15: 127.0.0.1:6000 | E15: 127.0.0.1:6005 | F15: 127.0.0.1:6009 | G15: 127.0.0.1:6008 | H15: 127.0.0.1:6005 | I15: 127.0.0.1:6007 | J15: 127.0.0.1:6006 | K15: 127.0.0.1:6002 | L15: 127.0.0.1:6003
A16: Node(10) | B16: 15 | C16: 127.0.0.1:6000 -127.0.0.1:6003 | D16: 127.0.0.1:6000 | E16: 127.0.0.1:6007 | F16: 127.0.0.1:6002 | G16: 127.0.0.1:6005 | H16: 127.0.0.1:6009 | I16: 127.0.0.1:6003
A17: Node(10) | B17: 16 | C17: 127.0.0.1:6000 -127.0.0.1:6003 | D17: 127.0.0.1:6000 | E17: 127.0.0.1:6003
A18: Node(10) | B18: 17 | C18: 127.0.0.1:6000 -127.0.0.1:6003 | D18: 127.0.0.1:6000 | E18: 127.0.0.1:6004 | F18: 127.0.0.1:6002 | G18: 127.0.0.1:6009 | H18: 127.0.0.1:6004 | I18: 127.0.0.1:6005 | J18: 127.0.0.1:6007 | K18: 127.0.0.1:6009 | L18: 127.0.0.1:6007 | M18: 127.0.0.1:6003
A19: Node(10) | B19: 18 | C19: 127.0.0.1:6000 -127.0.0.1:6003 | D19: 127.0.0.1:6000 | E19: 127.0.0.1:6005 | F19: 127.0.0.1:6009 | G19: 127.0.0.1:6008 | H19: 127.0.0.1:6007 | I19: 127.0.0.1:6006 | J19: 127.0.0.1:6009 | K19: 127.0.0.1:6003
A20: Node(10) | B20: 19 | C20: 127.0.0.1:6000 -127.0.0.1:6003 | D20: 127.0.0.1:6000 | E20: 127.0.0.1:6007 | F20: 127.0.0.1:6002 | G20: 127.0.0.1:6003
A21: Node(10) | B21: 20 | C21: 127.0.0.1:6000 -127.0.0.1:6003 | D21: 127.0.0.1:6000 | E21: 127.0.0.1:6003
A22: Node(10) | B22: 21 | C22: 127.0.0.1:6000 -127.0.0.1:6003 | D22: 127.0.0.1:6000 | E22: 127.0.0.1:6004 | F22: 127.0.0.1:6007 | G22: 127.0.0.1:6009 | H22: 127.0.0.1:6004 | I22: 127.0.0.1:6002 | J22: 127.0.0.1:6005 | K22: 127.0.0.1:6007 | L22: 127.0.0.1:6003
A23: Node(10) | B23: 22 | C23: 127.0.0.1:6000 -127.0.0.1:6003 | D23: 127.0.0.1:6000 | E23: 127.0.0.1:6005 | F23: 127.0.0.1:6009 | G23: 127.0.0.1:6007 | H23: 127.0.0.1:6006 | I23: 127.0.0.1:6004 | J23: 127.0.0.1:6005 | K23: 127.0.0.1:6007 | L23: 127.0.0.1:6002 | M23: 127.0.0.1:6009 | N23: 127.0.0.1:6008 | O23: 127.0.0.1:6000 | P23: 127.0.0.1:6007 | Q23: 127.0.0.1:6009 | R23: 127.0.0.1:6003
A24: Node(10) | B24: 23 | C24: 127.0.0.1:6000 -127.0.0.1:6003 | D24: 127.0.0.1:6000 | E24: 127.0.0.1:6003
A25: Node(10) | B25: 24 | C25: 127.0.0.1:6000 -127.0.0.1:6003 | D25: 127.0.0.1:6000 | E25: 127.0.0.1:6004 | F25: 127.0.0.1:6007 | G25: 127.0.0.1:6003
A26: Node(10) | B26: 25 | C26: 127.0.0.1:6000 -127.0.0.1:6003 | D26: 127.0.0.1:6000 | E26: 127.0.0.1:6005 | F26: 127.0.0.1:6009 | G26: 127.0.0.1:6004 | H26: 127.0.0.1:6002 | I26: 127.0.0.1:6003
A27: Node(10) | B27: 26 | C27: 127.0.0.1:6000 -127.0.0.1:6003 | D27: 127.0.0.1:6000 | E27: 127.0.0.1:6007 | F27: 127.0.0.1:6006 | G27: 127.0.0.1:6001 | H27: 127.0.0.1:6004 | I27: 127.0.0.1:6005 | J27: 127.0.0.1:6007 | K27: 127.0.0.1:6002 | L27: 127.0.0.1:6005 | M27: 127.0.0.1:6009 | N27: 127.0.0.1:6007 | O27: 127.0.0.1:6009 | P27: 127.0.0.1:6008 | Q27: 127.0.0.1:6003
A28: Node(10) | B28: 27 | C28: 127.0.0.1:6000 -127.0.0.1:6003 | D28: 127.0.0.1:6000 | E28: 127.0.0.1:6003
A29: Node(10) | B29: 28 | C29: 127.0.0.1:6000 -127.0.0.1:6003 | D29: 127.0.0.1:6000 | E29: 127.0.0.1:6004 | F29: 127.0.0.1:6007 | G29: 127.0.0.1:6003
A30: Node(10) | B30: 29 | C30: 127.0.0.1:6000 -127.0.0.1:6003 | D30: 127.0.0.1:6000 | E30: 127.0.0.1:6005 | F30: 127.0.0.1:6007 | G30: 127.0.0.1:6006 | H30: 127.0.0.1:6002 | I30: 127.0.0.1:6009 | J30: 127.0.0.1:6003
A31: Node(10) | B31: 30 | C31: 127.0.0.1:6000 -127.0.0.1:6003 | D31: 127.0.0.1:6000 | E31: 127.0.0.1:6007 | F31: 127.0.0.1:6002 | G31: 127.0.0.1:6003
A32: Node(10) | B32: 31 | C32: 127.0.0.1:6000 -127.0.0.1:6003 | D32: 127.0.0.1:6000 | E32: 127.0.0.1:6003
A33: Node(10) | B33: 32 | C33: 127.0.0.1:6000 -127.0.0.1:6003 | D33: 127.0.0.1:6000 | E33: 127.0.0.1:6004 | F33: 127.0.0.1:6002 | G33: 127.0.0.1:6005 | H33: 127.0.0.1:6009 | I33: 127.0.0.1:6004 | J33: 127.0.0.1:6005 | K33: 127.0.0.1:6007 | L33: 127.0.0.1:6009 | M33: 127.0.0.1:6007 | N33: 127.0.0.1:6003
A34: Node(10) | B34: 33 | C34: 127.0.0.1:6000 -127.0.0.1:6003 | D34: 127.0.0.1:6000 | E34: 127.0.0.1:6005 | F34: 127.0.0.1:6009 | G34: 127.0.0.1:6008 | H34: 127.0.0.1:6004 | I34: 127.0.0.1:6007 | J34: 127.0.0.1:6006 | K34: 127.0.0.1:6009 | L34: 127.0.0.1:6003
A35: Node(10) | B35: 34 | C35: 127.0.0.1:6000 -127.0.0.1:6003 | D35: 127.0.0.1:6000 | E35: 127.0.0.1:6007 | F35: 127.0.0.1:6002 | G35: 127.0.0.1:6009 | H35: 127.0.0.1:6004 | I35: 127.0.0.1:6002 | J35: 127.0.0.1:6003
A36: Node(10) | B36: 35 | C36: 127.0.0.1:6000 -127.0.0.1:6003 | D36: 127.0.0.1:6000 | E36: 127.0.0.1:6003
A37: Node(10) | B37: 36 | C37: 127.0.0.1:6000 -127.0.0.1:6003 | D37: 127.0.0.1:6000 | E37: 127.0.0.1:6004 | F37: 127.0.0.1:6005 | G37: 127.0.0.1:6007 | H37: 127.0.0.1:6009 | I37: 127.0.0.1:6007 | J37: 127.0.0.1:6003
A38: Node(10) | B38: 37 | C38: 127.0.0.1:6000 -127.0.0.1:6003 | D38: 127.0.0.1:6000 | E38: 127.0.0.1:6005 | F38: 127.0.0.1:6009 | G38: 127.0.0.1:6008 | H38: 127.0.0.1:6005 | I38: 127.0.0.1:6007 | J38: 127.0.0.1:6006 | K38: 127.0.0.1:6004 | L38: 127.0.0.1:6007 | M38: 127.0.0.1:6002 | N38: 127.0.0.1:6005 | O38: 127.0.0.1:6009 | P38: 127.0.0.1:6003
A39: Node(10) | B39: 38 | C39: 127.0.0.1:6000 -127.0.0.1:6003 | D39: 127.0.0.1:6000 | E39: 127.0.0.1:6007 | F39: 127.0.0.1:6009 | G39: 127.0.0.1:6004 | H39: 127.0.0.1:6002 | I39: 127.0.0.1:6009 | J39: 127.0.0.1:6007 | K39: 127.0.0.1:6003
A40: Node(10) | B40: 39 | C40: 127.0.0.1:6000 -127.0.0.1:6003 | D40: 127.0.0.1:6000 | E40: 127.0.0.1:6003
...

Sheet 이미지

Sheet 3. 테슽 (128)
