Workbook
Name _Hlk145398200: '3. 경로 탐색'!$D$16

Sheet 1. 기본 정보
A1: 1. Moduler | E1: 8
A3: 2. Peer 기본 정보
B4: ADDR | C4: crc32 | D4: HEX To INT
A5: PEER 1 | B5: x.x.x.10 | C5: 3a206a07 | D5: =HEX2DEC(C5) -> 975202823 | E5: =MOD(D5,$E$1) -> 7
A6: PEER 2 | B6: x.x.x.11 | C6: 8d3dab03 | D6: =HEX2DEC(C6) -> 2369628931 | E6: =MOD(D6,$E$1) -> 3
A7: PEER 3 | B7: x.x.x.12 | C7: 541be80e | D7: =HEX2DEC(C7) -> 1411115022 | E7: =MOD(D7,$E$1) -> 6
A8: PEER 4 | B8: x.x.x.13 | C8: e306290a | D8: =HEX2DEC(C8) -> 3808831754 | E8: =MOD(D8,$E$1) -> 2
A9: PEER 5 | B9: x.x.x.14 | C9: e6566e14 | D9: =HEX2DEC(C9) -> 3864423956 | E9: =MOD(D9,$E$1) -> 4
A10: PEER 6 | B10: x.x.x.15 | C10: 514baf10 | D10: =HEX2DEC(C10) -> 1363914512 | E10: =MOD(D10,$E$1) -> 0
A11: PEER 7 | B11: x.x.x.16 | C11: 886dec1d | D11: =HEX2DEC(C11) -> 2288905245 | E11: =MOD(D11,$E$1) -> 5
A12: PEER 8 | B12: x.x.x.17 | C12: 3f702d19 | D12: =HEX2DEC(C12) -> 1064316185 | E12: =MOD(D12,$E$1) -> 1
B14: 리소스 | C14: crc32 | D14: HEX To INT
A15: PEER 1 | B15: Data-Text | C15: eed9ae79 | D15: =HEX2DEC(C15) -> 4007243385 | E15: =MOD(D15,$E$1) -> 1
A16: PEER 2 | B16: AI-LLM | C16: 2c397047 | D16: =HEX2DEC(C16) -> 741961799 | E16: =MOD(D16,$E$1) -> 7
A17: PEER 3 | B17: Infra-Memory | C17: 7c98c82d | D17: =HEX2DEC(C17) -> 2090387501 | E17: =MOD(D17,$E$1) -> 5
A18: PEER 4 | B18: Data-Picture | C18: b34da9ae | D18: =HEX2DEC(C18) -> 3008211374 | E18: =MOD(D18,$E$1) -> 6
A19: PEER 5 | B19: AI-GAN | C19: 632dea5b | D19: =HEX2DEC(C19) -> 1663953499 | E19: =MOD(D19,$E$1) -> 3
A20: PEER 6 | B20: Infra-STORAGE | C20: 8eaffaaa | D20: =HEX2DEC(C20) -> 2393897642 | E20: =MOD(D20,$E$1) -> 2
A21: PEER 7 | B21: AI-DNN | C21: c2e504e4 | D21: =HEX2DEC(C21) -> 3269788900 | E21: =MOD(D21,$E$1) -> 4
A22: PEER 8 | B22: Data-Doc | C22: f5f174c0 | D22: =HEX2DEC(C22) -> 4126241984 | E22: =MOD(D22,$E$1) -> 0
A24: 3 동작 시간 (https://www.epochconverter.com/)
B25: 동작시간 | D25: UTC to INT | E25: SALT
A26: PEER 1 | B26: 15 Sep 2023 08:48:33 GMT | D26: 1694767713 | E26: =MOD(D26,$E$1) -> 1
A27: PEER 2 | B27: 18 Sep 2023 08:56:44 GMT | D27: 1695027404 | E27: =MOD(D27,$E$1) -> 4
A28: PEER 3 | B28: 18 Sep 2023 08:56:47 GMT | D28: 1695027407 | E28: =MOD(D28,$E$1) -> 7
A29: PEER 4 | B29: 18 Sep 2023 08:50:46 GMT | D29: 1695027046 | E29: =MOD(D29,$E$1) -> 6
A30: PEER 5 | B30: 17 Sep 2023 13:20:42 GMT | D30: 1694956842 | E30: =MOD(D30,$E$1) -> 2
A31: PEER 6 | B31: 16 Sep 2023 13:20:35 GMT | D31: 1694870435 | E31: =MOD(D31,$E$1) -> 3
A32: PEER 7 | B32: 16 Sep 2023 12:19:36 GMT | D32: 1694866776 | E32: =MOD(D32,$E$1) -> 0
A33: PEER 8 | B33: 15 Sep 2023 12:19:41 GMT | D33: 1694780381 | E33: =MOD(D33,$E$1) -> 5

Sheet 2. Finger Table(Addr, Resource)
A1: Peer 1 | B1: SALT | C1: ='1. 기본 정보'!E26 -> 1 | E1: Moduler | F1: ='1. 기본 정보'!$E$1 -> 8 | I1: Peer 1
C2: Address | D2: crc32 | E2: Hex to int | F2: ADD(Time + SLAT) | G2: Space(Mod) | J2: Resource | K2: crc32 | L2: Hex to int | M2: ADD(Time + SLAT) | N2: Space(Mod)
B3: 1 | C3: ='1. 기본 정보'!B5 -> x.x.x.10 | D3: ='1. 기본 정보'!C5 -> 3a206a07 | E3: ='1. 기본 정보'!D5 -> 975202823 | F3: =E3+$C$1 -> 975202824 | G3: =MOD(F3,$F$1) -> 0 | J3: ='1. 기본 정보'!B15 -> Data-Text | K3: ='1. 기본 정보'!C15 -> eed9ae79 | L3: ='1. 기본 정보'!D15 -> 4007243385 | M3: =L3+$C$1 -> 4007243386 | N3: =MOD(M3,$F$1) -> 2
B4: 2 | C4: ='1. 기본 정보'!B6 -> x.x.x.11 | D4: ='1. 기본 정보'!C6 -> 8d3dab03 | E4: ='1. 기본 정보'!D6 -> 2369628931 | F4: =E4+$C$1 -> 2369628932 | G4: =MOD(F4,$F$1) -> 4 | J4: ='1. 기본 정보'!B16 -> AI-LLM | K4: ='1. 기본 정보'!C16 -> 2c397047 | L4: ='1. 기본 정보'!D16 -> 741961799 | M4: =L4+$C$1 -> 741961800 | N4: =MOD(M4,$F$1) -> 0
B5: 3 | C5: ='1. 기본 정보'!B7 -> x.x.x.12 | D5: ='1. 기본 정보'!C7 -> 541be80e | E5: ='1. 기본 정보'!D7 -> 1411115022 | F5: =E5+$C$1 -> 1411115023 | G5: =MOD(F5,$F$1) -> 7 | J5: ='1. 기본 정보'!B17 -> Infra-Memory | K5: ='1. 기본 정보'!C17 -> 7c98c82d | L5: ='1. 기본 정보'!D17 -> 2090387501 | M5: =L5+$C$1 -> 2090387502 | N5: =MOD(M5,$F$1) -> 6
B6: 4 | C6: ='1. 기본 정보'!B8 -> x.x.x.13 | D6: ='1. 기본 정보'!C8 -> e306290a | E6: ='1. 기본 정보'!D8 -> 3808831754 | F6: =E6+$C$1 -> 3808831755 | G6: =MOD(F6,$F$1) -> 3 | J6: ='1. 기본 정보'!B18 -> Data-Picture | K6: ='1. 기본 정보'!C18 -> b34da9ae | L6: ='1. 기본 정보'!D18 -> 3008211374 | M6: =L6+$C$1 -> 3008211375 | N6: =MOD(M6,$F$1) -> 7
B7: 5 | C7: ='1. 기본 정보'!B9 -> x.x.x.14 | D7: ='1. 기본 정보'!C9 -> e6566e14 | E7: ='1. 기본 정보'!D9 -> 3864423956 | F7: =E7+$C$1 -> 3864423957 | G7: =MOD(F7,$F$1) -> 5 | J7: ='1. 기본 정보'!B19 -> AI-GAN | K7: ='1. 기본 정보'!C19 -> 632dea5b | L7: ='1. 기본 정보'!D19 -> 1663953499 | M7: =L7+$C$1 -> 1663953500 | N7: =MOD(M7,$F$1) -> 4
B8: 6 | C8: ='1. 기본 정보'!B10 -> x.x.x.15 | D8: ='1. 기본 정보'!C10 -> 514baf10 | E8: ='1. 기본 정보'!D10 -> 1363914512 | F8: =E8+$C$1 -> 1363914513 | G8: =MOD(F8,$F$1) -> 1 | J8: ='1. 기본 정보'!B20 -> Infra-STORAGE | K8: ='1. 기본 정보'!C20 -> 8eaffaaa | L8: ='1. 기본 정보'!D20 -> 2393897642 | M8: =L8+$C$1 -> 2393897643 | N8: =MOD(M8,$F$1) -> 3
B9: 7 | C9: ='1. 기본 정보'!B11 -> x.x.x.16 | D9: ='1. 기본 정보'!C11 -> 886dec1d | E9: ='1. 기본 정보'!D11 -> 2288905245 | F9: =E9+$C$1 -> 2288905246 | G9: =MOD(F9,$F$1) -> 6 | J9: ='1. 기본 정보'!B21 -> AI-DNN | K9: ='1. 기본 정보'!C21 -> c2e504e4 | L9: ='1. 기본 정보'!D21 -> 3269788900 | M9: =L9+$C$1 -> 3269788901 | N9: =MOD(M9,$F$1) -> 5
B10: 8 | C10: ='1. 기본 정보'!B12 -> x.x.x.17 | D10: ='1. 기본 정보'!C12 -> 3f702d19 | E10: ='1. 기본 정보'!D12 -> 1064316185 | F10: =E10+$C$1 -> 1064316186 | G10: =MOD(F10,$F$1) -> 2 | J10: ='1. 기본 정보'!B22 -> Data-Doc | K10: ='1. 기본 정보'!C22 -> f5f174c0 | L10: ='1. 기본 정보'!D22 -> 4126241984 | M10: =L10+$C$1 -> 4126241985 | N10: =MOD(M10,$F$1) -> 1
A12: Peer 2 | B12: SALT | C12: ='1. 기본 정보'!E27 -> 4 | E12: Moduler | F12: ='1. 기본 정보'!$E$1 -> 8 | I12: Peer 2
C13: Address | D13: crc32 | E13: Hex to int | F13: ADD(Time + SLAT) | G13: Space(Mod) | J13: Resource | K13: crc32 | L13: Hex to int | M13: ADD(Time + SLAT) | N13: Space(Mod)
B14: 1 | C14: =C3 -> x.x.x.10 | D14: =D3 -> 3a206a07 | E14: =HEX2DEC(D14) -> 975202823 | F14: =E14+$C$12 -> 975202827 | G14: =MOD(F14,$F$12) -> 3 | J14: =J3 -> Data-Text | K14: =K3 -> eed9ae79 | L14: =L3 -> 4007243385 | M14: =L14+$C$12 -> 4007243389 | N14: =MOD(M14,$F$12) -> 5
B15: 2 | C15: =C4 -> x.x.x.11 | D15: =D4 -> 8d3dab03 | E15: =HEX2DEC(D15) -> 2369628931 | F15: =E15+$C$12 -> 2369628935 | G15: =MOD(F15,$F$12) -> 7 | J15: =J4 -> AI-LLM | K15: =K4 -> 2c397047 | L15: =L4 -> 741961799 | M15: =L15+$C$12 -> 741961803 | N15: =MOD(M15,$F$12) -> 3
B16: 3 | C16: =C5 -> x.x.x.12 | D16: =D5 -> 541be80e | E16: =HEX2DEC(D16) -> 1411115022 | F16: =E16+$C$12 -> 1411115026 | G16: =MOD(F16,$F$12) -> 2 | J16: =J5 -> Infra-Memory | K16: =K5 -> 7c98c82d | L16: =L5 -> 2090387501 | M16: =L16+$C$12 -> 2090387505 | N16: =MOD(M16,$F$12) -> 1
B17: 4 | C17: =C6 -> x.x.x.13 | D17: =D6 -> e306290a | E17: =HEX2DEC(D17) -> 3808831754 | F17: =E17+$C$12 -> 3808831758 | G17: =MOD(F17,$F$12) -> 6 | J17: =J6 -> Data-Picture | K17: =K6 -> b34da9ae | L17: =L6 -> 3008211374 | M17: =L17+$C$12 -> 3008211378 | N17: =MOD(M17,$F$12) -> 2
B18: 5 | C18: =C7 -> x.x.x.14 | D18: =D7 -> e6566e14 | E18: =HEX2DEC(D18) -> 3864423956 | F18: =E18+$C$12 -> 3864423960 | G18: =MOD(F18,$F$12) -> 0 | J18: =J7 -> AI-GAN | K18: =K7 -> 632dea5b | L18: =L7 -> 1663953499 | M18: =L18+$C$12 -> 1663953503 | N18: =MOD(M18,$F$12) -> 7
B19: 6 | C19: =C8 -> x.x.x.15 | D19: =D8 -> 514baf10 | E19: =HEX2DEC(D19) -> 1363914512 | F19: =E19+$C$12 -> 1363914516 | G19: =MOD(F19,$F$12) -> 4 | J19: =J8 -> Infra-STORAGE | K19: =K8 -> 8eaffaaa | L19: =L8 -> 2393897642 | M19: =L19+$C$12 -> 2393897646 | N19: =MOD(M19,$F$12) -> 6
B20: 7 | C20: =C9 -> x.x.x.16 | D20: =D9 -> 886dec1d | E20: =HEX2DEC(D20) -> 2288905245 | F20: =E20+$C$12 -> 2288905249 | G20: =MOD(F20,$F$12) -> 1 | J20: =J9 -> AI-DNN | K20: =K9 -> c2e504e4 | L20: =L9 -> 3269788900 | M20: =L20+$C$12 -> 3269788904 | N20: =MOD(M20,$F$12) -> 0
B21: 8 | C21: =C10 -> x.x.x.17 | D21: =D10 -> 3f702d19 | E21: =HEX2DEC(D21) -> 1064316185 | F21: =E21+$C$12 -> 1064316189 | G21: =MOD(F21,$F$12) -> 5 | J21: =J10 -> Data-Doc | K21: =K10 -> f5f174c0 | L21: =L10 -> 4126241984 | M21: =L21+$C$12 -> 4126241988 | N21: =MOD(M21,$F$12) -> 4
A23: Peer 3 | B23: SALT | C23: ='1. 기본 정보'!E28 -> 7 | E23: Moduler | F23: ='1. 기본 정보'!$E$1 -> 8 | I23: Peer 3
C24: Address | D24: crc32 | E24: Hex to int | F24: ADD(Time + SLAT) | G24: Space(Mod) | J24: Resource | K24: crc32 | L24: Hex to int | M24: ADD(Time + SLAT) | N24: Space(Mod)
B25: 1 | C25: =C14 -> x.x.x.10 | D25: =D14 -> 3a206a07 | E25: =HEX2DEC(D25) -> 975202823 | F25: =E25+$C$23 -> 975202830 | G25: =MOD(F25,$F$23) -> 6 | J25: =J14 -> Data-Text | K25: =K14 -> eed9ae79 | L25: =L14 -> 4007243385 | M25: =L25+$C$23 -> 4007243392 | N25: =MOD(M25,$F$23) -> 0
B26: 2 | C26: =C15 -> x.x.x.11 | D26: =D15 -> 8d3dab03 | E26: =HEX2DEC(D26) -> 2369628931 | F26: =E26+$C$23 -> 2369628938 | G26: =MOD(F26,$F$23) -> 2 | J26: =J15 -> AI-LLM | K26: =K15 -> 2c397047 | L26: =L15 -> 741961799 | M26: =L26+$C$23 -> 741961806 | N26: =MOD(M26,$F$23) -> 6
B27: 3 | C27: =C16 -> x.x.x.12 | D27: =D16 -> 541be80e | E27: =HEX2DEC(D27) -> 1411115022 | F27: =E27+$C$23 -> 1411115029 | G27: =MOD(F27,$F$23) -> 5 | J27: =J16 -> Infra-Memory | K27: =K16 -> 7c98c82d | L27: =L16 -> 2090387501 | M27: =L27+$C$23 -> 2090387508 | N27: =MOD(M27,$F$23) -> 4
B28: 4 | C28: =C17 -> x.x.x.13 | D28: =D17 -> e306290a | E28: =HEX2DEC(D28) -> 3808831754 | F28: =E28+$C$23 -> 3808831761 | G28: =MOD(F28,$F$23) -> 1 | J28: =J17 -> Data-Picture | K28: =K17 -> b34da9ae | L28: =L17 -> 3008211374 | M28: =L28+$C$23 -> 3008211381 | N28: =MOD(M28,$F$23) -> 5
B29: 5 | C29: =C18 -> x.x.x.14 | D29: =D18 -> e6566e14 | E29: =HEX2DEC(D29) -> 3864423956 | F29: =E29+$C$23 -> 3864423963 | G29: =MOD(F29,$F$23) -> 3 | J29: =J18 -> AI-GAN | K29: =K18 -> 632dea5b | L29: =L18 -> 1663953499 | M29: =L29+$C$23 -> 1663953506 | N29: =MOD(M29,$F$23) -> 2
B30: 6 | C30: =C19 -> x.x.x.15 | D30: =D19 -> 514baf10 | E30: =HEX2DEC(D30) -> 1363914512 | F30: =E30+$C$23 -> 1363914519 | G30: =MOD(F30,$F$23) -> 7 | J30: =J19 -> Infra-STORAGE | K30: =K19 -> 8eaffaaa | L30: =L19 -> 2393897642 | M30: =L30+$C$23 -> 2393897649 | N30: =MOD(M30,$F$23) -> 1
B31: 7 | C31: =C20 -> x.x.x.16 | D31: =D20 -> 886dec1d | E31: =HEX2DEC(D31) -> 2288905245 | F31: =E31+$C$23 -> 2288905252 | G31: =MOD(F31,$F$23) -> 4 | J31: =J20 -> AI-DNN | K31: =K20 -> c2e504e4 | L31: =L20 -> 3269788900 | M31: =L31+$C$23 -> 3269788907 | N31: =MOD(M31,$F$23) -> 3
B32: 8 | C32: =C21 -> x.x.x.17 | D32: =D21 -> 3f702d19 | E32: =HEX2DEC(D32) -> 1064316185 | F32: =E32+$C$23 -> 1064316192 | G32: =MOD(F32,$F$23) -> 0 | J32: =J21 -> Data-Doc | K32: =K21 -> f5f174c0 | L32: =L21 -> 4126241984 | M32: =L32+$C$23 -> 4126241991 | N32: =MOD(M32,$F$23) -> 7
A34: Peer 4 | B34: SALT | C34: ='1. 기본 정보'!E29 -> 6 | E34: Moduler | F34: ='1. 기본 정보'!$E$1 -> 8 | I34: Peer 4
C35: Address | D35: crc32 | E35: Hex to int | F35: ADD(Time + SLAT) | G35: Space(Mod) | J35: Resource | K35: crc32 | L35: Hex to int | M35: ADD(Time + SLAT) | N35: Space(Mod)
B36: 1 | C36: =C25 -> x.x.x.10 | D36: =D25 -> 3a206a07 | E36: =HEX2DEC(D36) -> 975202823 | F36: =E36+$C$34 -> 975202829 | G36: =MOD(F36,$F$34) -> 5 | J36: =J25 -> Data-Text | K36: =K25 -> eed9ae79 | L36: =L25 -> 4007243385 | M36: =L36+$C$34 -> 4007243391 | N36: =MOD(M36,$F$34) -> 7
B37: 2 | C37: =C26 -> x.x.x.11 | D37: =D26 -> 8d3dab03 | E37: =HEX2DEC(D37) -> 2369628931 | F37: =E37+$C$34 -> 2369628937 | G37: =MOD(F37,$F$34) -> 1 | J37: =J26 -> AI-LLM | K37: =K26 -> 2c397047 | L37: =L26 -> 741961799 | M37: =L37+$C$34 -> 741961805 | N37: =MOD(M37,$F$34) -> 5
B38: 3 | C38: =C27 -> x.x.x.12 | D38: =D27 -> 541be80e | E38: =HEX2DEC(D38) -> 1411115022 | F38: =E38+$C$34 -> 1411115028 | G38: =MOD(F38,$F$34) -> 4 | J38: =J27 -> Infra-Memory | K38: =K27 -> 7c98c82d | L38: =L27 -> 2090387501 | M38: =L38+$C$34 -> 2090387507 | N38: =MOD(M38,$F$34) -> 3
B39: 4 | C39: =C28 -> x.x.x.13 | D39: =D28 -> e306290a | E39: =HEX2DEC(D39) -> 3808831754 | F39: =E39+$C$34 -> 3808831760 | G39: =MOD(F39,$F$34) -> 0 | J39: =J28 -> Data-Picture | K39: =K28 -> b34da9ae | L39: =L28 -> 3008211374 | M39: =L39+$C$34 -> 3008211380 | N39: =MOD(M39,$F$34) -> 4
B40: 5 | C40: =C29 -> x.x.x.14 | D40: =D29 -> e6566e14 | E40: =HEX2DEC(D40) -> 3864423956 | F40: =E40+$C$34 -> 3864423962 | G40: =MOD(F40,$F$34) -> 2 | J40: =J29 -> AI-GAN | K40: =K29 -> 632dea5b | L40: =L29 -> 1663953499 | M40: =L40+$C$34 -> 1663953505 | N40: =MOD(M40,$F$34) -> 1
B41: 6 | C41: =C30 -> x.x.x.15 | D41: =D30 -> 514baf10 | E41: =HEX2DEC(D41) -> 1363914512 | F41: =E41+$C$34 -> 1363914518 | G41: =MOD(F41,$F$34) -> 6 | J41: =J30 -> Infra-STORAGE | K41: =K30 -> 8eaffaaa | L41: =L30 -> 2393897642 | M41: =L41+$C$34 -> 2393897648 | N41: =MOD(M41,$F$34) -> 0
B42: 7 | C42: =C31 -> x.x.x.16 | D42: =D31 -> 886dec1d | E42: =HEX2DEC(D42) -> 2288905245 | F42: =E42+$C$34 -> 2288905251 | G42: =MOD(F42,$F$34) -> 3 | J42: =J31 -> AI-DNN | K42: =K31 -> c2e504e4 | L42: =L31 -> 3269788900 | M42: =L42+$C$34 -> 3269788906 | N42: =MOD(M42,$F$34) -> 2
B43: 8 | C43: =C32 -> x.x.x.17 | D43: =D32 -> 3f702d19 | E43: =HEX2DEC(D43) -> 1064316185 | F43: =E43+$C$34 -> 1064316191 | G43: =MOD(F43,$F$34) -> 7 | J43: =J32 -> Data-Doc | K43: =K32 -> f5f174c0 | L43: =L32 -> 4126241984 | M43: =L43+$C$34 -> 4126241990 | N43: =MOD(M43,$F$34) -> 6
...

Sheet 3. 경로 탐색
A1: 1. Moduler | E1: ='1. 기본 정보'!E1 -> 8
E3: H(x)=x mod 8
A5: PEER 1 | B5: 15 Sep 2023 08:48:33 GMT | D5: 1694767713 | E5: =MOD(D5,'1. 기본 정보'!$E$1) -> 1
B6: 15 Sep 2023 08:48:43 GMT | D6: 1694767723 | E6: =MOD(D6,'1. 기본 정보'!$E$1) -> 3
B7: 15 Sep 2023 08:48:53 GMT | D7: 1694767733 | E7: =MOD(D7,'1. 기본 정보'!$E$1) -> 5

Sheet 4. 암복호화
A1: RSA | B1: https://www.devglan.com/online-tools/rsa-encryption-decryption
A2: XOR | B2: https://xor.pw/#
A4: 1. 암호 알고리즘 | B4: Key Size | C4: 1024 bit
B5: Ciper type | C5: RSA/ECB/PKCS1Padding
B6: Key Pair | C6: Public Key | D6: Private Key
C7: MIGfMA0GCSqGSIb3DQEBAQUAA4GNADCBiQKBgQCrtLBLeThHU9mIXXTCYdyjJgkODfQGcRKglNrAZZxud1es1Da81AqJZjV1VdAEn0bN4+Ft4ExsCDHz8hM5mxnk75GnJCM5naffR6yovsO6rno6EXfiN9rAfYe2qXFXuso3yZV+3MIi3Rq9m2JQ0e7NSex4UV1KvRfnnvP5xlGcuwIDAQAB | D7: MIICdgIBADANBgkqhkiG9w0BAQEFAASCAmAwggJcAgEAAoGBAKu0sEt5OEdT2YhddMJh3KMmCQ4N9AZxEqCU2sBlnG53V6zUNrzUColmNXVV0ASfRs3j4W3gTGwIMfPyEzmbGeTvkackIzmdp99HrKi+w7quejoRd+I32sB9h7apcVe6yjfJlX7cwiLdGr2bYlDR7s1J7HhRXUq9F+ee8/nGUZy7AgMBAAECgYBZ/RGkDHzFTRml0Sz/LuC+lJGMTx3EPoB/rmPTD63jayKFDpc9cXewOOPtgbLKqVsnTrX3quUCfW0Ip6cRusrfhpz4Hj1V/yPy2wsk8nx+8mPrpQhNErn+wMifn9OHCjItTcXE8N0o0XQna+PhAl4zCszRJ6vZSYXmhdzc2V0SoQJBAOyU5+e/PpHsu3ACPozx2/qtW6FE9EofwFxLvnnvjesOdQqV6t4aNnJP0+FnqoYY89xPU2CKo7V1hFafAT8MMKsCQQC5zJm07hqwbY7lFtLjFFIact6YW6OHdm8B5ciOK7fWB6eG38bd1o+68jNT8rKXqBrn4xJodsKvuIJOHOL07OQxAkBQflFw/hax25PihkD1/4xS/AzDEAz181uli3fhUOo+YYrc8SkaLFz+A78ZYAYa3f6KpMq/fCw7HyLJvgvUgbdFAkB+tW+lmjQNWcn3pccQIc2UR/5R/TzapwQxURmjC2GFzxaKvpWKuEaxAXfLqlntXzFqLstg/ozq9XO3/a8xxVQhAkEA3QAxpu6SZdwTYaSiO23zT5UJ9VqZHt8NgcLi71Z2Qv81NrFZxyq1Hre3uyoWShBuAW942Jb4dFw7fPtesSdxXQ==
C9: 데이터(ASCII) | D9: 암호화(BASE64)
A10: 2. 평문 | C10: EncryptTest XOR CTR | D10: lCG70lhhpO5JH9vPWYMJq+9pBCHqZ0MTyCsyLQbriAI98Iai0Gsi//5HfTnRu36gEuLQwTdg0Czewv2tFlxMuNo6VWkfbtxR/1R31bF9x/H1/sHBPXs/drFzMBV3gyGnKLmmDhbllJA8dLqkGH8m1FET0+AXzdGyaf/cnNOpRfM=
B11: CTR | C11: 데이터(ASCII) | D11: XOR(HEX) | E11: 암호화(BASE64)
A12: 3. XOR 테스트 | B12: 1 | C12: EncryptTest XOR CTR | D12: 456e63727970745465737420584f5220435453 | E12: qvbbjHjUaOtHLj1dlS6Ble1rNrzZaKxyFUuoHaxMWkgI9mkNh3cv/R3oEH4xuYrsvKVVEA6k16K8zW8H27C8Hx2jC3IV1wNBmAXw+MGttKpfOYVrDvVucVpV2UHIhFcxIMV3WdwhRUk5mHy+FSJkYio8RrSyzfexdvW0vrI5wrA=
B13: 2 | C13: EncryptTest XOR CTR | D13: 456e63727970745465737420584f5220435450 | E13: QHOk3250m8nE3w/Yr3tvApoG+MQrOWCVyFNWKD16hhVT+HoCT3e2wjEqCKai3arA9O9SDMOjYzEgeAyfkWZklC5A5CCvdEr7nEzbrOqTwYwPublSNv2ghStH0pKu+22L7nV71jU/goqsNfUNzH5fHtXeAlGsANTOpAU/R9jkTNs=
B14: 3 | C14: EncryptTest XOR CTR | D14: 456e63727970745465737420584f5220435451 | E14: qi56kCNaqb4ubrq6LXFdTzRvTHzd+KWMcd/CTGqIiRlx6vbSF7IDwIajJuzpm4tg1su2s5Q4khqYy53iKxn1RiW/iKsaZfffpM7Qlc9pN5iDMHWJ/n5u8cjZwLRdcMerHi7WTdHG4BWtro9B0LX1v2KHR7lv/fx7InvtQQZqE/8=
B15: 4 | C15: EncryptTest XOR CTR | D15: 456e63727970745465737420584f5220435456 | E15: jH9IgijW1XOTlh4ZMbMW1wMwoGS0lJcKepC+nemu2L0abZC++7CM5TbjWjjm/gvE3z+LgBm6wBu45hYoF9RAwaYGabb0o9i75vb+nfsr4GJvbtWHve79WjZBkkP35VH4uoIivgVvJRVO61TI+97wqZ0iwScAZ9NcmAAUPBQ0174=
B16: 5 | C16: EncryptTest XOR CTR | D16: 456e63727970745465737420584f5220435457 | E16: f9MUZW24NPGBxCJC4bYk839hXSWDKLgFjjjzGUigV+3BqUIu0Xh3HMv38QwhnjTzLADUfdnEaXqJsblcIfv/oultju9cmN3ej45ssB9Kw+4aSdVsNHGmX4+DkdA1VwlvTP78x4tjHNUtNiomWM4SskZJ872Esj64bnmsWsKKCYc=
B19: CTR | C19: 암호화(BASE64) | D19: 복호화(HEX) | E19: XOR(ASCII)
B20: 1 | C20: =E12 -> qvbbjHjUaOtHLj1dlS6Ble1rNrzZaKxyFUuoHaxMWkgI9mkNh3cv/R3oEH4xuYrsvKVVEA6k16K8zW8H27C8Hx2jC3IV1wNBmAXw+MGttKpfOYVrDvVucVpV2UHIhFcxIMV3WdwhRUk5mHy+FSJkYio8RrSyzfexdvW0vrI5wrA= | D20: 456e63727970745465737420584f5220435453 | E20: EncryptTest XOR CTR
B21: 2 | C21: =E13 -> QHOk3250m8nE3w/Yr3tvApoG+MQrOWCVyFNWKD16hhVT+HoCT3e2wjEqCKai3arA9O9SDMOjYzEgeAyfkWZklC5A5CCvdEr7nEzbrOqTwYwPublSNv2ghStH0pKu+22L7nV71jU/goqsNfUNzH5fHtXeAlGsANTOpAU/R9jkTNs= | D21: 456e63727970745465737420584f5220435450 | E21: EncryptTest XOR CTR
B22: 3 | C22: =E14 -> qi56kCNaqb4ubrq6LXFdTzRvTHzd+KWMcd/CTGqIiRlx6vbSF7IDwIajJuzpm4tg1su2s5Q4khqYy53iKxn1RiW/iKsaZfffpM7Qlc9pN5iDMHWJ/n5u8cjZwLRdcMerHi7WTdHG4BWtro9B0LX1v2KHR7lv/fx7InvtQQZqE/8= | D22: 456e63727970745465737420584f5220435451 | E22: EncryptTest XOR CTR
B23: 4 | C23: =E15 -> jH9IgijW1XOTlh4ZMbMW1wMwoGS0lJcKepC+nemu2L0abZC++7CM5TbjWjjm/gvE3z+LgBm6wBu45hYoF9RAwaYGabb0o9i75vb+nfsr4GJvbtWHve79WjZBkkP35VH4uoIivgVvJRVO61TI+97wqZ0iwScAZ9NcmAAUPBQ0174= | D23: 456e63727970745465737420584f5220435456 | E23: EncryptTest XOR CTR
B24: 5 | C24: =E16 -> f9MUZW24NPGBxCJC4bYk839hXSWDKLgFjjjzGUigV+3BqUIu0Xh3HMv38QwhnjTzLADUfdnEaXqJsblcIfv/oultju9cmN3ej45ssB9Kw+4aSdVsNHGmX4+DkdA1VwlvTP78x4tjHNUtNiomWM4SskZJ872Esj64bnmsWsKKCYc= | D24: 456e63727970745465737420584f5220435457 | E24: EncryptTest XOR CTR

Sheet 5-1. Peer 경로(3개) 
B1: 1. Moduler | F1: 8
B3: 2. Peer 기본 정보
C4: ADDR | D4: crc32 | E4: HEX To INT
B5: PEER 1 | C5: x.x.x.10 | D5: 3a206a07 | E5: =HEX2DEC(D5) -> 975202823 | F5: =MOD(E5,$F$1) -> 7
B6: PEER 2 | C6: x.x.x.11 | D6: 8d3dab03 | E6: =HEX2DEC(D6) -> 2369628931 | F6: =MOD(E6,$F$1) -> 3
B7: PEER 3 | C7: x.x.x.12 | D7: 541be80e | E7: =HEX2DEC(D7) -> 1411115022 | F7: =MOD(E7,$F$1) -> 6
C9: 리소스 | D9: crc32 | E9: HEX To INT
B10: PEER 1 | C10: Data-Text | D10: eed9ae79 | E10: =HEX2DEC(D10) -> 4007243385 | F10: =MOD(E10,$F$1) -> 1
B11: PEER 2 | C11: AI-LLM | D11: 2c397047 | E11: =HEX2DEC(D11) -> 741961799 | F11: =MOD(E11,$F$1) -> 7
B12: PEER 3 | C12: Infra-Memory | D12: 7c98c82d | E12: =HEX2DEC(D12) -> 2090387501 | F12: =MOD(E12,$F$1) -> 5
B14: 3. 동작 시간 ()
C15: 동작시간 | E15: UTC to INT | F15: SALT
B16: PEER 1 | C16: 15 Sep 2023 08:48:33 GMT | E16: 1694767713 | F16: =MOD(E16,$F$1) -> 1
B17: PEER 2 | C17: 18 Sep 2023 08:56:44 GMT | E17: 1695027404 | F17: =MOD(E17,$F$1) -> 4
B18: PEER 3 | C18: 18 Sep 2023 08:56:47 GMT | E18: 1695027407 | F18: =MOD(E18,$F$1) -> 7
B19: PEER 1 | C19: 16 Sep 2023 12:19:36 GMT | E19: 1694866776 | F19: =MOD(E19,$F$1) -> 0
B20: PEER 2 | C20: 15 Sep 2023 12:12:41 GMT | E20: 1694779961 | F20: =MOD(E20,$F$1) -> 1
B21: PEER 3 | C21: 15 Sep 2023 12:19:41 GMT | E21: 1694780381 | F21: =MOD(E21,$F$1) -> 5
B22: PEER 1 | C22: 18 Sep 2023 08:50:46 GMT | E22: 1695027046 | F22: =MOD(E22,$F$1) -> 6
B23: PEER 2 | C23: 17 Sep 2023 13:20:42 GMT | E23: 1694956842 | F23: =MOD(E23,$F$1) -> 2
B24: PEER 3 | C24: 16 Sep 2023 13:20:35 GMT | E24: 1694870435 | F24: =MOD(E24,$F$1) -> 3
B26: 4. 갱신
B27: 1 | D27: SALT | E27: =F16 -> 1 | G27: Moduler | H27: =$F$1 -> 8
E28: Address | F28: crc32 | G28: ADD(Time+SLAT) | H28: Space(Mod) | J28: Resource | K28: Hex to int | L28: ADD(Time+SLAT) | M28: Space(Mod)
C29: Peer 1 | D29: 1 | E29: =$C$5 -> x.x.x.10 | F29: =$E$5 -> 975202823 | G29: =F29+$E$27 -> 975202824 | H29: =MOD(G29,$H$27) -> 0 | J29: =$C$10 -> Data-Text | K29: =$E$10 -> 4007243385 | L29: =K29+$E$27 -> 4007243386 | M29: =MOD(L29,$H$27) -> 2
D30: 2 | E30: =$C$6 -> x.x.x.11 | F30: =$E$6 -> 2369628931 | G30: =F30+$E$27 -> 2369628932 | H30: =MOD(G30,$H$27) -> 4 | J30: =$C$11 -> AI-LLM | K30: =$E$11 -> 741961799 | L30: =K30+$E$27 -> 741961800 | M30: =MOD(L30,$H$27) -> 0
D31: 3 | E31: =$C$7 -> x.x.x.12 | F31: =$E$7 -> 1411115022 | G31: =F31+$E$27 -> 1411115023 | H31: =MOD(G31,$H$27) -> 7 | J31: =$C$12 -> Infra-Memory | K31: =$E$12 -> 2090387501 | L31: =K31+$E$27 -> 2090387502 | M31: =MOD(L31,$H$27) -> 6
C33: Peer 2 | D33: SALT | E33: =F17 -> 4 | G33: Moduler | H33: =$F$1 -> 8
E34: Address | F34: crc32 | G34: ADD(Time+SLAT) | H34: Space(Mod) | J34: Resource | K34: Hex to int | L34: ADD(Time+SLAT) | M34: Space(Mod)
D35: 1 | E35: =E29 -> x.x.x.10 | F35: =F29 -> 975202823 | G35: =F35+$E$33 -> 975202827 | H35: =MOD(G35,$H$33) -> 3 | J35: =J29 -> Data-Text | K35: =K29 -> 4007243385 | L35: =K35+$E$33 -> 4007243389 | M35: =MOD(L35,$H$33) -> 5
D36: 2 | E36: =E30 -> x.x.x.11 | F36: =F30 -> 2369628931 | G36: =F36+$E$33 -> 2369628935 | H36: =MOD(G36,$H$33) -> 7 | J36: =J30 -> AI-LLM | K36: =K30 -> 741961799 | L36: =K36+$E$33 -> 741961803 | M36: =MOD(L36,$H$33) -> 3
D37: 3 | E37: =E31 -> x.x.x.12 | F37: =F31 -> 1411115022 | G37: =F37+$E$33 -> 1411115026 | H37: =MOD(G37,$H$33) -> 2 | J37: =J31 -> Infra-Memory | K37: =K31 -> 2090387501 | L37: =K37+$E$33 -> 2090387505 | M37: =MOD(L37,$H$33) -> 1
C39: Peer 3 | D39: SALT | E39: =F18 -> 7 | G39: Moduler | H39: =$F$1 -> 8
E40: Address | F40: crc32 | G40: ADD(Time+SLAT) | H40: Space(Mod) | J40: Resource | K40: Hex to int | L40: ADD(Time+SLAT) | M40: Space(Mod)
D41: 1 | E41: =E35 -> x.x.x.10 | F41: =F35 -> 975202823 | G41: =F41+$E$39 -> 975202830 | H41: =MOD(G41,$H$39) -> 6 | J41: =J35 -> Data-Text | K41: =K35 -> 4007243385 | L41: =K41+$E$39 -> 4007243392 | M41: =MOD(L41,$H$39) -> 0
D42: 2 | E42: =E36 -> x.x.x.11 | F42: =F36 -> 2369628931 | G42: =F42+$E$39 -> 2369628938 | H42: =MOD(G42,$H$39) -> 2 | J42: =J36 -> AI-LLM | K42: =K36 -> 741961799 | L42: =K42+$E$39 -> 741961806 | M42: =MOD(L42,$H$39) -> 6
D43: 3 | E43: =E37 -> x.x.x.12 | F43: =F37 -> 1411115022 | G43: =F43+$E$39 -> 1411115029 | H43: =MOD(G43,$H$39) -> 5 | J43: =J37 -> Infra-Memory | K43: =K37 -> 2090387501 | L43: =K43+$E$39 -> 2090387508 | M43: =MOD(L43,$H$39) -> 4
B45: 2 | D45: SALT | E45: =F19 -> 0 | G45: Moduler | H45: =$F$1 -> 8
E46: Address | F46: crc32 | G46: ADD(Time+SLAT) | H46: Space(Mod) | J46: Resource | K46: Hex to int | L46: ADD(Time+SLAT) | M46: Space(Mod)
C47: Peer 1 | D47: 1 | E47: =$C$5 -> x.x.x.10 | F47: =$E$5 -> 975202823 | G47: =F47+$E$45 -> 975202823 | H47: =MOD(G47,$H$45) -> 7 | J47: =$C$10 -> Data-Text | K47: =$E$10 -> 4007243385 | L47: =K47+$E$45 -> 4007243385 | M47: =MOD(L47,$H$45) -> 1
...

Sheet 5-2. Peer 경로(8개) 
A1: 1. Moduler | E1: 8
A3: 2. Peer 기본 정보
C4: ADDR | D4: crc32 | E4: HEX To INT | I4: 동작시간 | K4: UTC to INT | L4: SALT
B5: PEER 1 | C5: x.x.x.10 | D5: 3a206a07 | E5: =HEX2DEC(D5) -> 975202823 | F5: =MOD(E5,$E$1) -> 7 | H5: PEER 1 | I5: 15 Sep 2023 08:48:33 GMT | K5: 1694767713 | L5: =MOD(K5,$E$1) -> 1
B6: PEER 2 | C6: x.x.x.11 | D6: 8d3dab03 | E6: =HEX2DEC(D6) -> 2369628931 | F6: =MOD(E6,$E$1) -> 3 | H6: PEER 2 | I6: 18 Sep 2023 08:56:44 GMT | K6: 1695027404 | L6: =MOD(K6,$E$1) -> 4
B7: PEER 3 | C7: x.x.x.12 | D7: 541be80e | E7: =HEX2DEC(D7) -> 1411115022 | F7: =MOD(E7,$E$1) -> 6 | H7: PEER 3 | I7: 18 Sep 2023 08:56:47 GMT | K7: 1695027407 | L7: =MOD(K7,$E$1) -> 7
B8: PEER 4 | C8: x.x.x.13 | D8: e306290a | E8: =HEX2DEC(D8) -> 3808831754 | F8: =MOD(E8,$E$1) -> 2 | H8: PEER 4 | I8: 18 Sep 2023 08:50:46 GMT | K8: 1695027046 | L8: =MOD(K8,$E$1) -> 6
B9: PEER 5 | C9: x.x.x.14 | D9: e6566e14 | E9: =HEX2DEC(D9) -> 3864423956 | F9: =MOD(E9,$E$1) -> 4 | H9: PEER 5 | I9: 17 Sep 2023 13:20:42 GMT | K9: 1694956842 | L9: =MOD(K9,$E$1) -> 2
B10: PEER 6 | C10: x.x.x.15 | D10: 514baf10 | E10: =HEX2DEC(D10) -> 1363914512 | F10: =MOD(E10,$E$1) -> 0 | H10: PEER 6 | I10: 16 Sep 2023 13:20:35 GMT | K10: 1694870435 | L10: =MOD(K10,$E$1) -> 3
B11: PEER 7 | C11: x.x.x.16 | D11: 886dec1d | E11: =HEX2DEC(D11) -> 2288905245 | F11: =MOD(E11,$E$1) -> 5 | H11: PEER 7 | I11: 16 Sep 2023 12:19:36 GMT | K11: 1694866776 | L11: =MOD(K11,$E$1) -> 0
B12: PEER 8 | C12: x.x.x.17 | D12: 3f702d19 | E12: =HEX2DEC(D12) -> 1064316185 | F12: =MOD(E12,$E$1) -> 1 | H12: PEER 8 | I12: 15 Sep 2023 12:19:41 GMT | K12: 1694780381 | L12: =MOD(K12,$E$1) -> 5
C14: 리소스 | D14: crc32 | E14: HEX To INT | H14: 1회 | I14: 15 Sep 2023 08:48:33 GMT | K14: 1694767713 | L14: =MOD(K14,$E$1) -> 1
B15: PEER 1 | C15: Data-Text | D15: eed9ae79 | E15: =HEX2DEC(D15) -> 4007243385 | F15: =MOD(E15,$E$1) -> 1 | H15: 2회 | I15: 15 Sep 2023 12:19:41 GMT | K15: 1694780381 | L15: =MOD(K15,$E$1) -> 5
B16: PEER 2 | C16: AI-LLM | D16: 2c397047 | E16: =HEX2DEC(D16) -> 741961799 | F16: =MOD(E16,$E$1) -> 7 | H16: 3회 | I16: 16 Sep 2023 12:19:36 GMT | K16: 1694866776 | L16: =MOD(K16,$E$1) -> 0
B17: PEER 3 | C17: Infra-Memory | D17: 7c98c82d | E17: =HEX2DEC(D17) -> 2090387501 | F17: =MOD(E17,$E$1) -> 5 | H17: 4회 | I17: 16 Sep 2023 13:20:35 GMT | K17: 1694870435 | L17: =MOD(K17,$E$1) -> 3
B18: PEER 4 | C18: Data-Picture | D18: b34da9ae | E18: =HEX2DEC(D18) -> 3008211374 | F18: =MOD(E18,$E$1) -> 6 | H18: 5회 | I18: 17 Sep 2023 13:20:42 GMT | K18: 1694956842 | L18: =MOD(K18,$E$1) -> 2
B19: PEER 5 | C19: AI-GAN | D19: 632dea5b | E19: =HEX2DEC(D19) -> 1663953499 | F19: =MOD(E19,$E$1) -> 3 | H19: 6회 | I19: 18 Sep 2023 08:56:44 GMT | K19: 1695027404 | L19: =MOD(K19,$E$1) -> 4
B20: PEER 6 | C20: Infra-STORAGE | D20: 8eaffaaa | E20: =HEX2DEC(D20) -> 2393897642 | F20: =MOD(E20,$E$1) -> 2 | H20: 7회 | I20: 18 Sep 2023 08:56:47 GMT | K20: 1695027407 | L20: =MOD(K20,$E$1) -> 7
B21: PEER 7 | C21: AI-DNN | D21: c2e504e4 | E21: =HEX2DEC(D21) -> 3269788900 | F21: =MOD(E21,$E$1) -> 4 | H21: 8회 | I21: 18 Sep 2023 08:50:46 GMT | K21: 1695027046 | L21: =MOD(K21,$E$1) -> 6
B22: PEER 8 | C22: Data-Doc | D22: f5f174c0 | E22: =HEX2DEC(D22) -> 4126241984 | F22: =MOD(E22,$E$1) -> 0
B24: 3 동작 시간 (https://www.epochconverter.com/)
C25: 동작시간 | E25: UTC to INT | F25: SALT | H25: 각기 다른 동작 시간으로 인해 Salt 값이 다를때
B26: 1회 | C26: 15 Sep 2023 08:48:33 GMT | E26: 1694767713 | F26: =MOD(E26,$E$1) -> 1
B27: 2회 | C27: 15 Sep 2023 12:19:41 GMT | E27: 1694780381 | F27: =MOD(E27,$E$1) -> 5
B28: 3회 | C28: 16 Sep 2023 12:19:36 GMT | E28: 1694866776 | F28: =MOD(E28,$E$1) -> 0
B29: 4회 | C29: 16 Sep 2023 13:20:35 GMT | E29: 1694870435 | F29: =MOD(E29,$E$1) -> 3 | I29: =RANDBETWEEN(0,7) -> 0
B30: 5회 | C30: 17 Sep 2023 13:20:42 GMT | E30: 1694956842 | F30: =MOD(E30,$E$1) -> 2
B31: 6회 | C31: 18 Sep 2023 08:56:44 GMT | E31: 1695027404 | F31: =MOD(E31,$E$1) -> 4
B32: 7회 | C32: 18 Sep 2023 08:56:47 GMT | E32: 1695027407 | F32: =MOD(E32,$E$1) -> 7
B33: 8회 | C33: 18 Sep 2023 08:50:46 GMT | E33: 1695027046 | F33: =MOD(E33,$E$1) -> 6
C34: SALT 1회 | D34: SALT 2회 | E34: SALT 3회 | F34: SALT 4회 | G34: SALT 5회 | H34: SALT 6회 | I34: SALT 7회 | J34: SALT 8회
A35: 1 | B35: PEER 1 | C35: =RANDBETWEEN(0,7) -> 7 | D35: =RANDBETWEEN(0,7) -> 5 | E35: =RANDBETWEEN(0,7) -> 1 | F35: =RANDBETWEEN(0,7) -> 3 | G35: =RANDBETWEEN(0,7) -> 3 | H35: =RANDBETWEEN(0,7) -> 5 | I35: =RANDBETWEEN(0,7) -> 4 | J35: =RANDBETWEEN(0,7) -> 7
B36: PEER 2 | C36: =RANDBETWEEN(0,7) -> 0 | D36: =RANDBETWEEN(0,7) -> 1 | E36: =RANDBETWEEN(0,7) -> 0 | F36: =RANDBETWEEN(0,7) -> 7 | G36: =RANDBETWEEN(0,7) -> 4 | H36: =RANDBETWEEN(0,7) -> 7 | I36: =RANDBETWEEN(0,7) -> 0 | J36: =RANDBETWEEN(0,7) -> 5
B37: PEER 3 | C37: =RANDBETWEEN(0,7) -> 7 | D37: =RANDBETWEEN(0,7) -> 2 | E37: =RANDBETWEEN(0,7) -> 5 | F37: =RANDBETWEEN(0,7) -> 5 | G37: =RANDBETWEEN(0,7) -> 5 | H37: =RANDBETWEEN(0,7) -> 4 | I37: =RANDBETWEEN(0,7) -> 2 | J37: =RANDBETWEEN(0,7) -> 7
B38: PEER 4 | C38: =RANDBETWEEN(0,7) -> 6 | D38: =RANDBETWEEN(0,7) -> 2 | E38: =RANDBETWEEN(0,7) -> 1 | F38: =RANDBETWEEN(0,7) -> 2 | G38: =RANDBETWEEN(0,7) -> 7 | H38: =RANDBETWEEN(0,7) -> 0 | I38: =RANDBETWEEN(0,7) -> 2 | J38: =RANDBETWEEN(0,7) -> 3
B39: PEER 5 | C39: =RANDBETWEEN(0,7) -> 1 | D39: =RANDBETWEEN(0,7) -> 4 | E39: =RANDBETWEEN(0,7) -> 3 | F39: =RANDBETWEEN(0,7) -> 6 | G39: =RANDBETWEEN(0,7) -> 7 | H39: =RANDBETWEEN(0,7) -> 5 | I39: =RANDBETWEEN(0,7) -> 4 | J39: =RANDBETWEEN(0,7) -> 5
B40: PEER 6 | C40: =RANDBETWEEN(0,7) -> 1 | D40: =RANDBETWEEN(0,7) -> 3 | E40: =RANDBETWEEN(0,7) -> 0 | F40: =RANDBETWEEN(0,7) -> 5 | G40: =RANDBETWEEN(0,7) -> 2 | H40: =RANDBETWEEN(0,7) -> 5 | I40: =RANDBETWEEN(0,7) -> 1 | J40: =RANDBETWEEN(0,7) -> 4
B41: PEER 7 | C41: =RANDBETWEEN(0,7) -> 3 | D41: =RANDBETWEEN(0,7) -> 1 | E41: =RANDBETWEEN(0,7) -> 2 | F41: =RANDBETWEEN(0,7) -> 4 | G41: =RANDBETWEEN(0,7) -> 2 | H41: =RANDBETWEEN(0,7) -> 1 | I41: =RANDBETWEEN(0,7) -> 3 | J41: =RANDBETWEEN(0,7) -> 6
B42: PEER 8 | C42: =RANDBETWEEN(0,7) -> 4 | D42: =RANDBETWEEN(0,7) -> 1 | E42: =RANDBETWEEN(0,7) -> 6 | F42: =RANDBETWEEN(0,7) -> 5 | G42: =RANDBETWEEN(0,7) -> 4 | H42: =RANDBETWEEN(0,7) -> 0 | I42: =RANDBETWEEN(0,7) -> 5 | J42: =RANDBETWEEN(0,7) -> 0
A43: 3. 5개의 랜덤…..
...

Sheet 5-2. Peer 경로(8개-ctr)  
A1: 1. Space | E1: 16
A2: Peer | E2: 5
A3: 2. Peer 기본 정보
C4: ADDR | D4: crc32 | E4: HEX To INT | I4: 동작시간 | K4: UTC to INT | L4: SALT
B5: PEER 1 | C5: x.x.x.10 | D5: 3a206a07 | E5: =HEX2DEC(D5) -> 975202823 | F5: =MOD(E5,$E$1) -> 7 | H5: PEER 1 | I5: 15 Sep 2023 08:48:33 GMT | K5: 1694767713 | L5: =MOD(K5,$E$1) -> 1
B6: PEER 2 | C6: x.x.x.11 | D6: 8d3dab03 | E6: =HEX2DEC(D6) -> 2369628931 | F6: =MOD(E6,$E$1) -> 3 | H6: PEER 2 | I6: 18 Sep 2023 08:56:44 GMT | K6: 1695027404 | L6: =MOD(K6,$E$1) -> 12
B7: PEER 3 | C7: x.x.x.12 | D7: 541be80e | E7: =HEX2DEC(D7) -> 1411115022 | F7: =MOD(E7,$E$1) -> 14 | H7: PEER 3 | I7: 18 Sep 2023 08:56:47 GMT | K7: 1695027407 | L7: =MOD(K7,$E$1) -> 15
B8: PEER 4 | C8: x.x.x.13 | D8: e306290a | E8: =HEX2DEC(D8) -> 3808831754 | F8: =MOD(E8,$E$1) -> 10 | H8: PEER 4 | I8: 18 Sep 2023 08:50:46 GMT | K8: 1695027046 | L8: =MOD(K8,$E$1) -> 6
B9: PEER 5 | C9: x.x.x.14 | D9: e6566e14 | E9: =HEX2DEC(D9) -> 3864423956 | F9: =MOD(E9,$E$1) -> 4 | H9: PEER 5 | I9: 17 Sep 2023 13:20:42 GMT | K9: 1694956842 | L9: =MOD(K9,$E$1) -> 10
B10: PEER 6 | C10: x.x.x.15 | D10: 514baf10 | E10: =HEX2DEC(D10) -> 1363914512 | F10: =MOD(E10,$E$1) -> 0 | H10: PEER 6 | I10: 16 Sep 2023 13:20:35 GMT | K10: 1694870435 | L10: =MOD(K10,$E$1) -> 3
B11: PEER 7 | C11: x.x.x.16 | D11: 886dec1d | E11: =HEX2DEC(D11) -> 2288905245 | F11: =MOD(E11,$E$1) -> 13 | H11: PEER 7 | I11: 16 Sep 2023 12:19:36 GMT | K11: 1694866776 | L11: =MOD(K11,$E$1) -> 8
B12: PEER 8 | C12: x.x.x.17 | D12: 3f702d19 | E12: =HEX2DEC(D12) -> 1064316185 | F12: =MOD(E12,$E$1) -> 9 | H12: PEER 8 | I12: 15 Sep 2023 12:19:41 GMT | K12: 1694780381 | L12: =MOD(K12,$E$1) -> 13
C14: 리소스 | D14: crc32 | E14: HEX To INT | H14: 1회 | I14: 15 Sep 2023 08:48:33 GMT | K14: 1694767713 | L14: =MOD(K14,$E$1) -> 1
B15: PEER 1 | C15: Data-Text | D15: eed9ae79 | E15: =HEX2DEC(D15) -> 4007243385 | F15: =MOD(E15,$E$1) -> 9 | H15: 2회 | I15: 15 Sep 2023 12:19:41 GMT | K15: 1694780381 | L15: =MOD(K15,$E$1) -> 13
B16: PEER 2 | C16: AI-LLM | D16: 2c397047 | E16: =HEX2DEC(D16) -> 741961799 | F16: =MOD(E16,$E$1) -> 7 | H16: 3회 | I16: 16 Sep 2023 12:19:36 GMT | K16: 1694866776 | L16: =MOD(K16,$E$1) -> 8
B17: PEER 3 | C17: Infra-Memory | D17: 7c98c82d | E17: =HEX2DEC(D17) -> 2090387501 | F17: =MOD(E17,$E$1) -> 13 | H17: 4회 | I17: 16 Sep 2023 13:20:35 GMT | K17: 1694870435 | L17: =MOD(K17,$E$1) -> 3
B18: PEER 4 | C18: Data-Picture | D18: b34da9ae | E18: =HEX2DEC(D18) -> 3008211374 | F18: =MOD(E18,$E$1) -> 14 | H18: 5회 | I18: 17 Sep 2023 13:20:42 GMT | K18: 1694956842 | L18: =MOD(K18,$E$1) -> 10
B19: PEER 5 | C19: AI-GAN | D19: 632dea5b | E19: =HEX2DEC(D19) -> 1663953499 | F19: =MOD(E19,$E$1) -> 11 | H19: 6회 | I19: 18 Sep 2023 08:56:44 GMT | K19: 1695027404 | L19: =MOD(K19,$E$1) -> 12
B20: PEER 6 | C20: Infra-STORAGE | D20: 8eaffaaa | E20: =HEX2DEC(D20) -> 2393897642 | F20: =MOD(E20,$E$1) -> 10 | H20: 7회 | I20: 18 Sep 2023 08:56:47 GMT | K20: 1695027407 | L20: =MOD(K20,$E$1) -> 15
B21: PEER 7 | C21: AI-DNN | D21: c2e504e4 | E21: =HEX2DEC(D21) -> 3269788900 | F21: =MOD(E21,$E$1) -> 4 | H21: 8회 | I21: 18 Sep 2023 08:50:46 GMT | K21: 1695027046 | L21: =MOD(K21,$E$1) -> 6
B22: PEER 8 | C22: Data-Doc | D22: f5f174c0 | E22: =HEX2DEC(D22) -> 4126241984 | F22: =MOD(E22,$E$1) -> 0
B24: 3 동작 시간 (https://www.epochconverter.com/)
C25: 동작시간 | E25: UTC to INT | F25: SALT | H25: 각기 다른 동작 시간으로 인해 Salt 값이 다를때
B26: 1회 | C26: 15 Sep 2023 08:48:33 GMT | E26: 1694767713 | F26: =MOD(E26,$E$1) -> 1
B27: 2회 | C27: 15 Sep 2023 12:19:41 GMT | E27: 1694780381 | F27: =MOD(E27,$E$1) -> 13
B28: 3회 | C28: 16 Sep 2023 12:19:36 GMT | E28: 1694866776 | F28: =MOD(E28,$E$1) -> 8
B29: 4회 | C29: 16 Sep 2023 13:20:35 GMT | E29: 1694870435 | F29: =MOD(E29,$E$1) -> 3 | I29: =RANDBETWEEN(0,7) -> 6
B30: 5회 | C30: 17 Sep 2023 13:20:42 GMT | E30: 1694956842 | F30: =MOD(E30,$E$1) -> 10
B31: 6회 | C31: 18 Sep 2023 08:56:44 GMT | E31: 1695027404 | F31: =MOD(E31,$E$1) -> 12
B32: 7회 | C32: 18 Sep 2023 08:56:47 GMT | E32: 1695027407 | F32: =MOD(E32,$E$1) -> 15
B33: 8회 | C33: 18 Sep 2023 08:50:46 GMT | E33: 1695027046 | F33: =MOD(E33,$E$1) -> 6
C34: SALT 1회 | D34: SALT 2회 | E34: SALT 3회 | F34: SALT 4회 | G34: SALT 5회 | H34: SALT 6회 | I34: SALT 7회 | J34: SALT 8회
A35: 1 | B35: PEER 1 | C35: =RANDBETWEEN(0,7) -> 4 | D35: =RANDBETWEEN(0,7) -> 4 | E35: =RANDBETWEEN(0,7) -> 3 | F35: =RANDBETWEEN(0,7) -> 0 | G35: =RANDBETWEEN(0,7) -> 6 | H35: =RANDBETWEEN(0,7) -> 5 | I35: =RANDBETWEEN(0,7) -> 1 | J35: =RANDBETWEEN(0,7) -> 6
B36: PEER 2 | C36: =RANDBETWEEN(0,7) -> 0 | D36: =RANDBETWEEN(0,7) -> 1 | E36: =RANDBETWEEN(0,7) -> 7 | F36: =RANDBETWEEN(0,7) -> 5 | G36: =RANDBETWEEN(0,7) -> 4 | H36: =RANDBETWEEN(0,7) -> 4 | I36: =RANDBETWEEN(0,7) -> 0 | J36: =RANDBETWEEN(0,7) -> 4
B37: PEER 3 | C37: =RANDBETWEEN(0,7) -> 5 | D37: =RANDBETWEEN(0,7) -> 4 | E37: =RANDBETWEEN(0,7) -> 3 | F37: =RANDBETWEEN(0,7) -> 6 | G37: =RANDBETWEEN(0,7) -> 7 | H37: =RANDBETWEEN(0,7) -> 5 | I37: =RANDBETWEEN(0,7) -> 6 | J37: =RANDBETWEEN(0,7) -> 1
B38: PEER 4 | C38: =RANDBETWEEN(0,7) -> 1 | D38: =RANDBETWEEN(0,7) -> 4 | E38: =RANDBETWEEN(0,7) -> 3 | F38: =RANDBETWEEN(0,7) -> 2 | G38: =RANDBETWEEN(0,7) -> 1 | H38: =RANDBETWEEN(0,7) -> 1 | I38: =RANDBETWEEN(0,7) -> 6 | J38: =RANDBETWEEN(0,7) -> 4
B39: PEER 5 | C39: =RANDBETWEEN(0,7) -> 2 | D39: =RANDBETWEEN(0,7) -> 5 | E39: =RANDBETWEEN(0,7) -> 4 | F39: =RANDBETWEEN(0,7) -> 5 | G39: =RANDBETWEEN(0,7) -> 5 | H39: =RANDBETWEEN(0,7) -> 0 | I39: =RANDBETWEEN(0,7) -> 0 | J39: =RANDBETWEEN(0,7) -> 3
B40: PEER 6 | C40: =RANDBETWEEN(0,7) -> 3 | D40: =RANDBETWEEN(0,7) -> 4 | E40: =RANDBETWEEN(0,7) -> 2 | F40: =RANDBETWEEN(0,7) -> 5 | G40: =RANDBETWEEN(0,7) -> 4 | H40: =RANDBETWEEN(0,7) -> 5 | I40: =RANDBETWEEN(0,7) -> 1 | J40: =RANDBETWEEN(0,7) -> 5
B41: PEER 7 | C41: =RANDBETWEEN(0,7) -> 0 | D41: =RANDBETWEEN(0,7) -> 6 | E41: =RANDBETWEEN(0,7) -> 1 | F41: =RANDBETWEEN(0,7) -> 1 | G41: =RANDBETWEEN(0,7) -> 4 | H41: =RANDBETWEEN(0,7) -> 1 | I41: =RANDBETWEEN(0,7) -> 7 | J41: =RANDBETWEEN(0,7) -> 6
B42: PEER 8 | C42: =RANDBETWEEN(0,7) -> 1 | D42: =RANDBETWEEN(0,7) -> 2 | E42: =RANDBETWEEN(0,7) -> 3 | F42: =RANDBETWEEN(0,7) -> 5 | G42: =RANDBETWEEN(0,7) -> 3 | H42: =RANDBETWEEN(0,7) -> 3 | I42: =RANDBETWEEN(0,7) -> 4 | J42: =RANDBETWEEN(0,7) -> 5
...

Sheet 6. Peer 경로(개별 CTR, Peer 8)
A1: 1. Space 개수 | F1: 16
A2: 2. Peer 개수 | F2: 8 | G2: 2. Peer 개수
A3: 2. Peer 기본 정보
C4: ADDR | E4: crc32 | F4: HEX To INT | L4: 동작시간 | N4: UTC to INT | O4: SALT
B5: PEER 1 | C5: x.x.x.10 | E5: 3a206a07 | F5: =HEX2DEC(E5) -> 975202823 | G5: =MOD(F5,$F$1) -> 7 | K5: PEER 1 | L5: 15 Sep 2023 08:48:33 GMT | N5: 1694767713 | O5: =MOD(N5,$F$1) -> 1
B6: PEER 2 | C6: x.x.x.11 | E6: 8d3dab03 | F6: =HEX2DEC(E6) -> 2369628931 | G6: =MOD(F6,$F$1) -> 3 | K6: PEER 2 | L6: 18 Sep 2023 08:56:44 GMT | N6: 1695027404 | O6: =MOD(N6,$F$1) -> 12
B7: PEER 3 | C7: x.x.x.12 | E7: 541be80e | F7: =HEX2DEC(E7) -> 1411115022 | G7: =MOD(F7,$F$1) -> 14 | K7: PEER 3 | L7: 18 Sep 2023 08:56:47 GMT | N7: 1695027407 | O7: =MOD(N7,$F$1) -> 15
B8: PEER 4 | C8: x.x.x.13 | E8: e306290a | F8: =HEX2DEC(E8) -> 3808831754 | G8: =MOD(F8,$F$1) -> 10 | K8: PEER 4 | L8: 18 Sep 2023 08:50:46 GMT | N8: 1695027046 | O8: =MOD(N8,$F$1) -> 6
B9: PEER 5 | C9: x.x.x.14 | E9: e6566e14 | F9: =HEX2DEC(E9) -> 3864423956 | G9: =MOD(F9,$F$1) -> 4 | K9: PEER 5 | L9: 17 Sep 2023 13:20:42 GMT | N9: 1694956842 | O9: =MOD(N9,$F$1) -> 10
B10: PEER 6 | C10: x.x.x.15 | E10: 514baf10 | F10: =HEX2DEC(E10) -> 1363914512 | G10: =MOD(F10,$F$1) -> 0 | K10: PEER 6 | L10: 16 Sep 2023 13:20:35 GMT | N10: 1694870435 | O10: =MOD(N10,$F$1) -> 3
B11: PEER 7 | C11: x.x.x.16 | E11: 886dec1d | F11: =HEX2DEC(E11) -> 2288905245 | G11: =MOD(F11,$F$1) -> 13 | K11: PEER 7 | L11: 16 Sep 2023 12:19:36 GMT | N11: 1694866776 | O11: =MOD(N11,$F$1) -> 8
B12: PEER 8 | C12: x.x.x.17 | E12: 3f702d19 | F12: =HEX2DEC(E12) -> 1064316185 | G12: =MOD(F12,$F$1) -> 9 | K12: PEER 8 | L12: 15 Sep 2023 12:19:41 GMT | N12: 1694780381 | O12: =MOD(N12,$F$1) -> 13
A14: 우회 경로는 생김
A15: 경로 전송 횟수가 늘어남
A16: 1회 space 경로 작성 | G16: 사용횟수 | I16: 2회 space 경로 작성 | U16: 사용횟수 | W16: 3회 space 경로 작성 | AO16: 사용횟수 | AQ16: 4회 space 경로 작성 | BI16: 사용횟수 | BK16: 5회 space 경로 작성 | CC16: 사용횟수
A18: PEER | F18: =COUNT(F19:F98)/2 -> 8 | G18: =SUM(G19:G98) -> 8 | I18: PEER | N18: =COUNT(N19:N98)/2 -> 5 | O18: PEER | T18: =COUNT(T19:T98)/2 -> 5 | U18: =SUM(U19:U98) -> 10 | W18: PEER | AB18: =COUNT(AB19:AB98)/2 -> 4 | AC18: PEER | AH18: =COUNT(AH19:AH98)/2 -> 5 | AI18: PEER | AN18: =COUNT(AN19:AN98)/2 -> 4 | AO18: =SUM(AO19:AO98) -> 13 | AQ18: PEER | AV18: =COUNT(AV19:AV98)/2 -> 7 | AW18: PEER | BB18: =COUNT(BB19:BB98)/2 -> 3 | BC18: PEER | BH18: =COUNT(BH19:BH98)/2 -> 4 | BI18: =SUM(BI19:BI98) -> 14 | BK18: PEER | BP18: =COUNT(BP19:BP98)/2 -> 4 | BQ18: PEER | BV18: =COUNT(BV19:BV98)/2 -> 5 | BW18: PEER | CB18: =COUNT(CB19:CB98)/2 -> 3 | CC18: =SUM(CC19:CC98) -> 12
A19: 1 | B19: =O5 -> 1 | C19: CTR | D19: ctr * peer | E19: space 위치 | F19: 경로 순서 | G19: =IF(COUNT(F20:F28) >0, COUNT(F20:F28)/2,"") -> 1 | I19: 1 | K19: CTR | L19: ctr * peer | M19: space 위치 | N19: 경로 순서 | O19: 1 | Q19: CTR | R19: ctr * peer | S19: space 위치 | T19: 경로 순서 | U19: =IF(COUNT(N20:N28,T20:T28) >0, COUNT(N20:N28,T20:T28)/2,"") -> 2 | W19: 1 | Y19: CTR | Z19: ctr * peer | AA19: space 위치 | AB19: 경로 순서 | AC19: 1 | AE19: CTR | AF19: ctr * peer | AG19: space 위치 | AH19: 경로 순서 | AI19: 1 | AK19: CTR | AL19: ctr * peer | AM19: space 위치 | AN19: 경로 순서 | AO19: =IF(COUNT(AB20:AB28,AH20:AH28,AN20:AN28) >0, COUNT(AB20:AB28,AH20:AH28,AN20:AN28) /2,"") -> 3 | AQ19: 1 | AS19: CTR | AT19: ctr * peer | AU19: space 위치 | AV19: 경로 순서 | AW19: 1 | AY19: CTR | AZ19: ctr * peer | BA19: space 위치 | BB19: 경로 순서 | BC19: 1 | BE19: CTR | BF19: ctr * peer | BG19: space 위치 | BH19: 경로 순서 | BI19: =IF(COUNT(AV20:AV28,BB20:BB28,BH20:BH28) >0, COUNT(AV20:AV28,BB20:BB28,BH20:BH28) /2,"") -> 2 | BK19: 1 | BM19: CTR | BN19: ctr * peer | BO19: space 위치 | BP19: 경로 순서 | BQ19: 1 | BS19: CTR | BT19: ctr * peer | BU19: space 위치 | BV19: 경로 순서 | BW19: 1 | BY19: CTR | BZ19: ctr * peer | CA19: space 위치 | CB19: 경로 순서 | CC19: =IF(COUNT(BP20:BP28,BV20:BV28,CB20:CB28) >0, COUNT(BP20:BP28,BV20:BV28,CB20:CB28) /2,"") -> 2
B20: Peer 순서 | C20: 초기값 0 CTR=CTR+1 | D20: 계산 CTR*Peer 수 | E20: 계산 (Addr+SALT+CalCTR) % Space | J20: Peer 순서 | K20: CTR=CTR+1 | L20: 계산 CTR*Peer 수 | M20: 계산 (Addr+SALT+CalCTR) % Space | P20: Peer 순서 | Q20: CTR=CTR+1 | R20: 계산 CTR*Peer 수 | S20: 계산 (Addr+SALT+CalCTR) % Space | X20: Peer 순서 | Y20: CTR=CTR+1 | Z20: 계산 CTR*Peer 수 | AA20: 계산 (Addr+SALT+CalCTR) % Space | AD20: Peer 순서 | AE20: CTR=CTR+1 | AF20: 계산 CTR*Peer 수 | AG20: 계산 (Addr+SALT+CalCTR) % Space | AJ20: Peer 순서 | AK20: CTR=CTR+1 | AL20: 계산 CTR*Peer 수 | AM20: 계산 (Addr+SALT+CalCTR) % Space | AR20: Peer 순서 | AS20: CTR=CTR+1 | AT20: 계산 CTR*Peer 수 | AU20: 계산 (Addr+SALT+CalCTR) % Space | AX20: Peer 순서 | AY20: CTR=CTR+1 | AZ20: 계산 CTR*Peer 수 | BA20: 계산 (Addr+SALT+CalCTR) % Space | BD20: Peer 순서 | BE20: CTR=CTR+1 | BF20: 계산 CTR*Peer 수 | BG20: 계산 (Addr+SALT+CalCTR) % Space | BL20: Peer 순서 | BM20: CTR=CTR+1 | BN20: 계산 CTR*Peer 수 | BO20: 계산 (Addr+SALT+CalCTR) % Space | BR20: Peer 순서 | BS20: CTR=CTR+1 | BT20: 계산 CTR*Peer 수 | BU20: 계산 (Addr+SALT+CalCTR) % Space | BX20: Peer 순서 | BY20: CTR=CTR+1 | BZ20: 계산 CTR*Peer 수 | CA20: 계산 (Addr+SALT+CalCTR) % Space
B21: 1 | C21: 0 | D21: 0 | E21: =MOD($F5+D21+$B$19,$F$1) -> 8 | F21: 1 | J21: 1 | K21: =IF(F21="",C21,IF(F21=MIN(F$21:F$28),C21+1,0)) -> 1 | L21: =K21*$F$2 -> 8 | M21: =MOD($F5+L21+$B$19,$F$1) -> 0 | N21: 1 | P21: 1 | Q21: =IF(N21="",K21,IF(N21=MIN(N$21:N$28),K21+1,0)) -> 2 | R21: =Q21*$F$2 -> 16 | S21: =MOD($F5+R21+$B$19,$F$1) -> 8 | T21: 11 | X21: 1 | Y21: =IF(T21="",Q21,IF(T21=MIN(T$21:T$28),Q21+1,0)) -> 3 | Z21: =Y21*$F$2 -> 24 | AA21: =MOD($F5+Z21+$B$19,$F$1) -> 0 | AB21: 1 | AD21: 1 | AE21: =IF(AB21="",Y21,IF(AB21=MIN(AB$21:AB$28),Y21+1,0)) -> 4 | AF21: =AE21*$F$2 -> 32 | AG21: =MOD($F5+AF21+$B$19,$F$1) -> 8 | AH21: 9 | AJ21: 1 | AK21: =IF(AH21="",AE21,IF(AH21=MIN(AH$21:AH$28),AE21+1,0)) -> 5 | AL21: =AK21*$F$2 -> 40 | AM21: =MOD($F5+AL21+$B$19,$F$1) -> 0 | AN21: 19 | AR21: 1 | AS21: =IF(AN21="",AK21,IF(AN21=MIN(AN$21:AN$28),AK21+1,0)) -> 6 | AT21: =AS21*$F$2 -> 48 | AU21: =MOD($F5+AT21+$B$19,$F$1) -> 8 | AV21: 1 | AX21: 1 | AY21: =IF(AV21="",AS21,IF(AV21=MIN(AV$21:AV$28),AS21+1,0)) -> 7 | AZ21: =AY21*$F$2 -> 56 | BA21: =MOD($F5+AZ21+$B$19,$F$1) -> 0 | BD21: 1 | BE21: =IF(BB21="",AY21,IF(BB21=MIN(BB$21:BB$28),AY21+1,0)) -> 7 | BF21: =BE21*$F$2 -> 56 | BG21: =MOD($F5+BF21+$B$19,$F$1) -> 0 | BH21: 21 | BL21: 1 | BM21: =IF(BH21="",BE21,IF(BH21=MIN(BH$21:BH$28),BE21+1,0)) -> 8 | BN21: =BM21*$F$2 -> 64 | BO21: =MOD($F5+BN21+$B$19,$F$1) -> 8 | BP21: 1 | BR21: 1 | BS21: =IF(BP21="",BM21,IF(BP21=MIN(BP$21:BP$28),BM21+1,0)) -> 9 | BT21: =BS21*$F$2 -> 72 | BU21: =MOD($F5+BT21+$B$19,$F$1) -> 0 | BV21: 9 | BX21: 1 | BY21: =IF(BV21="",BS21,IF(BV21=MIN(BV$21:BV$28),BS21+1,0)) -> 10 | BZ21: =BY21*$F$2 -> 80 | CA21: =MOD($F5+BZ21+$B$19,$F$1) -> 8
B22: 2 | C22: =IF(B22=MIN(B$21:B$28),1,0) -> 0 | D22: 0 | E22: =MOD($F6+D22+$B$19,$F$1) -> 4 | J22: 2 | K22: =IF(F22="",C22,IF(F22=MIN(F$21:F$28),C22+1,0)) -> 0 | L22: =K22*$F$2 -> 0 | M22: =MOD($F6+L22+$B$19,$F$1) -> 4 | P22: 2 | Q22: =IF(N22="",K22,IF(N22=MIN(N$21:N$28),K22+1,0)) -> 0 | R22: =Q22*$F$2 -> 0 | S22: =MOD($F6+R22+$B$19,$F$1) -> 4 | X22: 2 | Y22: =IF(T22="",Q22,IF(T22=MIN(T$21:T$28),Q22+1,0)) -> 0 | Z22: =Y22*$F$2 -> 0 | AA22: =MOD($F6+Z22+$B$19,$F$1) -> 4 | AD22: 2 | AE22: =IF(AB22="",Y22,IF(AB22=MIN(AB$21:AB$28),Y22+1,0)) -> 0 | AF22: =AE22*$F$2 -> 0 | AG22: =MOD($F6+AF22+$B$19,$F$1) -> 4 | AJ22: 2 | AK22: =IF(AH22="",AE22,IF(AH22=MIN(AH$21:AH$28),AE22+1,0)) -> 0 | AL22: =AK22*$F$2 -> 0 | AM22: =MOD($F6+AL22+$B$19,$F$1) -> 4 | AR22: 2 | AS22: =IF(AN22="",AK22,IF(AN22=MIN(AN$21:AN$28),AK22+1,0)) -> 0 | AT22: =AS22*$F$2 -> 0 | AU22: =MOD($F6+AT22+$B$19,$F$1) -> 4 | AX22: 2 | AY22: =IF(AV22="",AS22,IF(AV22=MIN(AV$21:AV$28),AS22+1,0)) -> 0 | AZ22: =AY22*$F$2 -> 0 | BA22: =MOD($F6+AZ22+$B$19,$F$1) -> 4 | BD22: 2 | BE22: =IF(BB22="",AY22,IF(BB22=MIN(BB$21:BB$28),AY22+1,0)) -> 0 | BF22: =BE22*$F$2 -> 0 | BG22: =MOD($F6+BF22+$B$19,$F$1) -> 4 | BL22: 2 | BM22: =IF(BH22="",BE22,IF(BH22=MIN(BH$21:BH$28),BE22+1,0)) -> 0 | BN22: =BM22*$F$2 -> 0 | BO22: =MOD($F6+BN22+$B$19,$F$1) -> 4 | BR22: 2 | BS22: =IF(BP22="",BM22,IF(BP22=MIN(BP$21:BP$28),BM22+1,0)) -> 0 | BT22: =BS22*$F$2 -> 0 | BU22: =MOD($F6+BT22+$B$19,$F$1) -> 4 | BX22: 2 | BY22: =IF(BV22="",BS22,IF(BV22=MIN(BV$21:BV$28),BS22+1,0)) -> 0 | BZ22: =BY22*$F$2 -> 0 | CA22: =MOD($F6+BZ22+$B$19,$F$1) -> 4
B23: 3 | C23: =IF(B23=MIN(B$21:B$28),1,0) -> 0 | D23: 0 | E23: =MOD($F7+D23+$B$19,$F$1) -> 15 | J23: 3 | K23: =IF(F23="",C23,IF(F23=MIN(F$21:F$28),C23+1,0)) -> 0 | L23: =K23*$F$2 -> 0 | M23: =MOD($F7+L23+$B$19,$F$1) -> 15 | P23: 3 | Q23: =IF(N23="",K23,IF(N23=MIN(N$21:N$28),K23+1,0)) -> 0 | R23: =Q23*$F$2 -> 0 | S23: =MOD($F7+R23+$B$19,$F$1) -> 15 | X23: 3 | Y23: =IF(T23="",Q23,IF(T23=MIN(T$21:T$28),Q23+1,0)) -> 0 | Z23: =Y23*$F$2 -> 0 | AA23: =MOD($F7+Z23+$B$19,$F$1) -> 15 | AD23: 3 | AE23: =IF(AB23="",Y23,IF(AB23=MIN(AB$21:AB$28),Y23+1,0)) -> 0 | AF23: =AE23*$F$2 -> 0 | AG23: =MOD($F7+AF23+$B$19,$F$1) -> 15 | AJ23: 3 | AK23: =IF(AH23="",AE23,IF(AH23=MIN(AH$21:AH$28),AE23+1,0)) -> 0 | AL23: =AK23*$F$2 -> 0 | AM23: =MOD($F7+AL23+$B$19,$F$1) -> 15 | AR23: 3 | AS23: =IF(AN23="",AK23,IF(AN23=MIN(AN$21:AN$28),AK23+1,0)) -> 0 | AT23: =AS23*$F$2 -> 0 | AU23: =MOD($F7+AT23+$B$19,$F$1) -> 15 | AX23: 3 | AY23: =IF(AV23="",AS23,IF(AV23=MIN(AV$21:AV$28),AS23+1,0)) -> 0 | AZ23: =AY23*$F$2 -> 0 | BA23: =MOD($F7+AZ23+$B$19,$F$1) -> 15 | BD23: 3 | BE23: =IF(BB23="",AY23,IF(BB23=MIN(BB$21:BB$28),AY23+1,0)) -> 0 | BF23: =BE23*$F$2 -> 0 | BG23: =MOD($F7+BF23+$B$19,$F$1) -> 15 | BL23: 3 | BM23: =IF(BH23="",BE23,IF(BH23=MIN(BH$21:BH$28),BE23+1,0)) -> 0 | BN23: =BM23*$F$2 -> 0 | BO23: =MOD($F7+BN23+$B$19,$F$1) -> 15 | BR23: 3 | BS23: =IF(BP23="",BM23,IF(BP23=MIN(BP$21:BP$28),BM23+1,0)) -> 0 | BT23: =BS23*$F$2 -> 0 | BU23: =MOD($F7+BT23+$B$19,$F$1) -> 15 | BX23: 3 | BY23: =IF(BV23="",BS23,IF(BV23=MIN(BV$21:BV$28),BS23+1,0)) -> 0 | BZ23: =BY23*$F$2 -> 0 | CA23: =MOD($F7+BZ23+$B$19,$F$1) -> 15
B24: 4 | C24: =IF(B24=MIN(B$21:B$28),1,0) -> 0 | D24: 0 | E24: =MOD($F8+D24+$B$19,$F$1) -> 11 | J24: 4 | K24: =IF(F24="",C24,IF(F24=MIN(F$21:F$28),C24+1,0)) -> 0 | L24: =K24*$F$2 -> 0 | M24: =MOD($F8+L24+$B$19,$F$1) -> 11 | P24: 4 | Q24: =IF(N24="",K24,IF(N24=MIN(N$21:N$28),K24+1,0)) -> 0 | R24: =Q24*$F$2 -> 0 | S24: =MOD($F8+R24+$B$19,$F$1) -> 11 | X24: 4 | Y24: =IF(T24="",Q24,IF(T24=MIN(T$21:T$28),Q24+1,0)) -> 0 | Z24: =Y24*$F$2 -> 0 | AA24: =MOD($F8+Z24+$B$19,$F$1) -> 11 | AD24: 4 | AE24: =IF(AB24="",Y24,IF(AB24=MIN(AB$21:AB$28),Y24+1,0)) -> 0 | AF24: =AE24*$F$2 -> 0 | AG24: =MOD($F8+AF24+$B$19,$F$1) -> 11 | AJ24: 4 | AK24: =IF(AH24="",AE24,IF(AH24=MIN(AH$21:AH$28),AE24+1,0)) -> 0 | AL24: =AK24*$F$2 -> 0 | AM24: =MOD($F8+AL24+$B$19,$F$1) -> 11 | AR24: 4 | AS24: =IF(AN24="",AK24,IF(AN24=MIN(AN$21:AN$28),AK24+1,0)) -> 0 | AT24: =AS24*$F$2 -> 0 | AU24: =MOD($F8+AT24+$B$19,$F$1) -> 11 | AX24: 4 | AY24: =IF(AV24="",AS24,IF(AV24=MIN(AV$21:AV$28),AS24+1,0)) -> 0 | AZ24: =AY24*$F$2 -> 0 | BA24: =MOD($F8+AZ24+$B$19,$F$1) -> 11 | BD24: 4 | BE24: =IF(BB24="",AY24,IF(BB24=MIN(BB$21:BB$28),AY24+1,0)) -> 0 | BF24: =BE24*$F$2 -> 0 | BG24: =MOD($F8+BF24+$B$19,$F$1) -> 11 | BL24: 4 | BM24: =IF(BH24="",BE24,IF(BH24=MIN(BH$21:BH$28),BE24+1,0)) -> 0 | BN24: =BM24*$F$2 -> 0 | BO24: =MOD($F8+BN24+$B$19,$F$1) -> 11 | BR24: 4 | BS24: =IF(BP24="",BM24,IF(BP24=MIN(BP$21:BP$28),BM24+1,0)) -> 0 | BT24: =BS24*$F$2 -> 0 | BU24: =MOD($F8+BT24+$B$19,$F$1) -> 11 | BX24: 4 | BY24: =IF(BV24="",BS24,IF(BV24=MIN(BV$21:BV$28),BS24+1,0)) -> 0 | BZ24: =BY24*$F$2 -> 0 | CA24: =MOD($F8+BZ24+$B$19,$F$1) -> 11
B25: 5 | C25: =IF(B25=MIN(B$21:B$28),1,0) -> 0 | D25: 0 | E25: =MOD($F9+D25+$B$19,$F$1) -> 5 | J25: 5 | K25: =IF(F25="",C25,IF(F25=MIN(F$21:F$28),C25+1,0)) -> 0 | L25: =K25*$F$2 -> 0 | M25: =MOD($F9+L25+$B$19,$F$1) -> 5 | P25: 5 | Q25: =IF(N25="",K25,IF(N25=MIN(N$21:N$28),K25+1,0)) -> 0 | R25: =Q25*$F$2 -> 0 | S25: =MOD($F9+R25+$B$19,$F$1) -> 5 | X25: 5 | Y25: =IF(T25="",Q25,IF(T25=MIN(T$21:T$28),Q25+1,0)) -> 0 | Z25: =Y25*$F$2 -> 0 | AA25: =MOD($F9+Z25+$B$19,$F$1) -> 5 | AD25: 5 | AE25: =IF(AB25="",Y25,IF(AB25=MIN(AB$21:AB$28),Y25+1,0)) -> 0 | AF25: =AE25*$F$2 -> 0 | AG25: =MOD($F9+AF25+$B$19,$F$1) -> 5 | AJ25: 5 | AK25: =IF(AH25="",AE25,IF(AH25=MIN(AH$21:AH$28),AE25+1,0)) -> 0 | AL25: =AK25*$F$2 -> 0 | AM25: =MOD($F9+AL25+$B$19,$F$1) -> 5 | AR25: 5 | AS25: =IF(AN25="",AK25,IF(AN25=MIN(AN$21:AN$28),AK25+1,0)) -> 0 | AT25: =AS25*$F$2 -> 0 | AU25: =MOD($F9+AT25+$B$19,$F$1) -> 5 | AX25: 5 | AY25: =IF(AV25="",AS25,IF(AV25=MIN(AV$21:AV$28),AS25+1,0)) -> 0 | AZ25: =AY25*$F$2 -> 0 | BA25: =MOD($F9+AZ25+$B$19,$F$1) -> 5 | BD25: 5 | BE25: =IF(BB25="",AY25,IF(BB25=MIN(BB$21:BB$28),AY25+1,0)) -> 0 | BF25: =BE25*$F$2 -> 0 | BG25: =MOD($F9+BF25+$B$19,$F$1) -> 5 | BL25: 5 | BM25: =IF(BH25="",BE25,IF(BH25=MIN(BH$21:BH$28),BE25+1,0)) -> 0 | BN25: =BM25*$F$2 -> 0 | BO25: =MOD($F9+BN25+$B$19,$F$1) -> 5 | BR25: 5 | BS25: =IF(BP25="",BM25,IF(BP25=MIN(BP$21:BP$28),BM25+1,0)) -> 0 | BT25: =BS25*$F$2 -> 0 | BU25: =MOD($F9+BT25+$B$19,$F$1) -> 5 | BX25: 5 | BY25: =IF(BV25="",BS25,IF(BV25=MIN(BV$21:BV$28),BS25+1,0)) -> 0 | BZ25: =BY25*$F$2 -> 0 | CA25: =MOD($F9+BZ25+$B$19,$F$1) -> 5
B26: 6 | C26: =IF(B26=MIN(B$21:B$28),1,0) -> 0 | D26: 0 | E26: =MOD($F10+D26+$B$19,$F$1) -> 1 | J26: 6 | K26: =IF(F26="",C26,IF(F26=MIN(F$21:F$28),C26+1,0)) -> 0 | L26: =K26*$F$2 -> 0 | M26: =MOD($F10+L26+$B$19,$F$1) -> 1 | N26: 2 | P26: 6 | Q26: =IF(N26="",K26,IF(N26=MIN(N$21:N$28),K26+1,0)) -> 0 | R26: =Q26*$F$2 -> 0 | S26: =MOD($F10+R26+$B$19,$F$1) -> 1 | X26: 6 | Y26: =IF(T26="",Q26,IF(T26=MIN(T$21:T$28),Q26+1,0)) -> 0 | Z26: =Y26*$F$2 -> 0 | AA26: =MOD($F10+Z26+$B$19,$F$1) -> 1 | AB26: 2 | AD26: 6 | AE26: =IF(AB26="",Y26,IF(AB26=MIN(AB$21:AB$28),Y26+1,0)) -> 0 | AF26: =AE26*$F$2 -> 0 | AG26: =MOD($F10+AF26+$B$19,$F$1) -> 1 | AJ26: 6 | AK26: =IF(AH26="",AE26,IF(AH26=MIN(AH$21:AH$28),AE26+1,0)) -> 0 | AL26: =AK26*$F$2 -> 0 | AM26: =MOD($F10+AL26+$B$19,$F$1) -> 1 | AN26: 20 | AR26: 6 | AS26: =IF(AN26="",AK26,IF(AN26=MIN(AN$21:AN$28),AK26+1,0)) -> 0 | AT26: =AS26*$F$2 -> 0 | AU26: =MOD($F10+AT26+$B$19,$F$1) -> 1 | AX26: 6 | AY26: =IF(AV26="",AS26,IF(AV26=MIN(AV$21:AV$28),AS26+1,0)) -> 0 | AZ26: =AY26*$F$2 -> 0 | BA26: =MOD($F10+AZ26+$B$19,$F$1) -> 1 | BD26: 6 | BE26: =IF(BB26="",AY26,IF(BB26=MIN(BB$21:BB$28),AY26+1,0)) -> 0 | BF26: =BE26*$F$2 -> 0 | BG26: =MOD($F10+BF26+$B$19,$F$1) -> 1 | BH26: 22 | BL26: 6 | BM26: =IF(BH26="",BE26,IF(BH26=MIN(BH$21:BH$28),BE26+1,0)) -> 0 | BN26: =BM26*$F$2 -> 0 | BO26: =MOD($F10+BN26+$B$19,$F$1) -> 1 | BR26: 6 | BS26: =IF(BP26="",BM26,IF(BP26=MIN(BP$21:BP$28),BM26+1,0)) -> 0 | BT26: =BS26*$F$2 -> 0 | BU26: =MOD($F10+BT26+$B$19,$F$1) -> 1 | BV26: 10 | BX26: 6 | BY26: =IF(BV26="",BS26,IF(BV26=MIN(BV$21:BV$28),BS26+1,0)) -> 0 | BZ26: =BY26*$F$2 -> 0 | CA26: =MOD($F10+BZ26+$B$19,$F$1) -> 1
B27: 7 | C27: =IF(B27=MIN(B$21:B$28),1,0) -> 0 | D27: 0 | E27: =MOD($F11+D27+$B$19,$F$1) -> 14 | J27: 7 | K27: =IF(F27="",C27,IF(F27=MIN(F$21:F$28),C27+1,0)) -> 0 | L27: =K27*$F$2 -> 0 | M27: =MOD($F11+L27+$B$19,$F$1) -> 14 | P27: 7 | Q27: =IF(N27="",K27,IF(N27=MIN(N$21:N$28),K27+1,0)) -> 0 | R27: =Q27*$F$2 -> 0 | S27: =MOD($F11+R27+$B$19,$F$1) -> 14 | X27: 7 | Y27: =IF(T27="",Q27,IF(T27=MIN(T$21:T$28),Q27+1,0)) -> 0 | Z27: =Y27*$F$2 -> 0 | AA27: =MOD($F11+Z27+$B$19,$F$1) -> 14 | AD27: 7 | AE27: =IF(AB27="",Y27,IF(AB27=MIN(AB$21:AB$28),Y27+1,0)) -> 0 | AF27: =AE27*$F$2 -> 0 | AG27: =MOD($F11+AF27+$B$19,$F$1) -> 14 | AJ27: 7 | AK27: =IF(AH27="",AE27,IF(AH27=MIN(AH$21:AH$28),AE27+1,0)) -> 0 | AL27: =AK27*$F$2 -> 0 | AM27: =MOD($F11+AL27+$B$19,$F$1) -> 14 | AR27: 7 | AS27: =IF(AN27="",AK27,IF(AN27=MIN(AN$21:AN$28),AK27+1,0)) -> 0 | AT27: =AS27*$F$2 -> 0 | AU27: =MOD($F11+AT27+$B$19,$F$1) -> 14 | AX27: 7 | AY27: =IF(AV27="",AS27,IF(AV27=MIN(AV$21:AV$28),AS27+1,0)) -> 0 | AZ27: =AY27*$F$2 -> 0 | BA27: =MOD($F11+AZ27+$B$19,$F$1) -> 14 | BD27: 7 | BE27: =IF(BB27="",AY27,IF(BB27=MIN(BB$21:BB$28),AY27+1,0)) -> 0 | BF27: =BE27*$F$2 -> 0 | BG27: =MOD($F11+BF27+$B$19,$F$1) -> 14 | BL27: 7 | BM27: =IF(BH27="",BE27,IF(BH27=MIN(BH$21:BH$28),BE27+1,0)) -> 0 | BN27: =BM27*$F$2 -> 0 | BO27: =MOD($F11+BN27+$B$19,$F$1) -> 14 | BR27: 7 | BS27: =IF(BP27="",BM27,IF(BP27=MIN(BP$21:BP$28),BM27+1,0)) -> 0 | BT27: =BS27*$F$2 -> 0 | BU27: =MOD($F11+BT27+$B$19,$F$1) -> 14 | BX27: 7 | BY27: =IF(BV27="",BS27,IF(BV27=MIN(BV$21:BV$28),BS27+1,0)) -> 0 | BZ27: =BY27*$F$2 -> 0 | CA27: =MOD($F11+BZ27+$B$19,$F$1) -> 14
B28: 8 | C28: =IF(B28=MIN(B$21:B$28),1,0) -> 0 | D28: 0 | E28: =MOD($F12+D28+$B$19,$F$1) -> 10 | F28: 2 | J28: 8 | K28: =IF(F28="",C28,IF(F28=MIN(F$21:F$28),C28+1,0)) -> 0 | L28: =K28*$F$2 -> 0 | M28: =MOD($F12+L28+$B$19,$F$1) -> 10 | P28: 8 | Q28: =IF(N28="",K28,IF(N28=MIN(N$21:N$28),K28+1,0)) -> 0 | R28: =Q28*$F$2 -> 0 | S28: =MOD($F12+R28+$B$19,$F$1) -> 10 | T28: 12 | X28: 8 | Y28: =IF(T28="",Q28,IF(T28=MIN(T$21:T$28),Q28+1,0)) -> 0 | Z28: =Y28*$F$2 -> 0 | AA28: =MOD($F12+Z28+$B$19,$F$1) -> 10 | AD28: 8 | AE28: =IF(AB28="",Y28,IF(AB28=MIN(AB$21:AB$28),Y28+1,0)) -> 0 | AF28: =AE28*$F$2 -> 0 | AG28: =MOD($F12+AF28+$B$19,$F$1) -> 10 | AH28: 10 | AJ28: 8 | AK28: =IF(AH28="",AE28,IF(AH28=MIN(AH$21:AH$28),AE28+1,0)) -> 0 | AL28: =AK28*$F$2 -> 0 | AM28: =MOD($F12+AL28+$B$19,$F$1) -> 10 | AR28: 8 | AS28: =IF(AN28="",AK28,IF(AN28=MIN(AN$21:AN$28),AK28+1,0)) -> 0 | AT28: =AS28*$F$2 -> 0 | AU28: =MOD($F12+AT28+$B$19,$F$1) -> 10 | AV28: 2 | AX28: 8 | AY28: =IF(AV28="",AS28,IF(AV28=MIN(AV$21:AV$28),AS28+1,0)) -> 0 | AZ28: =AY28*$F$2 -> 0 | BA28: =MOD($F12+AZ28+$B$19,$F$1) -> 10 | BD28: 8 | BE28: =IF(BB28="",AY28,IF(BB28=MIN(BB$21:BB$28),AY28+1,0)) -> 0 | BF28: =BE28*$F$2 -> 0 | BG28: =MOD($F12+BF28+$B$19,$F$1) -> 10 | BL28: 8 | BM28: =IF(BH28="",BE28,IF(BH28=MIN(BH$21:BH$28),BE28+1,0)) -> 0 | BN28: =BM28*$F$2 -> 0 | BO28: =MOD($F12+BN28+$B$19,$F$1) -> 10 | BP28: 2 | BR28: 8 | BS28: =IF(BP28="",BM28,IF(BP28=MIN(BP$21:BP$28),BM28+1,0)) -> 0 | BT28: =BS28*$F$2 -> 0 | BU28: =MOD($F12+BT28+$B$19,$F$1) -> 10 | BX28: 8 | BY28: =IF(BV28="",BS28,IF(BV28=MIN(BV$21:BV$28),BS28+1,0)) -> 0 | BZ28: =BY28*$F$2 -> 0 | CA28: =MOD($F12+BZ28+$B$19,$F$1) -> 10
A29: 2 | B29: =O6 -> 12 | C29: CTR | D29: ctr * peer | E29: space 위치 | G29: =IF(COUNT(F30:F38) >0, COUNT(F30:F38)/2,"") -> 1 | I29: 2 | K29: CTR | L29: ctr * peer | M29: space 위치 | O29: 2 | Q29: CTR | R29: ctr * peer | S29: space 위치 | U29: =IF(COUNT(N30:N38,T30:T38) >0, COUNT(N30:N38,T30:T38)/2,"") -> 1 | W29: 2 | Y29: CTR | Z29: ctr * peer | AA29: space 위치 | AC29: 2 | AE29: CTR | AF29: ctr * peer | AG29: space 위치 | AI29: 2 | AK29: =IF(AH29="",AE29,IF(AH29=MIN(AH$21:AH$28),AE29+1,0)) -> CTR | AL29: ctr * peer | AM29: space 위치 | AO29: =IF(COUNT(AB30:AB38,AH30:AH38,AN30:AN38) >0, COUNT(AB30:AB38,AH30:AH38,AN30:AN38) /2,"") -> 2 | AQ29: 2 | AS29: CTR | AT29: ctr * peer | AU29: space 위치 | AW29: 2 | AY29: CTR | AZ29: ctr * peer | BA29: space 위치 | BC29: 2 | BE29: CTR | BF29: ctr * peer | BG29: space 위치 | BI29: =IF(COUNT(AV30:AV38,BB30:BB38,BH30:BH38) >0, COUNT(AV30:AV38,BB30:BB38,BH30:BH38) /2,"") -> 2 | BK29: 2 | BM29: CTR | BN29: ctr * peer | BO29: space 위치 | BQ29: 2 | BS29: CTR | BT29: ctr * peer | BU29: space 위치 | BW29: 2 | BY29: CTR | BZ29: ctr * peer | CA29: space 위치 | CC29: =IF(COUNT(BP30:BP38,BV30:BV38,CB30:CB38) >0, COUNT(BP30:BP38,BV30:BV38,CB30:CB38) /2,"") -> 2
B30: Peer 순서 | C30: 초기값 0 CTR=CTR+1 | D30: 계산 CTR*Peer 수 | E30: 계산 (Addr+SALT+CalCTR) % Space | J30: Peer 순서 | K30: CTR=CTR+1 | L30: 계산 CTR*Peer 수 | M30: 계산 (Addr+SALT+CalCTR) % Space | P30: Peer 순서 | Q30: CTR=CTR+1 | R30: 계산 CTR*Peer 수 | S30: 계산 (Addr+SALT+CalCTR) % Space | X30: Peer 순서 | Y30: CTR=CTR+1 | Z30: 계산 CTR*Peer 수 | AA30: 계산 (Addr+SALT+CalCTR) % Space | AD30: Peer 순서 | AE30: CTR=CTR+1 | AF30: 계산 CTR*Peer 수 | AG30: 계산 (Addr+SALT+CalCTR) % Space | AJ30: Peer 순서 | AK30: =IF(AH30="",AE30,IF(AH30=MIN(AH$21:AH$28),AE30+1,0)) -> CTR=CTR+1 | AL30: 계산 CTR*Peer 수 | AM30: 계산 (Addr+SALT+CalCTR) % Space | AR30: Peer 순서 | AS30: CTR=CTR+1 | AT30: 계산 CTR*Peer 수 | AU30: 계산 (Addr+SALT+CalCTR) % Space | AX30: Peer 순서 | AY30: CTR=CTR+1 | AZ30: 계산 CTR*Peer 수 | BA30: 계산 (Addr+SALT+CalCTR) % Space | BD30: Peer 순서 | BE30: CTR=CTR+1 | BF30: 계산 CTR*Peer 수 | BG30: 계산 (Addr+SALT+CalCTR) % Space | BL30: Peer 순서 | BM30: CTR=CTR+1 | BN30: 계산 CTR*Peer 수 | BO30: 계산 (Addr+SALT+CalCTR) % Space | BR30: Peer 순서 | BS30: CTR=CTR+1 | BT30: 계산 CTR*Peer 수 | BU30: 계산 (Addr+SALT+CalCTR) % Space | BX30: Peer 순서 | BY30: CTR=CTR+1 | BZ30: 계산 CTR*Peer 수 | CA30: 계산 (Addr+SALT+CalCTR) % Space
B31: 1 | C31: 0 | D31: 0 | E31: =MOD($F5+D31+$B$29,$F$1) -> 3 | J31: 1 | K31: =IF(F31="", C31,IF(F31=MIN(F$31:F$38),C31+1,0)) -> 0 | L31: =K31*$F$2 -> 0 | M31: =MOD($F5+L31+$B$29,$F$1) -> 3 | P31: 1 | Q31: =IF(N31="", K31,IF(N31=MIN(N$31:N$38),K31+1,0)) -> 0 | R31: =Q31*$F$2 -> 0 | S31: =MOD($F5+R31+$B$29,$F$1) -> 3 | X31: 1 | Y31: =IF(T31="", Q31,IF(T31=MIN(T$31:T$38),Q31+1,0)) -> 0 | Z31: =Y31*$F$2 -> 0 | AA31: =MOD($F5+Z31+$B$29,$F$1) -> 3 | AD31: 1 | AE31: =IF(AB31="", Y31,IF(AB31=MIN(AB$31:AB$38),Y31+1,0)) -> 0 | AF31: =AE31*$F$2 -> 0 | AG31: =MOD($F5+AF31+$B$29,$F$1) -> 3 | AJ31: 1 | AK31: =IF(AH31="",AE31,IF(AH31=MIN(AH$21:AH$28),AE31+1,0)) -> 0 | AL31: =AK31*$F$2 -> 0 | AM31: =MOD($F5+AL31+$B$29,$F$1) -> 3 | AR31: 1 | AS31: =IF(AN31="", AK31,IF(AN31=MIN(AN$31:AN$38),AK31+1,0)) -> 0 | AT31: =AS31*$F$2 -> 0 | AU31: =MOD($F5+AT31+$B$29,$F$1) -> 3 | AX31: 1 | AY31: =IF(AV31="", AS31,IF(AV31=MIN(AV$31:AV$38),AS31+1,0)) -> 0 | AZ31: =AY31*$F$2 -> 0 | BA31: =MOD($F5+AZ31+$B$29,$F$1) -> 3 | BD31: 1 | BE31: =IF(BB31="", AY31,IF(BB31=MIN(BB$31:BB$38),AY31+1,0)) -> 0 | BF31: =BE31*$F$2 -> 0 | BG31: =MOD($F5+BF31+$B$29,$F$1) -> 3 | BL31: 1 | BM31: =IF(BH31="", BE31,IF(BH31=MIN(BH$31:BH$38),BE31+1,0)) -> 0 | BN31: =BM31*$F$2 -> 0 | BO31: =MOD($F5+BN31+$B$29,$F$1) -> 3 | BR31: 1 | BS31: =IF(BP31="", BM31,IF(BP31=MIN(BP$31:BP$38),BM31+1,0)) -> 0 | BT31: =BS31*$F$2 -> 0 | BU31: =MOD($F5+BT31+$B$29,$F$1) -> 3 | BX31: 1 | BY31: =IF(BV31="", BS31,IF(BV31=MIN(BV$31:BV$38),BS31+1,0)) -> 0 | BZ31: =BY31*$F$2 -> 0 | CA31: =MOD($F5+BZ31+$B$29,$F$1) -> 3
B32: 2 | C32: =IF(B32=MIN(B$21:B$28),1,0) -> 0 | D32: 0 | E32: =MOD($F6+D32+$B$29,$F$1) -> 15 | F32: 13 | J32: 2 | K32: =IF(F32="", C32,IF(F32=MIN(F$31:F$38),C32+1,0)) -> 1 | L32: =K32*$F$2 -> 8 | M32: =MOD($F6+L32+$B$29,$F$1) -> 7 | N32: 7 | P32: 2 | Q32: =IF(N32="", K32,IF(N32=MIN(N$31:N$38),K32+1,0)) -> 2 | R32: =Q32*$F$2 -> 16 | S32: =MOD($F6+R32+$B$29,$F$1) -> 15 | X32: 2 | Y32: =IF(T32="", Q32,IF(T32=MIN(T$31:T$38),Q32+1,0)) -> 2 | Z32: =Y32*$F$2 -> 16 | AA32: =MOD($F6+Z32+$B$29,$F$1) -> 15 | AB32: 5 | AD32: 2 | AE32: =IF(AB32="", Y32,IF(AB32=MIN(AB$31:AB$38),Y32+1,0)) -> 3 | AF32: =AE32*$F$2 -> 24 | AG32: =MOD($F6+AF32+$B$29,$F$1) -> 7 | AH32: 13 | AJ32: 2 | AK32: =IF(AH32="",AE32,IF(AH32=MIN(AH$21:AH$28),AE32+1,0)) -> 0 | AL32: =AK32*$F$2 -> 0 | AM32: =MOD($F6+AL32+$B$29,$F$1) -> 15 | AR32: 2 | AS32: =IF(AN32="", AK32,IF(AN32=MIN(AN$31:AN$38),AK32+1,0)) -> 0 | AT32: =AS32*$F$2 -> 0 | AU32: =MOD($F6+AT32+$B$29,$F$1) -> 15 | AV32: 5 | AX32: 2 | AY32: =IF(AV32="", AS32,IF(AV32=MIN(AV$31:AV$38),AS32+1,0)) -> 1 | AZ32: =AY32*$F$2 -> 8 | BA32: =MOD($F6+AZ32+$B$29,$F$1) -> 7 | BB32: 15 | BD32: 2 | BE32: =IF(BB32="", AY32,IF(BB32=MIN(BB$31:BB$38),AY32+1,0)) -> 2 | BF32: =BE32*$F$2 -> 16 | BG32: =MOD($F6+BF32+$B$29,$F$1) -> 15 | BL32: 2 | BM32: =IF(BH32="", BE32,IF(BH32=MIN(BH$31:BH$38),BE32+1,0)) -> 2 | BN32: =BM32*$F$2 -> 16 | BO32: =MOD($F6+BN32+$B$29,$F$1) -> 15 | BP32: 5 | BR32: 2 | BS32: =IF(BP32="", BM32,IF(BP32=MIN(BP$31:BP$38),BM32+1,0)) -> 3 | BT32: =BS32*$F$2 -> 24 | BU32: =MOD($F6+BT32+$B$29,$F$1) -> 7 | BV32: 13 | BX32: 2 | BY32: =IF(BV32="", BS32,IF(BV32=MIN(BV$31:BV$38),BS32+1,0)) -> 4 | BZ32: =BY32*$F$2 -> 32 | CA32: =MOD($F6+BZ32+$B$29,$F$1) -> 15
