Workbook

Sheet # 1. 정리
B2: A. | C2: 기본 DHT, 10개 노드
C3: USING_PACKET_CNT_FOR_TEST=0
C4: USING_TEST_NODE_IDX=-1
C5: #define DEF_BASE_M 10 | H5: 32
C6: iapl_chord.exe c 6000
C7: 2_SubNode.bat 9
B9: B. | C9: 패킷 기반 DHT, 10개 노드
C10: USING_PACKET_CNT_FOR_TEST=1
C11: USING_TEST_NODE_IDX=-1
C12: #define DEF_BASE_M 10
C13: iapl_chord.exe c 6000
C14: 2_SubNode.bat 9
B16: C. | C16: 패킷 기반 DHT, 10개 노드 (8번 Indx 100번)
C17: USING_PACKET_CNT_FOR_TEST=100
C18: USING_TEST_NODE_IDX=7
C19: #define DEF_BASE_M 10
C20: iapl_chord.exe c 6000
C21: 2_SubNode.bat 9
B23: 노드 | C23: DHT | D23: 패킷기반 | E23: 패킷기반 (단일노드) | F23: 패킷기반 (단일노드)
B24: 127.0.0.1:6000 | C24: =COUNTIF('2. 기본(Node 10개, 랜덤 10번 동작 )'!$E$3:$V$102,B24) -> 10 | D24: =COUNTIF('2. 패킷(Node 10개, 랜덤 10번 동작)'!$E$3:$V$102,B24) -> 10 | E24: =COUNTIF('2. 패킷(Node 10개, 고정 100번 동작)'!$E$3:$V$102,B24) -> 104 | F24: =E24/10 -> 10.4
B25: 127.0.0.1:6001 | C25: =COUNTIF('2. 기본(Node 10개, 랜덤 10번 동작 )'!$E$3:$V$102,B25) -> 1 | D25: =COUNTIF('2. 패킷(Node 10개, 랜덤 10번 동작)'!$E$3:$V$102,B25) -> 1 | E25: =COUNTIF('2. 패킷(Node 10개, 고정 100번 동작)'!$E$3:$V$102,B25) -> 7 | F25: =E25/10 -> 0.7
B26: 127.0.0.1:6002 | C26: =COUNTIF('2. 기본(Node 10개, 랜덤 10번 동작 )'!$E$3:$V$102,B26) -> 1 | D26: =COUNTIF('2. 패킷(Node 10개, 랜덤 10번 동작)'!$E$3:$V$102,B26) -> 5 | E26: =COUNTIF('2. 패킷(Node 10개, 고정 100번 동작)'!$E$3:$V$102,B26) -> 55 | F26: =E26/10 -> 5.5
B27: 127.0.0.1:6003 | C27: =COUNTIF('2. 기본(Node 10개, 랜덤 10번 동작 )'!$E$3:$V$102,B27) -> 1 | D27: =COUNTIF('2. 패킷(Node 10개, 랜덤 10번 동작)'!$E$3:$V$102,B27) -> 6 | E27: =COUNTIF('2. 패킷(Node 10개, 고정 100번 동작)'!$E$3:$V$102,B27) -> 100 | F27: =E27/10 -> 10
B28: 127.0.0.1:6004 | C28: =COUNTIF('2. 기본(Node 10개, 랜덤 10번 동작 )'!$E$3:$V$102,B28) -> 1 | D28: =COUNTIF('2. 패킷(Node 10개, 랜덤 10번 동작)'!$E$3:$V$102,B28) -> 7 | E28: =COUNTIF('2. 패킷(Node 10개, 고정 100번 동작)'!$E$3:$V$102,B28) -> 62 | F28: =E28/10 -> 6.2
B29: 127.0.0.1:6005 | C29: =COUNTIF('2. 기본(Node 10개, 랜덤 10번 동작 )'!$E$3:$V$102,B29) -> 1 | D29: =COUNTIF('2. 패킷(Node 10개, 랜덤 10번 동작)'!$E$3:$V$102,B29) -> 6 | E29: =COUNTIF('2. 패킷(Node 10개, 고정 100번 동작)'!$E$3:$V$102,B29) -> 69 | F29: =E29/10 -> 6.9
B30: 127.0.0.1:6006 | C30: =COUNTIF('2. 기본(Node 10개, 랜덤 10번 동작 )'!$E$3:$V$102,B30) -> 2 | D30: =COUNTIF('2. 패킷(Node 10개, 랜덤 10번 동작)'!$E$3:$V$102,B30) -> 3 | E30: =COUNTIF('2. 패킷(Node 10개, 고정 100번 동작)'!$E$3:$V$102,B30) -> 27 | F30: =E30/10 -> 2.7
B31: 127.0.0.1:6007 | C31: =COUNTIF('2. 기본(Node 10개, 랜덤 10번 동작 )'!$E$3:$V$102,B31) -> 6 | D31: =COUNTIF('2. 패킷(Node 10개, 랜덤 10번 동작)'!$E$3:$V$102,B31) -> 10 | E31: =COUNTIF('2. 패킷(Node 10개, 고정 100번 동작)'!$E$3:$V$102,B31) -> 106 | F31: =E31/10 -> 10.6
B32: 127.0.0.1:6008 | C32: =COUNTIF('2. 기본(Node 10개, 랜덤 10번 동작 )'!$E$3:$V$102,B32) -> 1 | D32: =COUNTIF('2. 패킷(Node 10개, 랜덤 10번 동작)'!$E$3:$V$102,B32) -> 2 | E32: =COUNTIF('2. 패킷(Node 10개, 고정 100번 동작)'!$E$3:$V$102,B32) -> 22 | F32: =E32/10 -> 2.2
B33: 127.0.0.1:6009 | C33: =COUNTIF('2. 기본(Node 10개, 랜덤 10번 동작 )'!$E$3:$V$102,B33) -> 2 | D33: =COUNTIF('2. 패킷(Node 10개, 랜덤 10번 동작)'!$E$3:$V$102,B33) -> 6 | E33: =COUNTIF('2. 패킷(Node 10개, 고정 100번 동작)'!$E$3:$V$102,B33) -> 89 | F33: =E33/10 -> 8.9
B34: 총노드수
C35: =SUM(C24:C34) -> 26 | D35: =SUM(D24:D34) -> 56 | E35: =SUM(E24:E34) -> 641 | F35: =E35/10 -> 64.1
C52: 기본모델 홉수 | D52: 제안모델 홉수
C53: 2 | D53: 2
C54: 2 | D54: 5
C55: 2 | D55: 5
C56: 3 | D56: 16
C57: 4 | D57: 6
C58: 3 | D58: 4 | P58: 노드 10개, 랜덤한 탐색 10번
C59: 3 | D59: 9
C60: 4 | D60: 6
...

Sheet 2. 기본(Node 10개, 랜덤 10번 동작 )
A2: 홉수
A3: =IF(COUNTA(E3:AN3)>0, COUNTA(E3:AN3), "") -> 2 | B3: Node(10) | C3: 0 | D3: 127.0.0.1:6000 -127.0.0.1:6004 | E3: 127.0.0.1:6000 | F3: 127.0.0.1:6004
A4: =IF(COUNTA(E4:AN4)>0, COUNTA(E4:AN4), "") -> 2 | B4: Node(10) | C4: 1 | D4: 127.0.0.1:6000 -127.0.0.1:6005 | E4: 127.0.0.1:6000 | F4: 127.0.0.1:6005
A5: =IF(COUNTA(E5:AN5)>0, COUNTA(E5:AN5), "") -> 2 | B5: Node(10) | C5: 2 | D5: 127.0.0.1:6000 -127.0.0.1:6007 | E5: 127.0.0.1:6000 | F5: 127.0.0.1:6007
A6: =IF(COUNTA(E6:AN6)>0, COUNTA(E6:AN6), "") -> 3 | B6: Node(10) | C6: 3 | D6: 127.0.0.1:6000 -127.0.0.1:6006 | E6: 127.0.0.1:6000 | F6: 127.0.0.1:6007 | G6: 127.0.0.1:6006
A7: =IF(COUNTA(E7:AN7)>0, COUNTA(E7:AN7), "") -> 4 | B7: Node(10) | C7: 4 | D7: 127.0.0.1:6000 -127.0.0.1:6001 | E7: 127.0.0.1:6000 | F7: 127.0.0.1:6007 | G7: 127.0.0.1:6006 | H7: 127.0.0.1:6001
A8: =IF(COUNTA(E8:AN8)>0, COUNTA(E8:AN8), "") -> 3 | B8: Node(10) | C8: 5 | D8: 127.0.0.1:6000 -127.0.0.1:6002 | E8: 127.0.0.1:6000 | F8: 127.0.0.1:6007 | G8: 127.0.0.1:6002
A9: =IF(COUNTA(E9:AN9)>0, COUNTA(E9:AN9), "") -> 3 | B9: Node(10) | C9: 6 | D9: 127.0.0.1:6000 -127.0.0.1:6009 | E9: 127.0.0.1:6000 | F9: 127.0.0.1:6007 | G9: 127.0.0.1:6009
A10: =IF(COUNTA(E10:AN10)>0, COUNTA(E10:AN10), "") -> 4 | B10: Node(10) | C10: 7 | D10: 127.0.0.1:6000 -127.0.0.1:6008 | E10: 127.0.0.1:6000 | F10: 127.0.0.1:6007 | G10: 127.0.0.1:6009 | H10: 127.0.0.1:6008
A11: =IF(COUNTA(E11:AN11)>0, COUNTA(E11:AN11), "") -> 1 | B11: Node(10) | C11: 8 | D11: 127.0.0.1:6000 -127.0.0.1:6000 | E11: 127.0.0.1:6000
A12: =IF(COUNTA(E12:AN12)>0, COUNTA(E12:AN12), "") -> 2 | B12: Node(10) | C12: 9 | D12: 127.0.0.1:6000 -127.0.0.1:6003 | E12: 127.0.0.1:6000 | F12: 127.0.0.1:6003
A13: =IF(COUNTA(E13:AN13)>0, COUNTA(E13:AN13), "")
A14: =IF(COUNTA(E14:AN14)>0, COUNTA(E14:AN14), "")
A15: =IF(COUNTA(E15:AN15)>0, COUNTA(E15:AN15), "")
A16: =IF(COUNTA(E16:AN16)>0, COUNTA(E16:AN16), "")
A17: =IF(COUNTA(E17:AN17)>0, COUNTA(E17:AN17), "")
A18: =IF(COUNTA(E18:AN18)>0, COUNTA(E18:AN18), "")
A19: =IF(COUNTA(E19:AN19)>0, COUNTA(E19:AN19), "")
A20: =IF(COUNTA(E20:AN20)>0, COUNTA(E20:AN20), "")
A21: =IF(COUNTA(E21:AN21)>0, COUNTA(E21:AN21), "")
A22: =IF(COUNTA(E22:AN22)>0, COUNTA(E22:AN22), "")
A23: =IF(COUNTA(E23:AN23)>0, COUNTA(E23:AN23), "")
A24: =IF(COUNTA(E24:AN24)>0, COUNTA(E24:AN24), "")
... A902: =IF(COUNTA(E902:AN902)>0, COUNTA(E902:AN902), "")

Sheet 2. 패킷(Node 10개, 랜덤 10번 동작)
A2: 홉수
A3: =IF(COUNTA(E3:AN3)>0, COUNTA(E3:AN3), "") -> 2 | B3: Node(10) | C3: 0 | D3: 127.0.0.1:6000 -127.0.0.1:6004 | E3: 127.0.0.1:6000 | F3: 127.0.0.1:6004
A4: =IF(COUNTA(E4:AN4)>0, COUNTA(E4:AN4), "") -> 5 | B4: Node(10) | C4: 1 | D4: 127.0.0.1:6000 -127.0.0.1:6005 | E4: 127.0.0.1:6000 | F4: 127.0.0.1:6007 | G4: 127.0.0.1:6003 | H4: 127.0.0.1:6004 | I4: 127.0.0.1:6005
A5: =IF(COUNTA(E5:AN5)>0, COUNTA(E5:AN5), "") -> 5 | B5: Node(10) | C5: 2 | D5: 127.0.0.1:6000 -127.0.0.1:6007 | E5: 127.0.0.1:6000 | F5: 127.0.0.1:6004 | G5: 127.0.0.1:6002 | H5: 127.0.0.1:6005 | I5: 127.0.0.1:6007
A6: =IF(COUNTA(E6:AN6)>0, COUNTA(E6:AN6), "") -> 16 | B6: Node(10) | C6: 3 | D6: 127.0.0.1:6000 -127.0.0.1:6006 | E6: 127.0.0.1:6000 | F6: 127.0.0.1:6005 | G6: 127.0.0.1:6009 | H6: 127.0.0.1:6007 | I6: 127.0.0.1:6002 | J6: 127.0.0.1:6009 | K6: 127.0.0.1:6008 | L6: 127.0.0.1:6007 | M6: 127.0.0.1:6009 | N6: 127.0.0.1:6003 | O6: 127.0.0.1:6004 | P6: 127.0.0.1:6005 | Q6: 127.0.0.1:6007 | R6: 127.0.0.1:6003 | S6: 127.0.0.1:6007 | T6: 127.0.0.1:6006
A7: =IF(COUNTA(E7:AN7)>0, COUNTA(E7:AN7), "") -> 6 | B7: Node(10) | C7: 4 | D7: 127.0.0.1:6000 -127.0.0.1:6001 | E7: 127.0.0.1:6000 | F7: 127.0.0.1:6007 | G7: 127.0.0.1:6002 | H7: 127.0.0.1:6003 | I7: 127.0.0.1:6006 | J7: 127.0.0.1:6001
A8: =IF(COUNTA(E8:AN8)>0, COUNTA(E8:AN8), "") -> 4 | B8: Node(10) | C8: 5 | D8: 127.0.0.1:6000 -127.0.0.1:6002 | E8: 127.0.0.1:6000 | F8: 127.0.0.1:6003 | G8: 127.0.0.1:6004 | H8: 127.0.0.1:6002
A9: =IF(COUNTA(E9:AN9)>0, COUNTA(E9:AN9), "") -> 9 | B9: Node(10) | C9: 6 | D9: 127.0.0.1:6000 -127.0.0.1:6009 | E9: 127.0.0.1:6000 | F9: 127.0.0.1:6004 | G9: 127.0.0.1:6005 | H9: 127.0.0.1:6007 | I9: 127.0.0.1:6006 | J9: 127.0.0.1:6004 | K9: 127.0.0.1:6007 | L9: 127.0.0.1:6002 | M9: 127.0.0.1:6009
A10: =IF(COUNTA(E10:AN10)>0, COUNTA(E10:AN10), "") -> 6 | B10: Node(10) | C10: 7 | D10: 127.0.0.1:6000 -127.0.0.1:6008 | E10: 127.0.0.1:6000 | F10: 127.0.0.1:6005 | G10: 127.0.0.1:6009 | H10: 127.0.0.1:6007 | I10: 127.0.0.1:6009 | J10: 127.0.0.1:6008
A11: =IF(COUNTA(E11:AN11)>0, COUNTA(E11:AN11), "") -> 1 | B11: Node(10) | C11: 8 | D11: 127.0.0.1:6000 -127.0.0.1:6000 | E11: 127.0.0.1:6000
A12: =IF(COUNTA(E12:AN12)>0, COUNTA(E12:AN12), "") -> 2 | B12: Node(10) | C12: 9 | D12: 127.0.0.1:6000 -127.0.0.1:6003 | E12: 127.0.0.1:6000 | F12: 127.0.0.1:6003
A13: =IF(COUNTA(E13:AN13)>0, COUNTA(E13:AN13), "")
A14: =IF(COUNTA(E14:AN14)>0, COUNTA(E14:AN14), "")
A15: =IF(COUNTA(E15:AN15)>0, COUNTA(E15:AN15), "")
A16: =IF(COUNTA(E16:AN16)>0, COUNTA(E16:AN16), "")
A17: =IF(COUNTA(E17:AN17)>0, COUNTA(E17:AN17), "")
A18: =IF(COUNTA(E18:AN18)>0, COUNTA(E18:AN18), "")
A19: =IF(COUNTA(E19:AN19)>0, COUNTA(E19:AN19), "")
A20: =IF(COUNTA(E20:AN20)>0, COUNTA(E20:AN20), "")
A21: =IF(COUNTA(E21:AN21)>0, COUNTA(E21:AN21), "")
A22: =IF(COUNTA(E22:AN22)>0, COUNTA(E22:AN22), "")
A23: =IF(COUNTA(E23:AN23)>0, COUNTA(E23:AN23), "")
A24: =IF(COUNTA(E24:AN24)>0, COUNTA(E24:AN24), "")
... A902: =IF(COUNTA(E902:AN902)>0, COUNTA(E902:AN902), "")

Sheet 2. 패킷(Node 10개, 고정 100번 동작)
A2: 홉수
A3: =IF(COUNTA(E3:AN3)>0, COUNTA(E3:AN3), "") -> 2 | B3: Node(10) | C3: 0 | D3: 127.0.0.1:6000 -127.0.0.1:6003 | E3: 127.0.0.1:6000 | F3: 127.0.0.1:6003
A4: =IF(COUNTA(E4:AN4)>0, COUNTA(E4:AN4), "") -> 4 | B4: Node(10) | C4: 1 | D4: 127.0.0.1:6000 -127.0.0.1:6003 | E4: 127.0.0.1:6000 | F4: 127.0.0.1:6004 | G4: 127.0.0.1:6002 | H4: 127.0.0.1:6003
A5: =IF(COUNTA(E5:AN5)>0, COUNTA(E5:AN5), "") -> 4 | B5: Node(10) | C5: 2 | D5: 127.0.0.1:6000 -127.0.0.1:6003 | E5: 127.0.0.1:6000 | F5: 127.0.0.1:6005 | G5: 127.0.0.1:6009 | H5: 127.0.0.1:6003
A6: =IF(COUNTA(E6:AN6)>0, COUNTA(E6:AN6), "") -> 3 | B6: Node(10) | C6: 3 | D6: 127.0.0.1:6000 -127.0.0.1:6003 | E6: 127.0.0.1:6000 | F6: 127.0.0.1:6007 | G6: 127.0.0.1:6003
A7: =IF(COUNTA(E7:AN7)>0, COUNTA(E7:AN7), "") -> 2 | B7: Node(10) | C7: 4 | D7: 127.0.0.1:6000 -127.0.0.1:6003 | E7: 127.0.0.1:6000 | F7: 127.0.0.1:6003
A8: =IF(COUNTA(E8:AN8)>0, COUNTA(E8:AN8), "") -> 15 | B8: Node(10) | C8: 5 | D8: 127.0.0.1:6000 -127.0.0.1:6003 | E8: 127.0.0.1:6000 | F8: 127.0.0.1:6004 | G8: 127.0.0.1:6005 | H8: 127.0.0.1:6007 | I8: 127.0.0.1:6006 | J8: 127.0.0.1:6009 | K8: 127.0.0.1:6004 | L8: 127.0.0.1:6007 | M8: 127.0.0.1:6002 | N8: 127.0.0.1:6005 | O8: 127.0.0.1:6009 | P8: 127.0.0.1:6007 | Q8: 127.0.0.1:6009 | R8: 127.0.0.1:6008 | S8: 127.0.0.1:6003
A9: =IF(COUNTA(E9:AN9)>0, COUNTA(E9:AN9), "") -> 4 | B9: Node(10) | C9: 6 | D9: 127.0.0.1:6000 -127.0.0.1:6003 | E9: 127.0.0.1:6000 | F9: 127.0.0.1:6005 | G9: 127.0.0.1:6007 | H9: 127.0.0.1:6003
A10: =IF(COUNTA(E10:AN10)>0, COUNTA(E10:AN10), "") -> 7 | B10: Node(10) | C10: 7 | D10: 127.0.0.1:6000 -127.0.0.1:6003 | E10: 127.0.0.1:6000 | F10: 127.0.0.1:6007 | G10: 127.0.0.1:6006 | H10: 127.0.0.1:6004 | I10: 127.0.0.1:6002 | J10: 127.0.0.1:6009 | K10: 127.0.0.1:6003
A11: =IF(COUNTA(E11:AN11)>0, COUNTA(E11:AN11), "") -> 2 | B11: Node(10) | C11: 8 | D11: 127.0.0.1:6000 -127.0.0.1:6003 | E11: 127.0.0.1:6000 | F11: 127.0.0.1:6003
A12: =IF(COUNTA(E12:AN12)>0, COUNTA(E12:AN12), "") -> 8 | B12: Node(10) | C12: 9 | D12: 127.0.0.1:6000 -127.0.0.1:6003 | E12: 127.0.0.1:6000 | F12: 127.0.0.1:6004 | G12: 127.0.0.1:6005 | H12: 127.0.0.1:6009 | I12: 127.0.0.1:6004 | J12: 127.0.0.1:6007 | K12: 127.0.0.1:6002 | L12: 127.0.0.1:6003
A13: =IF(COUNTA(E13:AN13)>0, COUNTA(E13:AN13), "") -> 6 | B13: Node(10) | C13: 10 | D13: 127.0.0.1:6000 -127.0.0.1:6003 | E13: 127.0.0.1:6000 | F13: 127.0.0.1:6005 | G13: 127.0.0.1:6007 | H13: 127.0.0.1:6009 | I13: 127.0.0.1:6007 | J13: 127.0.0.1:6003
A14: =IF(COUNTA(E14:AN14)>0, COUNTA(E14:AN14), "") -> 11 | B14: Node(10) | C14: 11 | D14: 127.0.0.1:6000 -127.0.0.1:6003 | E14: 127.0.0.1:6000 | F14: 127.0.0.1:6007 | G14: 127.0.0.1:6006 | H14: 127.0.0.1:6001 | I14: 127.0.0.1:6009 | J14: 127.0.0.1:6008 | K14: 127.0.0.1:6004 | L14: 127.0.0.1:6002 | M14: 127.0.0.1:6005 | N14: 127.0.0.1:6009 | O14: 127.0.0.1:6003
A15: =IF(COUNTA(E15:AN15)>0, COUNTA(E15:AN15), "") -> 2 | B15: Node(10) | C15: 12 | D15: 127.0.0.1:6000 -127.0.0.1:6003 | E15: 127.0.0.1:6000 | F15: 127.0.0.1:6003
A16: =IF(COUNTA(E16:AN16)>0, COUNTA(E16:AN16), "") -> 11 | B16: Node(10) | C16: 13 | D16: 127.0.0.1:6000 -127.0.0.1:6003 | E16: 127.0.0.1:6000 | F16: 127.0.0.1:6004 | G16: 127.0.0.1:6005 | H16: 127.0.0.1:6007 | I16: 127.0.0.1:6002 | J16: 127.0.0.1:6009 | K16: 127.0.0.1:6004 | L16: 127.0.0.1:6007 | M16: 127.0.0.1:6009 | N16: 127.0.0.1:6007 | O16: 127.0.0.1:6003
A17: =IF(COUNTA(E17:AN17)>0, COUNTA(E17:AN17), "") -> 9 | B17: Node(10) | C17: 14 | D17: 127.0.0.1:6000 -127.0.0.1:6003 | E17: 127.0.0.1:6000 | F17: 127.0.0.1:6005 | G17: 127.0.0.1:6009 | H17: 127.0.0.1:6008 | I17: 127.0.0.1:6005 | J17: 127.0.0.1:6007 | K17: 127.0.0.1:6006 | L17: 127.0.0.1:6002 | M17: 127.0.0.1:6003
A18: =IF(COUNTA(E18:AN18)>0, COUNTA(E18:AN18), "") -> 6 | B18: Node(10) | C18: 15 | D18: 127.0.0.1:6000 -127.0.0.1:6003 | E18: 127.0.0.1:6000 | F18: 127.0.0.1:6007 | G18: 127.0.0.1:6002 | H18: 127.0.0.1:6005 | I18: 127.0.0.1:6009 | J18: 127.0.0.1:6003
A19: =IF(COUNTA(E19:AN19)>0, COUNTA(E19:AN19), "") -> 2 | B19: Node(10) | C19: 16 | D19: 127.0.0.1:6000 -127.0.0.1:6003 | E19: 127.0.0.1:6000 | F19: 127.0.0.1:6003
A20: =IF(COUNTA(E20:AN20)>0, COUNTA(E20:AN20), "") -> 10 | B20: Node(10) | C20: 17 | D20: 127.0.0.1:6000 -127.0.0.1:6003 | E20: 127.0.0.1:6000 | F20: 127.0.0.1:6004 | G20: 127.0.0.1:6002 | H20: 127.0.0.1:6009 | I20: 127.0.0.1:6004 | J20: 127.0.0.1:6005 | K20: 127.0.0.1:6007 | L20: 127.0.0.1:6009 | M20: 127.0.0.1:6007 | N20: 127.0.0.1:6003
A21: =IF(COUNTA(E21:AN21)>0, COUNTA(E21:AN21), "") -> 8 | B21: Node(10) | C21: 18 | D21: 127.0.0.1:6000 -127.0.0.1:6003 | E21: 127.0.0.1:6000 | F21: 127.0.0.1:6005 | G21: 127.0.0.1:6009 | H21: 127.0.0.1:6008 | I21: 127.0.0.1:6007 | J21: 127.0.0.1:6006 | K21: 127.0.0.1:6009 | L21: 127.0.0.1:6003
A22: =IF(COUNTA(E22:AN22)>0, COUNTA(E22:AN22), "") -> 4 | B22: Node(10) | C22: 19 | D22: 127.0.0.1:6000 -127.0.0.1:6003 | E22: 127.0.0.1:6000 | F22: 127.0.0.1:6007 | G22: 127.0.0.1:6002 | H22: 127.0.0.1:6003
A23: =IF(COUNTA(E23:AN23)>0, COUNTA(E23:AN23), "") -> 2 | B23: Node(10) | C23: 20 | D23: 127.0.0.1:6000 -127.0.0.1:6003 | E23: 127.0.0.1:6000 | F23: 127.0.0.1:6003
A24: =IF(COUNTA(E24:AN24)>0, COUNTA(E24:AN24), "") -> 9 | B24: Node(10) | C24: 21 | D24: 127.0.0.1:6000 -127.0.0.1:6003 | E24: 127.0.0.1:6000 | F24: 127.0.0.1:6004 | G24: 127.0.0.1:6007 | H24: 127.0.0.1:6009 | I24: 127.0.0.1:6004 | J24: 127.0.0.1:6002 | K24: 127.0.0.1:6005 | L24: 127.0.0.1:6007 | M24: 127.0.0.1:6003
A25: =IF(COUNTA(E25:AN25)>0, COUNTA(E25:AN25), "") -> 15 | B25: Node(10) | C25: 22 | D25: 127.0.0.1:6000 -127.0.0.1:6003 | E25: 127.0.0.1:6000 | F25: 127.0.0.1:6005 | G25: 127.0.0.1:6009 | H25: 127.0.0.1:6007 | I25: 127.0.0.1:6006 | J25: 127.0.0.1:6004 | K25: 127.0.0.1:6005 | L25: 127.0.0.1:6007 | M25: 127.0.0.1:6002 | N25: 127.0.0.1:6009 | O25: 127.0.0.1:6008 | P25: 127.0.0.1:6000 | Q25: 127.0.0.1:6007 | R25: 127.0.0.1:6009 | S25: 127.0.0.1:6003
A26: =IF(COUNTA(E26:AN26)>0, COUNTA(E26:AN26), "") -> 2 | B26: Node(10) | C26: 23 | D26: 127.0.0.1:6000 -127.0.0.1:6003 | E26: 127.0.0.1:6000 | F26: 127.0.0.1:6003
A27: =IF(COUNTA(E27:AN27)>0, COUNTA(E27:AN27), "") -> 4 | B27: Node(10) | C27: 24 | D27: 127.0.0.1:6000 -127.0.0.1:6003 | E27: 127.0.0.1:6000 | F27: 127.0.0.1:6004 | G27: 127.0.0.1:6007 | H27: 127.0.0.1:6003
A28: =IF(COUNTA(E28:AN28)>0, COUNTA(E28:AN28), "") -> 6 | B28: Node(10) | C28: 25 | D28: 127.0.0.1:6000 -127.0.0.1:6003 | E28: 127.0.0.1:6000 | F28: 127.0.0.1:6005 | G28: 127.0.0.1:6009 | H28: 127.0.0.1:6004 | I28: 127.0.0.1:6002 | J28: 127.0.0.1:6003
A29: =IF(COUNTA(E29:AN29)>0, COUNTA(E29:AN29), "") -> 14 | B29: Node(10) | C29: 26 | D29: 127.0.0.1:6000 -127.0.0.1:6003 | E29: 127.0.0.1:6000 | F29: 127.0.0.1:6007 | G29: 127.0.0.1:6006 | H29: 127.0.0.1:6001 | I29: 127.0.0.1:6004 | J29: 127.0.0.1:6005 | K29: 127.0.0.1:6007 | L29: 127.0.0.1:6002 | M29: 127.0.0.1:6005 | N29: 127.0.0.1:6009 | O29: 127.0.0.1:6007 | P29: 127.0.0.1:6009 | Q29: 127.0.0.1:6008 | R29: 127.0.0.1:6003
A30: =IF(COUNTA(E30:AN30)>0, COUNTA(E30:AN30), "") -> 2 | B30: Node(10) | C30: 27 | D30: 127.0.0.1:6000 -127.0.0.1:6003 | E30: 127.0.0.1:6000 | F30: 127.0.0.1:6003
A31: =IF(COUNTA(E31:AN31)>0, COUNTA(E31:AN31), "") -> 4 | B31: Node(10) | C31: 28 | D31: 127.0.0.1:6000 -127.0.0.1:6003 | E31: 127.0.0.1:6000 | F31: 127.0.0.1:6004 | G31: 127.0.0.1:6007 | H31: 127.0.0.1:6003
A32: =IF(COUNTA(E32:AN32)>0, COUNTA(E32:AN32), "") -> 7 | B32: Node(10) | C32: 29 | D32: 127.0.0.1:6000 -127.0.0.1:6003 | E32: 127.0.0.1:6000 | F32: 127.0.0.1:6005 | G32: 127.0.0.1:6007 | H32: 127.0.0.1:6006 | I32: 127.0.0.1:6002 | J32: 127.0.0.1:6009 | K32: 127.0.0.1:6003
A33: =IF(COUNTA(E33:AN33)>0, COUNTA(E33:AN33), "") -> 4 | B33: Node(10) | C33: 30 | D33: 127.0.0.1:6000 -127.0.0.1:6003 | E33: 127.0.0.1:6000 | F33: 127.0.0.1:6007 | G33: 127.0.0.1:6002 | H33: 127.0.0.1:6003
A34: =IF(COUNTA(E34:AN34)>0, COUNTA(E34:AN34), "") -> 2 | B34: Node(10) | C34: 31 | D34: 127.0.0.1:6000 -127.0.0.1:6003 | E34: 127.0.0.1:6000 | F34: 127.0.0.1:6003
A35: =IF(COUNTA(E35:AN35)>0, COUNTA(E35:AN35), "") -> 11 | B35: Node(10) | C35: 32 | D35: 127.0.0.1:6000 -127.0.0.1:6003 | E35: 127.0.0.1:6000 | F35: 127.0.0.1:6004 | G35: 127.0.0.1:6002 | H35: 127.0.0.1:6005 | I35: 127.0.0.1:6009 | J35: 127.0.0.1:6004 | K35: 127.0.0.1:6005 | L35: 127.0.0.1:6007 | M35: 127.0.0.1:6009 | N35: 127.0.0.1:6007 | O35: 127.0.0.1:6003
A36: =IF(COUNTA(E36:AN36)>0, COUNTA(E36:AN36), "") -> 9 | B36: Node(10) | C36: 33 | D36: 127.0.0.1:6000 -127.0.0.1:6003 | E36: 127.0.0.1:6000 | F36: 127.0.0.1:6005 | G36: 127.0.0.1:6009 | H36: 127.0.0.1:6008 | I36: 127.0.0.1:6004 | J36: 127.0.0.1:6007 | K36: 127.0.0.1:6006 | L36: 127.0.0.1:6009 | M36: 127.0.0.1:6003
A37: =IF(COUNTA(E37:AN37)>0, COUNTA(E37:AN37), "") -> 7 | B37: Node(10) | C37: 34 | D37: 127.0.0.1:6000 -127.0.0.1:6003 | E37: 127.0.0.1:6000 | F37: 127.0.0.1:6007 | G37: 127.0.0.1:6002 | H37: 127.0.0.1:6009 | I37: 127.0.0.1:6004 | J37: 127.0.0.1:6002 | K37: 127.0.0.1:6003
A38: =IF(COUNTA(E38:AN38)>0, COUNTA(E38:AN38), "") -> 2 | B38: Node(10) | C38: 35 | D38: 127.0.0.1:6000 -127.0.0.1:6003 | E38: 127.0.0.1:6000 | F38: 127.0.0.1:6003
A39: =IF(COUNTA(E39:AN39)>0, COUNTA(E39:AN39), "") -> 7 | B39: Node(10) | C39: 36 | D39: 127.0.0.1:6000 -127.0.0.1:6003 | E39: 127.0.0.1:6000 | F39: 127.0.0.1:6004 | G39: 127.0.0.1:6005 | H39: 127.0.0.1:6007 | I39: 127.0.0.1:6009 | J39: 127.0.0.1:6007 | K39: 127.0.0.1:6003
A40: =IF(COUNTA(E40:AN40)>0, COUNTA(E40:AN40), "") -> 13 | B40: Node(10) | C40: 37 | D40: 127.0.0.1:6000 -127.0.0.1:6003 | E40: 127.0.0.1:6000 | F40: 127.0.0.1:6005 | G40: 127.0.0.1:6009 | H40: 127.0.0.1:6008 | I40: 127.0.0.1:6005 | J40: 127.0.0.1:6007 | K40: 127.0.0.1:6006 | L40: 127.0.0.1:6004 | M40: 127.0.0.1:6007 | N40: 127.0.0.1:6002 | O40: 127.0.0.1:6005 | P40: 127.0.0.1:6009 | Q40: 127.0.0.1:6003
A41: =IF(COUNTA(E41:AN41)>0, COUNTA(E41:AN41), "") -> 8 | B41: Node(10) | C41: 38 | D41: 127.0.0.1:6000 -127.0.0.1:6003 | E41: 127.0.0.1:6000 | F41: 127.0.0.1:6007 | G41: 127.0.0.1:6009 | H41: 127.0.0.1:6004 | I41: 127.0.0.1:6002 | J41: 127.0.0.1:6009 | K41: 127.0.0.1:6007 | L41: 127.0.0.1:6003
...

Sheet 3. 패킷(Node 128개, 랜덤 128번 동작)
B2: 홉수 | F2: 1 | G2: 2 | H2: 3 | I2: 4 | J2: 5 | K2: 6 | L2: 7 | M2: 8 | N2: 9 | O2: 10 | P2: 11 | Q2: 12 | R2: 13 | S2: 14 | T2: 15 | U2: 16 | V2: 17 | W2: 18 | X2: 19 | Y2: 20 | Z2: 21 | AA2: 22 | AB2: 23 | AC2: 24 | AD2: 25 | AE2: 26 | AF2: 27 | AG2: 28 | AH2: 29 | AI2: 30 | AJ2: 31 | AK2: 32 | AL2: 33 | AM2: 34 | AN2: 35 | AO2: 36 | AP2: 37 | AQ2: 38 | AR2: 39 | AS2: 40 | AT2: 41 | AU2: 42 | AV2: 43 | AW2: 44 | AX2: 45 | AY2: 46 | AZ2: 47 | BA2: 48 | BB2: 49 | BC2: 50 | BD2: 51 | BE2: 52 | BF2: 53 | BG2: 54 | BH2: 55 | BI2: 56 | BJ2: 57 | BK2: 58 | BL2: 59 | BM2: 60 | BN2: 61 | BO2: 62 | BP2: 63 | BQ2: 64 | BR2: 65 | BS2: 66 | BT2: 67 | BU2: 68 | BV2: 69 | BW2: 70 | BX2: 71 | BY2: 72 | BZ2: 73 | CA2: 74 | CB2: 75 | CC2: 76 | CD2: 77 | CE2: 78 | CF2: 79 | CG2: 80 | CH2: 81 | CI2: 82 | CJ2: 83 | CK2: 84 | CL2: 85 | CM2: 86 | CN2: 87 | CO2: 88 | CP2: 89 | CQ2: 90 | CR2: 91 | CS2: 92 | CT2: 93 | CU2: 94 | CV2: 95 | CW2: 96 | CX2: 97 | CY2: 98 | CZ2: 99 | DA2: 100 | DB2: 101 | DC2: 102 | DD2: 103 | DE2: 104 | DF2: 105 | DG2: 106 | DH2: 107 | DI2: 108 | DJ2: 109 | DK2: 110 | DL2: 111 | DM2: 112 | DN2: 113 | DO2: 114 | DP2: 115 | DQ2: 116 | DR2: 117 | DS2: 118 | DT2: 119 | DU2: 120 | DV2: 121 | DW2: 122 | DX2: 123 | DY2: 124 | DZ2: 125 | EA2: 126 | EB2: 127 | EC2: 128 | ED2: 129 | EE2: 130 | EF2: 131 | EG2: 132 | EH2: 133 | EI2: 134 | EJ2: 135 | EK2: 136 | EL2: 137 | EM2: 138 | EN2: 139 | EO2: 140 | EP2: 141 | EQ2: 142 | ER2: 143 | ES2: 144 | ET2: 145 | EU2: 146 | EV2: 147 | EW2: 148 | EX2: 149 | EY2: 150 | EZ2: 151 | FA2: 152 | FB2: 153 | FC2: 154 | FD2: 155 | FE2: 156 | FF2: 157 | FG2: 158 | FH2: 159 | FI2: 160 | FJ2: 161 | FK2: 162 | FL2: 163 | FM2: 164 | FN2: 165 | FO2: 166 | FP2: 167 | FQ2: 168 | FR2: 169 | FS2: 170 | FT2: 171 | FU2: 172 | FV2: 173 | FW2: 174 | FX2: 175 | FY2: 176 | FZ2: 177 | GA2: 178 | GB2: 179 | GC2: 180 | GD2: 181 | GE2: 182 | GF2: 183 | GG2: 184 | GH2: 185 | GI2: 186 | GJ2: 187 | GK2: 188 | GL2: 189 | GM2: 190 | GN2: 191 | GO2: 192 | GP2: 193 | GQ2: 194 | GR2: 195 | GS2: 196 | GT2: 197 | GU2: 198 | GV2: 199 | GW2: 200 | GX2: 201 | GY2: 202 | GZ2: 203 | HA2: 204 | HB2: 205 | HC2: 206 | HD2: 207 | HE2: 208 | HF2: 209 | HG2: 210 | HH2: 211 | HI2: 212 | HJ2: 213 | HK2: 214 | HL2: 215 | HM2: 216 | HN2: 217 | HO2: 218 | HP2: 219 | HQ2: 220 | HR2: 221 | HS2: 222 | HT2: 223 | HU2: 224 | HV2: 225 | HW2: 226 | HX2: 227 | HY2: 228 | HZ2: 229 | IA2: 230 | IB2: 231 | IC2: 232 | ID2: 233 | IE2: 234 | IF2: 235 | IG2: 236 | IH2: 237 | II2: 238 | IJ2: 239 | IK2: 240 | IL2: 241 | IM2: 242 | IN2: 243 | IO2: 244 | IP2: 245 | IQ2: 246 | IR2: 247 | IS2: 248 | IT2: 249 | IU2: 250 | IV2: 251 | IW2: 252 | IX2: 253 | IY2: 254 | IZ2: 255 | JA2: 256 | JB2: 257 | JC2: 258 | JD2: 259 | JE2: 260 | JF2: 261 | JG2: 262 | JH2: 263 | JI2: 264 | JJ2: 265 | JK2: 266 | JL2: 267 | JM2: 268 | JN2: 269 | JO2: 270 | JP2: 271 | JQ2: 272 | JR2: 273 | JS2: 274 | JT2: 275 | JU2: 276 | JV2: 277 | JW2: 278 | JX2: 279 | JY2: 280 | JZ2: 281 | KA2: 282 | KB2: 283 | KC2: 284 | KD2: 285 | KE2: 286 | KF2: 287 | KG2: 288 | KH2: 289 | KI2: 290 | KJ2: 291 | KK2: 292 | KL2: 293 | KM2: 294 | KN2: 295 | KO2: 296 | KP2: 297 | KQ2: 298 | KR2: 299 | KS2: 300 | KT2: 301 | KU2: 302 | KV2: 303 | KW2: 304 | KX2: 305 | KY2: 306 | KZ2: 307 | LA2: 308 | LB2: 309 | LC2: 310 | LD2: 311 | LE2: 312 | LF2: 313 | LG2: 314 | LH2: 315 | LI2: 316 | LJ2: 317 | LK2: 318 | LL2: 319 | LM2: 320 | LN2: 321 | LO2: 322 | LP2: 323 | LQ2: 324 | LR2: 325 | LS2: 326 | LT2: 327 | LU2: 328 | LV2: 329 | LW2: 330 | LX2: 331 | LY2: 332 | LZ2: 333 | MA2: 334 | MB2: 335 | MC2: 336 | MD2: 337 | ME2: 338 | MF2: 339 | MG2: 340 | MH2: 341 | MI2: 342 | MJ2: 343 | MK2: 344 | ML2: 345 | MM2: 346 | MN2: 347 | MO2: 348 | MP2: 349 | MQ2: 350 | MR2: 351 | MS2: 352 | MT2: 353 | MU2: 354 | MV2: 355 | MW2: 356 | MX2: 357 | MY2: 358 | MZ2: 359 | NA2: 360 | NB2: 361 | NC2: 362 | ND2: 363 | NE2: 364 | NF2: 365 | NG2: 366 | NH2: 367 | NI2: 368 | NJ2: 369 | NK2: 370 | NL2: 371 | NM2: 372 | NN2: 373 | NO2: 374 | NP2: 375 | NQ2: 376 | NR2: 377 | NS2: 378 | NT2: 379 | NU2: 380 | NV2: 381 | NW2: 382 | NX2: 383 | NY2: 384 | NZ2: 385 | OA2: 386 | OB2: 387 | OC2: 388 | OD2: 389 | OE2: 390 | OF2: 391 | OG2: 392 | OH2: 393 | OI2: 394 | OJ2: 395 | OK2: 396 | OL2: 397 | OM2: 398 | ON2: 399 | OO2: 400 | OP2: 401 | OQ2: 402 | OR2: 403 | OS2: 404 | OT2: 405 | OU2: 406 | OV2: 407 | OW2: 408 | OX2: 409 | OY2: 410 | OZ2: 411 | PA2: 412 | PB2: 413 | PC2: 414 | PD2: 415 | PE2: 416 | PF2: 417 | PG2: 418 | PH2: 419 | PI2: 420 | PJ2: 421 | PK2: 422 | PL2: 423 | PM2: 424 | PN2: 425 | PO2: 426 | PP2: 427 | PQ2: 428 | PR2: 429 | PS2: 430 | PT2: 431 | PU2: 432 | PV2: 433 | PW2: 434 | PX2: 435 | PY2: 436 | PZ2: 437 | QA2: 438 | QB2: 439 | QC2: 440 | QD2: 441 | QE2: 442 | QF2: 443 | QG2: 444 | QH2: 445 | QI2: 446 | QJ2: 447 | QK2: 448 | QL2: 449 | QM2: 450 | QN2: 451 | QO2: 452 | QP2: 453 | QQ2: 454 | QR2: 455 | QS2: 456 | QT2: 457 | QU2: 458 | QV2: 459 | QW2: 460 | QX2: 461 | QY2: 462 | QZ2: 463 | RA2: 464 | RB2: 465 | RC2: 466 | RD2: 467 | RE2: 468 | RF2: 469 | RG2: 470 | RH2: 471 | RI2: 472 | RJ2: 473 | RK2: 474 | RL2: 475 | RM2: 476 | RN2: 477 | RO2: 478 | RP2: 479 | RQ2: 480 | RR2: 481 | RS2: 482 | RT2: 483 | RU2: 484 | RV2: 485 | RW2: 486 | RX2: 487 | RY2: 488 | RZ2: 489 | SA2: 490 | SB2: 491 | SC2: 492 | SD2: 493 | SE2: 494 | SF2: 495 | SG2: 496 | SH2: 497 | SI2: 498 | SJ2: 499 | SK2: 500 | SL2: 501 | SM2: 502 | SN2: 503 | SO2: 504 | SP2: 505 | SQ2: 506 | SR2: 507 | SS2: 508 | ST2: 509 | SU2: 510 | SV2: 511 | SW2: 512 | SX2: 513 | SY2: 514 | SZ2: 515 | TA2: 516 | TB2: 517 | TC2: 518 | TD2: 519 | TE2: 520 | TF2: 521 | TG2: 522 | TH2: 523 | TI2: 524 | TJ2: 525 | TK2: 526 | TL2: 527 | TM2: 528 | TN2: 529 | TO2: 530 | TP2: 531 | TQ2: 532 | TR2: 533 | TS2: 534 | TT2: 535 | TU2: 536 | TV2: 537 | TW2: 538 | TX2: 539 | TY2: 540 | TZ2: 541 | UA2: 542 | UB2: 543 | UC2: 544 | UD2: 545 | UE2: 546 | UF2: 547 | UG2: 548 | UH2: 549 | UI2: 550 | UJ2: 551 | UK2: 552 | UL2: 553 | UM2: 554 | UN2: 555 | UO2: 556 | UP2: 557 | UQ2: 558 | UR2: 559 | US2: 560 | UT2: 561 | UU2: 562 | UV2: 563 | UW2: 564 | UX2: 565 | UY2: 566 | UZ2: 567 | VA2: 568 | VB2: 569 | VC2: 570 | VD2: 571 | VE2: 572 | VF2: 573 | VG2: 574 | VH2: 575 | VI2: 576 | VJ2: 577 | VK2: 578 | VL2: 579 | VM2: 580 | VN2: 581 | VO2: 582 | VP2: 583 | VQ2: 584 | VR2: 585 | VS2: 586 | VT2: 587 | VU2: 588 | VV2: 589 | VW2: 590 | VX2: 591 | VY2: 592 | VZ2: 593 | WA2: 594 | WB2: 595 | WC2: 596 | WD2: 597 | WE2: 598 | WF2: 599 | WG2: 600 | WH2: 601 | WI2: 602 | WJ2: 603 | WK2: 604 | WL2: 605 | WM2: 606 | WN2: 607 | WO2: 608 | WP2: 609 | WQ2: 610 | WR2: 611 | WS2: 612 | WT2: 613 | WU2: 614 | WV2: 615 | WW2: 616 | WX2: 617 | WY2: 618 | WZ2: 619 | XA2: 620 | XB2: 621 | XC2: 622 | XD2: 623 | XE2: 624 | XF2: 625 | XG2: 626 | XH2: 627 | XI2: 628 | XJ2: 629 | XK2: 630 | XL2: 631 | XM2: 632 | XN2: 633 | XO2: 634 | XP2: 635 | XQ2: 636 | XR2: 637 | XS2: 638 | XT2: 639 | XU2: 640 | XV2: 641 | XW2: 642 | XX2: 643 | XY2: 644 | XZ2: 645 | YA2: 646 | YB2: 647 | YC2: 648 | YD2: 649 | YE2: 650 | YF2: 651 | YG2: 652 | YH2: 653 | YI2: 654 | YJ2: 655 | YK2: 656 | YL2: 657 | YM2: 658 | YN2: 659 | YO2: 660 | YP2: 661 | YQ2: 662 | YR2: 663 | YS2: 664 | YT2: 665 | YU2: 666 | YV2: 667 | YW2: 668 | YX2: 669 | YY2: 670 | YZ2: 671 | ZA2: 672 | ZB2: 673 | ZC2: 674 | ZD2: 675 | ZE2: 676 | ZF2: 677 | ZG2: 678 | ZH2: 679 | ZI2: 680 | ZJ2: 681 | ZK2: 682 | ZL2: 683 | ZM2: 684 | ZN2: 685 | ZO2: 686 | ZP2: 687 | ZQ2: 688 | ZR2: 689 | ZS2: 690 | ZT2: 691 | ZU2: 692 | ZV2: 693 | ZW2: 694 | ZX2: 695 | ZY2: 696 | ZZ2: 697 | AAA2: 698 | AAB2: 699 | AAC2: 700 | AAD2: 701 | AAE2: 702 | AAF2: 703 | AAG2: 704 | AAH2: 705 | AAI2: 706 | AAJ2: 707 | AAK2: 708 | AAL2: 709 | AAM2: 710 | AAN2: 711 | AAO2: 712 | AAP2: 713 | AAQ2: 714 | AAR2: 715 | AAS2: 716 | AAT2: 717 | AAU2: 718 | AAV2: 719 | AAW2: 720 | AAX2: 721 | AAY2: 722 | AAZ2: 723 | ABA2: 724 | ABB2: 725 | ABC2: 726 | ABD2: 727 | ABE2: 728 | ABF2: 729 | ABG2: 730 | ABH2: 731 | ABI2: 732 | ABJ2: 733 | ABK2: 734 | ABL2: 735 | ABM2: 736 | ABN2: 737 | ABO2: 738 | ABP2: 739 | ABQ2: 740 | ABR2: 741 | ABS2: 742 | ABT2: 743 | ABU2: 744 | ABV2: 745 | ABW2: 746 | ABX2: 747 | ABY2: 748 | ABZ2: 749 | ACA2: 750 | ACB2: 751 | ACC2: 752 | ACD2: 753 | ACE2: 754 | ACF2: 755 | ACG2: 756 | ACH2: 757 | ACI2: 758 | ACJ2: 759 | ACK2: 760 | ACL2: 761 | ACM2: 762 | ACN2: 763 | ACO2: 764 | ACP2: 765 | ACQ2: 766 | ACR2: 767 | ACS2: 768 | ACT2: 769 | ACU2: 770 | ACV2: 771 | ACW2: 772 | ACX2: 773 | ACY2: 774 | ACZ2: 775 | ADA2: 776 | ADB2: 777 | ADC2: 778 | ADD2: 779 | ADE2: 780 | ADF2: 781 | ADG2: 782 | ADH2: 783 | ADI2: 784 | ADJ2: 785 | ADK2: 786 | ADL2: 787 | ADM2: 788 | ADN2: 789 | ADO2: 790 | ADP2: 791 | ADQ2: 792 | ADR2: 793 | ADS2: 794 | ADT2: 795 | ADU2: 796 | ADV2: 797 | ADW2: 798 | ADX2: 799 | ADY2: 800 | ADZ2: 801 | AEA2: 802 | AEB2: 803 | AEC2: 804 | AED2: 805 | AEE2: 806 | AEF2: 807 | AEG2: 808 | AEH2: 809 | AEI2: 810 | AEJ2: 811 | AEK2: 812 | AEL2: 813 | AEM2: 814 | AEN2: 815 | AEO2: 816 | AEP2: 817 | AEQ2: 818 | AER2: 819 | AES2: 820 | AET2: 821 | AEU2: 822 | AEV2: 823 | AEW2: 824 | AEX2: 825 | AEY2: 826 | AEZ2: 827 | AFA2: 828 | AFB2: 829 | AFC2: 830 | AFD2: 831 | AFE2: 832 | AFF2: 833 | AFG2: 834 | AFH2: 835 | AFI2: 836 | AFJ2: 837 | AFK2: 838 | AFL2: 839 | AFM2: 840 | AFN2: 841 | AFO2: 842 | AFP2: 843 | AFQ2: 844 | AFR2: 845 | AFS2: 846 | AFT2: 847 | AFU2: 848 | AFV2: 849 | AFW2: 850 | AFX2: 851 | AFY2: 852 | AFZ2: 853 | AGA2: 854 | AGB2: 855 | AGC2: 856 | AGD2: 857 | AGE2: 858 | AGF2: 859 | AGG2: 860 | AGH2: 861 | AGI2: 862 | AGJ2: 863 | AGK2: 864 | AGL2: 865 | AGM2: 866 | AGN2: 867 | AGO2: 868 | AGP2: 869 | AGQ2: 870 | AGR2: 871 | AGS2: 872 | AGT2: 873 | AGU2: 874 | AGV2: 875 | AGW2: 876 | AGX2: 877 | AGY2: 878 | AGZ2: 879 | AHA2: 880 | AHB2: 881 | AHC2: 882 | AHD2: 883 | AHE2: 884 | AHF2: 885 | AHG2: 886 | AHH2: 887 | AHI2: 888 | AHJ2: 889 | AHK2: 890 | AHL2: 891 | AHM2: 892 | AHN2: 893 | AHO2: 894 | AHP2: 895 | AHQ2: 896 | AHR2: 897 | AHS2: 898 | AHT2: 899 | AHU2: 900 | AHV2: 901 | AHW2: 902 | AHX2: 903 | AHY2: 904 | AHZ2: 905 | AIA2: 906 | AIB2: 907 | AIC2: 908 | AID2: 909 | AIE2: 910 | AIF2: 911 | AIG2: 912 | AIH2: 913 | AII2: 914 | AIJ2: 915 | AIK2: 916 | AIL2: 917 | AIM2: 918 | AIN2: 919 | AIO2: 920 | AIP2: 921 | AIQ2: 922 | AIR2: 923 | AIS2: 924 | AIT2: 925 | AIU2: 926 | AIV2: 927 | AIW2: 928 | AIX2: 929 | AIY2: 930 | AIZ2: 931 | AJA2: 932 | AJB2: 933 | AJC2: 934 | AJD2: 935 | AJE2: 936 | AJF2: 937 | AJG2: 938 | AJH2: 939 | AJI2: 940 | AJJ2: 941 | AJK2: 942 | AJL2: 943 | AJM2: 944 | AJN2: 945 | AJO2: 946 | AJP2: 947 | AJQ2: 948 | AJR2: 949 | AJS2: 950 | AJT2: 951 | AJU2: 952 | AJV2: 953 | AJW2: 954 | AJX2: 955 | AJY2: 956 | AJZ2: 957 | AKA2: 958 | AKB2: 959 | AKC2: 960 | AKD2: 961 | AKE2: 962 | AKF2: 963 | AKG2: 964 | AKH2: 965 | AKI2: 966 | AKJ2: 967 | AKK2: 968 | AKL2: 969 | AKM2: 970 | AKN2: 971 | AKO2: 972 | AKP2: 973 | AKQ2: 974 | AKR2: 975 | AKS2: 976 | AKT2: 977 | AKU2: 978 | AKV2: 979 | AKW2: 980 | AKX2: 981 | AKY2: 982 | AKZ2: 983 | ALA2: 984 | ALB2: 985 | ALC2: 986 | ALD2: 987 | ALE2: 988 | ALF2: 989 | ALG2: 990 | ALH2: 991 | ALI2: 992 | ALJ2: 993 | ALK2: 994 | ALL2: 995 | ALM2: 996 | ALN2: 997 | ALO2: 998 | ALP2: 999 | ALQ2: 1000 | ALR2: 1001
A3: =IF(COUNTIF(E3:ALS3, "*FOUND*") > 0, "", "F") | B3: =IF(COUNTA(F3:AO3)>0, COUNTA(F3:AO3), "") -> 5 | C3: Node(128) | D3: 0 | E3: 127.0.0.1:6000 - 127.0.0.1:6019 | F3: 127.0.0.1:6000 | G3: 127.0.0.1:6061 | H3: 127.0.0.1:6115 | I3: 127.0.0.1:6019 | J3: # FOUND
A4: =IF(COUNTIF(E4:ALS4, "*FOUND*") > 0, "", "F") | B4: =IF(COUNTA(F4:AO4)>0, COUNTA(F4:AO4), "") -> 11 | C4: Node(128) | D4: 1 | E4: 127.0.0.1:6000 - 127.0.0.1:6126 | F4: 127.0.0.1:6000 | G4: 127.0.0.1:6000 | H4: 127.0.0.1:6000 | I4: 127.0.0.1:6109 | J4: 127.0.0.1:6061 | K4: 127.0.0.1:6018 | L4: 127.0.0.1:6078 | M4: 127.0.0.1:6017 | N4: 127.0.0.1:6019 | O4: 127.0.0.1:6126 | P4: # FOUND
A5: =IF(COUNTIF(E5:ALS5, "*FOUND*") > 0, "", "F") | B5: =IF(COUNTA(F5:AO5)>0, COUNTA(F5:AO5), "") -> 6 | C5: Node(128) | D5: 2 | E5: 127.0.0.1:6000 - 127.0.0.1:6041 | F5: 127.0.0.1:6000 | G5: 127.0.0.1:6107 | H5: 127.0.0.1:6054 | I5: 127.0.0.1:6119 | J5: 127.0.0.1:6041 | K5: # FOUND
A6: =IF(COUNTIF(E6:ALS6, "*FOUND*") > 0, "", "F") | B6: =IF(COUNTA(F6:AO6)>0, COUNTA(F6:AO6), "") -> 6 | C6: Node(128) | D6: 3 | E6: 127.0.0.1:6000 - 127.0.0.1:6127 | F6: 127.0.0.1:6000 | G6: 127.0.0.1:6022 | H6: 127.0.0.1:6116 | I6: 127.0.0.1:6126 | J6: 127.0.0.1:6127 | K6: # FOUND
A7: =IF(COUNTIF(E7:ALS7, "*FOUND*") > 0, "", "F") | B7: =IF(COUNTA(F7:AO7)>0, COUNTA(F7:AO7), "") -> 15 | C7: Node(128) | D7: 4 | E7: 127.0.0.1:6000 - 127.0.0.1:6046 | F7: 127.0.0.1:6000 | G7: 127.0.0.1:6081 | H7: 127.0.0.1:6115 | I7: 127.0.0.1:6018 | J7: 127.0.0.1:6018 | K7: 127.0.0.1:6037 | L7: 127.0.0.1:6111 | M7: 127.0.0.1:6017 | N7: 127.0.0.1:6047 | O7: 127.0.0.1:6009 | P7: 127.0.0.1:6110 | Q7: 127.0.0.1:6041 | R7: 127.0.0.1:6127 | S7: 127.0.0.1:6046 | T7: # FOUND
A8: =IF(COUNTIF(E8:ALS8, "*FOUND*") > 0, "", "F") | B8: =IF(COUNTA(F8:AO8)>0, COUNTA(F8:AO8), "") -> 36 | C8: Node(128) | D8: 5 | E8: 127.0.0.1:6000 - 127.0.0.1:6029 | F8: 127.0.0.1:6000 | G8: 127.0.0.1:6071 | H8: 127.0.0.1:6061 | I8: 127.0.0.1:6023 | J8: 127.0.0.1:6055 | K8: 127.0.0.1:6115 | L8: 127.0.0.1:6079 | M8: 127.0.0.1:6013 | N8: 127.0.0.1:6119 | O8: 127.0.0.1:6035 | P8: 127.0.0.1:6071 | Q8: 127.0.0.1:6076 | R8: 127.0.0.1:6057 | S8: 127.0.0.1:6061 | T8: 127.0.0.1:6061 | U8: 127.0.0.1:6055 | V8: 127.0.0.1:6018 | W8: 127.0.0.1:6047 | X8: 127.0.0.1:6047 | Y8: 127.0.0.1:6051 | Z8: 127.0.0.1:6009 | AA8: 127.0.0.1:6020 | AB8: 127.0.0.1:6042 | AC8: 127.0.0.1:6021 | AD8: 127.0.0.1:6119 | AE8: 127.0.0.1:6037 | AF8: 127.0.0.1:6037 | AG8: 127.0.0.1:6047 | AH8: 127.0.0.1:6123 | AI8: 127.0.0.1:6009 | AJ8: 127.0.0.1:6009 | AK8: 127.0.0.1:6006 | AL8: 127.0.0.1:6014 | AM8: 127.0.0.1:6127 | AN8: 127.0.0.1:6074 | AO8: 127.0.0.1:6031 | AP8: 127.0.0.1:6083 | AQ8: 127.0.0.1:6094 | AR8: 127.0.0.1:6119 | AS8: 127.0.0.1:6011 | AT8: 127.0.0.1:6075 | AU8: 127.0.0.1:6126 | AV8: 127.0.0.1:6035 | AW8: 127.0.0.1:6035 | AX8: 127.0.0.1:6076 | AY8: 127.0.0.1:6076 | AZ8: 127.0.0.1:6059 | BA8: 127.0.0.1:6004 | BB8: 127.0.0.1:6054 | BC8: 127.0.0.1:6037 | BD8: 127.0.0.1:6020 | BE8: 127.0.0.1:6020 | BF8: 127.0.0.1:6065 | BG8: 127.0.0.1:6042 | BH8: 127.0.0.1:6120 | BI8: 127.0.0.1:6105 | BJ8: 127.0.0.1:6034 | BK8: 127.0.0.1:6041 | BL8: 127.0.0.1:6074 | BM8: 127.0.0.1:6074 | BN8: 127.0.0.1:6035 | BO8: 127.0.0.1:6059 | BP8: 127.0.0.1:6059 | BQ8: 127.0.0.1:6018 | BR8: 127.0.0.1:6123 | BS8: 127.0.0.1:6123 | BT8: 127.0.0.1:6117 | BU8: 127.0.0.1:6009 | BV8: 127.0.0.1:6042 | BW8: 127.0.0.1:6042 | BX8: 127.0.0.1:6089 | BY8: 127.0.0.1:6094 | BZ8: 127.0.0.1:6035 | CA8: 127.0.0.1:6047 | CB8: 127.0.0.1:6020 | CC8: 127.0.0.1:6077 | CD8: 127.0.0.1:6042 | CE8: 127.0.0.1:6105 | CF8: 127.0.0.1:6106 | CG8: 127.0.0.1:6001 | CH8: 127.0.0.1:6115 | CI8: 127.0.0.1:6085 | CJ8: 127.0.0.1:6119 | CK8: 127.0.0.1:6003 | CL8: 127.0.0.1:6019 | CM8: 127.0.0.1:6074 | CN8: 127.0.0.1:6076 | CO8: 127.0.0.1:6018 | CP8: 127.0.0.1:6120 | CQ8: 127.0.0.1:6120 | CR8: 127.0.0.1:6106 | CS8: 127.0.0.1:6106 | CT8: 127.0.0.1:6050 | CU8: 127.0.0.1:6001 | CV8: 127.0.0.1:6066 | CW8: 127.0.0.1:6013 | CX8: 127.0.0.1:6030 | CY8: 127.0.0.1:6098 | CZ8: 127.0.0.1:6119 | DA8: 127.0.0.1:6119 | DB8: 127.0.0.1:6096 | DC8: 127.0.0.1:6041 | DD8: 127.0.0.1:6035 | DE8: 127.0.0.1:6106 | DF8: 127.0.0.1:6087 | DG8: 127.0.0.1:6001 | DH8: 127.0.0.1:6001 | DI8: 127.0.0.1:6013 | DJ8: 127.0.0.1:6013 | DK8: 127.0.0.1:6012 | DL8: 127.0.0.1:6119 | DM8: 127.0.0.1:6019 | DN8: 127.0.0.1:6076 | DO8: 127.0.0.1:6037 | DP8: 127.0.0.1:6106 | DQ8: 127.0.0.1:6044 | DR8: 127.0.0.1:6001 | DS8: 127.0.0.1:6098 | DT8: 127.0.0.1:6011 | DU8: 127.0.0.1:6011 | DV8: 127.0.0.1:6097 | DW8: 127.0.0.1:6075 | DX8: 127.0.0.1:6101 | DY8: 127.0.0.1:6095 | DZ8: 127.0.0.1:6094 | EA8: 127.0.0.1:6120 | EB8: 127.0.0.1:6044 | EC8: 127.0.0.1:6044 | ED8: 127.0.0.1:6066 | EE8: 127.0.0.1:6066 | EF8: 127.0.0.1:6068 | EG8: 127.0.0.1:6013 | EH8: 127.0.0.1:6098 | EI8: 127.0.0.1:6098 | EJ8: 127.0.0.1:6103 | EK8: 127.0.0.1:6019 | EL8: 127.0.0.1:6051 | EM8: 127.0.0.1:6051 | EN8: 127.0.0.1:6123 | EO8: 127.0.0.1:6020 | EP8: 127.0.0.1:6082 | EQ8: 127.0.0.1:6042 | ER8: 127.0.0.1:6001 | ES8: 127.0.0.1:6040 | ET8: 127.0.0.1:6019 | EU8: 127.0.0.1:6011 | EV8: 127.0.0.1:6101 | EW8: 127.0.0.1:6101 | EX8: 127.0.0.1:6048 | EY8: 127.0.0.1:6083 | EZ8: 127.0.0.1:6035 | FA8: 127.0.0.1:6010 | FB8: 127.0.0.1:6052 | FC8: 127.0.0.1:6034 | FD8: 127.0.0.1:6076 | FE8: 127.0.0.1:6020 | FF8: 127.0.0.1:6118 | FG8: 127.0.0.1:6042 | FH8: 127.0.0.1:6012 | FI8: 127.0.0.1:6030 | FJ8: 127.0.0.1:6030 | FK8: 127.0.0.1:6011 | FL8: 127.0.0.1:6048 | FM8: 127.0.0.1:6048 | FN8: 127.0.0.1:6036 | FO8: 127.0.0.1:6052 | FP8: 127.0.0.1:6076 | FQ8: 127.0.0.1:6044 | FR8: 127.0.0.1:6079 | FS8: 127.0.0.1:6079 | FT8: 127.0.0.1:6030 | FU8: 127.0.0.1:6048 | FV8: 127.0.0.1:6010 | FW8: 127.0.0.1:6010 | FX8: 127.0.0.1:6099 | FY8: 127.0.0.1:6061 | FZ8: 127.0.0.1:6054 | GA8: 127.0.0.1:6026 | GB8: 127.0.0.1:6017 | GC8: 127.0.0.1:6022 | GD8: 127.0.0.1:6022 | GE8: 127.0.0.1:6049 | GF8: 127.0.0.1:6110 | GG8: 127.0.0.1:6020 | GH8: 127.0.0.1:6120 | GI8: 127.0.0.1:6011 | GJ8: 127.0.0.1:6027 | GK8: 127.0.0.1:6061 | GL8: 127.0.0.1:6017 | GM8: 127.0.0.1:6017 | GN8: 127.0.0.1:6067 | GO8: 127.0.0.1:6019 | GP8: 127.0.0.1:6092 | GQ8: 127.0.0.1:6127 | GR8: 127.0.0.1:6035 | GS8: 127.0.0.1:6071 | GT8: 127.0.0.1:6071 | GU8: 127.0.0.1:6057 | GV8: 127.0.0.1:6059 | GW8: 127.0.0.1:6037 | GX8: 127.0.0.1:6011 | GY8: 127.0.0.1:6049 | GZ8: 127.0.0.1:6049 | HA8: 127.0.0.1:6038 | HB8: 127.0.0.1:6014 | HC8: 127.0.0.1:6020 | HD8: 127.0.0.1:6106 | HE8: 127.0.0.1:6068 | HF8: 127.0.0.1:6068 | HG8: 127.0.0.1:6079 | HH8: 127.0.0.1:6011 | HI8: 127.0.0.1:6092 | HJ8: 127.0.0.1:6092 | HK8: 127.0.0.1:6080 | HL8: 127.0.0.1:6127 | HM8: 127.0.0.1:6076 | HN8: 127.0.0.1:6109 | HO8: 127.0.0.1:6109 | HP8: 127.0.0.1:6023 | HQ8: 127.0.0.1:6023 | HR8: 127.0.0.1:6090 | HS8: 127.0.0.1:6055 | HT8: 127.0.0.1:6056 | HU8: 127.0.0.1:6054 | HV8: 127.0.0.1:6054 | HW8: 127.0.0.1:6017 | HX8: 127.0.0.1:6116 | HY8: 127.0.0.1:6123 | HZ8: 127.0.0.1:6077 | IA8: 127.0.0.1:6077 | IB8: 127.0.0.1:6082 | IC8: 127.0.0.1:6082 | ID8: 127.0.0.1:6118 | IE8: 127.0.0.1:6118 | IF8: 127.0.0.1:6120 | IG8: 127.0.0.1:6036 | IH8: 127.0.0.1:6036 | II8: 127.0.0.1:6010 | IJ8: 127.0.0.1:6000 | IK8: 127.0.0.1:6061 | IL8: 127.0.0.1:6100 | IM8: 127.0.0.1:6127 | IN8: 127.0.0.1:6018 | IO8: 127.0.0.1:6030 | IP8: 127.0.0.1:6026 | IQ8: 127.0.0.1:6026 | IR8: 127.0.0.1:6064 | IS8: 127.0.0.1:6017 | IT8: 127.0.0.1:6110 | IU8: 127.0.0.1:6038 | IV8: 127.0.0.1:6038 | IW8: 127.0.0.1:6091 | IX8: 127.0.0.1:6100 | IY8: 127.0.0.1:6082 | IZ8: 127.0.0.1:6120 | JA8: 127.0.0.1:6104 | JB8: 127.0.0.1:6034 | JC8: 127.0.0.1:6044 | JD8: 127.0.0.1:6030 | JE8: 127.0.0.1:6015 | JF8: 127.0.0.1:6119 | JG8: 127.0.0.1:6041 | JH8: 127.0.0.1:6059 | JI8: 127.0.0.1:6047 | JJ8: 127.0.0.1:6118 | JK8: 127.0.0.1:6106 | JL8: 127.0.0.1:6011 | JM8: 127.0.0.1:6075 | JN8: 127.0.0.1:6075 | JO8: 127.0.0.1:6112 | JP8: 127.0.0.1:6041 | JQ8: 127.0.0.1:6020 | JR8: 127.0.0.1:6066 | JS8: 127.0.0.1:6079 | JT8: 127.0.0.1:6101 | JU8: 127.0.0.1:6036 | JV8: 127.0.0.1:6099 | JW8: 127.0.0.1:6099 | JX8: 127.0.0.1:6000 | JY8: 127.0.0.1:6000 | JZ8: 127.0.0.1:6027 | KA8: 127.0.0.1:6027 | KB8: 127.0.0.1:6109 | KC8: 127.0.0.1:6056 | KD8: 127.0.0.1:6056 | KE8: 127.0.0.1:6107 | KF8: 127.0.0.1:6107 | KG8: 127.0.0.1:6026 | KH8: 127.0.0.1:6114 | KI8: 127.0.0.1:6017 | KJ8: 127.0.0.1:6072 | KK8: 127.0.0.1:6029 | KL8: # FOUND
A9: =IF(COUNTIF(E9:ALS9, "*FOUND*") > 0, "", "F") | B9: =IF(COUNTA(F9:AO9)>0, COUNTA(F9:AO9), "") -> 36 | C9: Node(128) | D9: 6 | E9: 127.0.0.1:6000 - 127.0.0.1:6074 | F9: 127.0.0.1:6000 | G9: 127.0.0.1:6109 | H9: 127.0.0.1:6107 | I9: 127.0.0.1:6064 | J9: 127.0.0.1:6064 | K9: 127.0.0.1:6114 | L9: 127.0.0.1:6114 | M9: 127.0.0.1:6069 | N9: 127.0.0.1:6017 | O9: 127.0.0.1:6034 | P9: 127.0.0.1:6081 | Q9: 127.0.0.1:6081 | R9: 127.0.0.1:6085 | S9: 127.0.0.1:6085 | T9: 127.0.0.1:6015 | U9: 127.0.0.1:6015 | V9: 127.0.0.1:6003 | W9: 127.0.0.1:6003 | X9: 127.0.0.1:6092 | Y9: 127.0.0.1:6024 | Z9: 127.0.0.1:6127 | AA9: 127.0.0.1:6101 | AB9: 127.0.0.1:6000 | AC9: 127.0.0.1:6107 | AD9: 127.0.0.1:6114 | AE9: 127.0.0.1:6070 | AF9: 127.0.0.1:6017 | AG9: 127.0.0.1:6019 | AH9: 127.0.0.1:6126 | AI9: 127.0.0.1:6076 | AJ9: 127.0.0.1:6057 | AK9: 127.0.0.1:6057 | AL9: 127.0.0.1:6004 | AM9: 127.0.0.1:6018 | AN9: 127.0.0.1:6107 | AO9: 127.0.0.1:6070 | AP9: 127.0.0.1:6070 | AQ9: 127.0.0.1:6022 | AR9: 127.0.0.1:6038 | AS9: 127.0.0.1:6043 | AT9: 127.0.0.1:6072 | AU9: 127.0.0.1:6120 | AV9: 127.0.0.1:6105 | AW9: 127.0.0.1:6105 | AX9: 127.0.0.1:6084 | AY9: 127.0.0.1:6034 | AZ9: 127.0.0.1:6034 | BA9: 127.0.0.1:6124 | BB9: 127.0.0.1:6041 | BC9: 127.0.0.1:6092 | BD9: 127.0.0.1:6108 | BE9: 127.0.0.1:6074 | BF9: # FOUND
A10: =IF(COUNTIF(E10:ALS10, "*FOUND*") > 0, "", "F") | B10: =IF(COUNTA(F10:AO10)>0, COUNTA(F10:AO10), "") -> 8 | C10: Node(128) | D10: 7 | E10: 127.0.0.1:6000 - 127.0.0.1:6035 | F10: 127.0.0.1:6000 | G10: 127.0.0.1:6022 | H10: 127.0.0.1:6125 | I10: 127.0.0.1:6094 | J10: 127.0.0.1:6094 | K10: 127.0.0.1:6016 | L10: 127.0.0.1:6035 | M10: # FOUND
A11: =IF(COUNTIF(E11:ALS11, "*FOUND*") > 0, "", "F") | B11: =IF(COUNTA(F11:AO11)>0, COUNTA(F11:AO11), "") -> 36 | C11: Node(128) | D11: 8 | E11: 127.0.0.1:6000 - 127.0.0.1:6076 | F11: 127.0.0.1:6000 | G11: 127.0.0.1:6081 | H11: 127.0.0.1:6003 | I11: 127.0.0.1:6071 | J11: 127.0.0.1:6025 | K11: 127.0.0.1:6017 | L11: 127.0.0.1:6047 | M11: 127.0.0.1:6044 | N11: 127.0.0.1:6011 | O11: 127.0.0.1:6011 | P11: 127.0.0.1:6097 | Q11: 127.0.0.1:6097 | R11: 127.0.0.1:6101 | S11: 127.0.0.1:6107 | T11: 127.0.0.1:6022 | U11: 127.0.0.1:6081 | V11: 127.0.0.1:6092 | W11: 127.0.0.1:6122 | X11: 127.0.0.1:6035 | Y11: 127.0.0.1:6059 | Z11: 127.0.0.1:6020 | AA11: 127.0.0.1:6101 | AB11: 127.0.0.1:6045 | AC11: 127.0.0.1:6072 | AD11: 127.0.0.1:6125 | AE11: 127.0.0.1:6125 | AF11: 127.0.0.1:6104 | AG11: 127.0.0.1:6104 | AH11: 127.0.0.1:6063 | AI11: 127.0.0.1:6034 | AJ11: 127.0.0.1:6119 | AK11: 127.0.0.1:6037 | AL11: 127.0.0.1:6114 | AM11: 127.0.0.1:6022 | AN11: 127.0.0.1:6092 | AO11: 127.0.0.1:6071 | AP11: 127.0.0.1:6009 | AQ11: 127.0.0.1:6105 | AR11: 127.0.0.1:6001 | AS11: 127.0.0.1:6086 | AT11: 127.0.0.1:6127 | AU11: 127.0.0.1:6046 | AV11: 127.0.0.1:6076 | AW11: # FOUND
A12: =IF(COUNTIF(E12:ALS12, "*FOUND*") > 0, "", "F") | B12: =IF(COUNTA(F12:AO12)>0, COUNTA(F12:AO12), "") -> 36 | C12: Node(128) | D12: 9 | E12: 127.0.0.1:6000 - 127.0.0.1:6059 | F12: 127.0.0.1:6000 | G12: 127.0.0.1:6071 | H12: 127.0.0.1:6001 | I12: 127.0.0.1:6061 | J12: 127.0.0.1:6115 | K12: 127.0.0.1:6115 | L12: 127.0.0.1:6119 | M12: 127.0.0.1:6011 | N12: 127.0.0.1:6101 | O12: 127.0.0.1:6108 | P12: 127.0.0.1:6108 | Q12: 127.0.0.1:6031 | R12: 127.0.0.1:6031 | S12: 127.0.0.1:6002 | T12: 127.0.0.1:6035 | U12: 127.0.0.1:6106 | V12: 127.0.0.1:6099 | W12: 127.0.0.1:6027 | X12: 127.0.0.1:6090 | Y12: 127.0.0.1:6090 | Z12: 127.0.0.1:6008 | AA12: 127.0.0.1:6055 | AB12: 127.0.0.1:6055 | AC12: 127.0.0.1:6054 | AD12: 127.0.0.1:6116 | AE12: 127.0.0.1:6049 | AF12: 127.0.0.1:6045 | AG12: 127.0.0.1:6045 | AH12: 127.0.0.1:6125 | AI12: 127.0.0.1:6060 | AJ12: 127.0.0.1:6034 | AK12: 127.0.0.1:6041 | AL12: 127.0.0.1:6074 | AM12: 127.0.0.1:6031 | AN12: 127.0.0.1:6122 | AO12: 127.0.0.1:6122 | AP12: 127.0.0.1:6071 | AQ12: 127.0.0.1:6061 | AR12: 127.0.0.1:6018 | AS12: 127.0.0.1:6078 | AT12: 127.0.0.1:6037 | AU12: 127.0.0.1:6111 | AV12: 127.0.0.1:6047 | AW12: 127.0.0.1:6011 | AX12: 127.0.0.1:6048 | AY12: 127.0.0.1:6027 | AZ12: 127.0.0.1:6064 | BA12: 127.0.0.1:6069 | BB12: 127.0.0.1:6069 | BC12: 127.0.0.1:6070 | BD12: 127.0.0.1:6049 | BE12: 127.0.0.1:6104 | BF12: 127.0.0.1:6060 | BG12: 127.0.0.1:6060 | BH12: 127.0.0.1:6102 | BI12: 127.0.0.1:6034 | BJ12: 127.0.0.1:6076 | BK12: 127.0.0.1:6018 | BL12: 127.0.0.1:6018 | BM12: 127.0.0.1:6037 | BN12: 127.0.0.1:6037 | BO12: 127.0.0.1:6047 | BP12: 127.0.0.1:6022 | BQ12: 127.0.0.1:6009 | BR12: 127.0.0.1:6001 | BS12: 127.0.0.1:6115 | BT12: 127.0.0.1:6019 | BU12: 127.0.0.1:6074 | BV12: 127.0.0.1:6074 | BW12: 127.0.0.1:6035 | BX12: 127.0.0.1:6010 | BY12: 127.0.0.1:6027 | BZ12: 127.0.0.1:6049 | CA12: 127.0.0.1:6081 | CB12: 127.0.0.1:6057 | CC12: 127.0.0.1:6007 | CD12: 127.0.0.1:6017 | CE12: 127.0.0.1:6022 | CF12: 127.0.0.1:6116 | CG12: 127.0.0.1:6116 | CH12: 127.0.0.1:6110 | CI12: 127.0.0.1:6110 | CJ12: 127.0.0.1:6014 | CK12: 127.0.0.1:6091 | CL12: 127.0.0.1:6091 | CM12: 127.0.0.1:6073 | CN12: 127.0.0.1:6100 | CO12: 127.0.0.1:6043 | CP12: 127.0.0.1:6043 | CQ12: 127.0.0.1:6045 | CR12: 127.0.0.1:6104 | CS12: 127.0.0.1:6102 | CT12: 127.0.0.1:6102 | CU12: 127.0.0.1:6081 | CV12: 127.0.0.1:6001 | CW12: 127.0.0.1:6066 | CX12: 127.0.0.1:6030 | CY12: 127.0.0.1:6098 | CZ12: 127.0.0.1:6113 | DA12: 127.0.0.1:6019 | DB12: 127.0.0.1:6076 | DC12: 127.0.0.1:6037 | DD12: 127.0.0.1:6020 | DE12: 127.0.0.1:6091 | DF12: 127.0.0.1:6043 | DG12: 127.0.0.1:6125 | DH12: 127.0.0.1:6081 | DI12: 127.0.0.1:6115 | DJ12: 127.0.0.1:6127 | DK12: 127.0.0.1:6029 | DL12: 127.0.0.1:6076 | DM12: 127.0.0.1:6020 | DN12: 127.0.0.1:6042 | DO12: 127.0.0.1:6095 | DP12: 127.0.0.1:6048 | DQ12: 127.0.0.1:6064 | DR12: 127.0.0.1:6070 | DS12: 127.0.0.1:6038 | DT12: 127.0.0.1:6045 | DU12: 127.0.0.1:6063 | DV12: 127.0.0.1:6063 | DW12: 127.0.0.1:6060 | DX12: 127.0.0.1:6081 | DY12: 127.0.0.1:6081 | DZ12: 127.0.0.1:6085 | EA12: 127.0.0.1:6003 | EB12: 127.0.0.1:6007 | EC12: 127.0.0.1:6047 | ED12: 127.0.0.1:6009 | EE12: 127.0.0.1:6112 | EF12: 127.0.0.1:6101 | EG12: 127.0.0.1:6095 | EH12: 127.0.0.1:6095 | EI12: 127.0.0.1:6032 | EJ12: 127.0.0.1:6074 | EK12: 127.0.0.1:6076 | EL12: 127.0.0.1:6044 | EM12: 127.0.0.1:6101 | EN12: 127.0.0.1:6101 | EO12: 127.0.0.1:6048 | EP12: 127.0.0.1:6104 | EQ12: 127.0.0.1:6081 | ER12: 127.0.0.1:6003 | ES12: 127.0.0.1:6040 | ET12: 127.0.0.1:6011 | EU12: 127.0.0.1:6027 | EV12: 127.0.0.1:6081 | EW12: 127.0.0.1:6092 | EX12: 127.0.0.1:6004 | EY12: 127.0.0.1:6004 | EZ12: 127.0.0.1:6093 | FA12: 127.0.0.1:6054 | FB12: 127.0.0.1:6094 | FC12: 127.0.0.1:6034 | FD12: 127.0.0.1:6044 | FE12: 127.0.0.1:6109 | FF12: 127.0.0.1:6026 | FG12: 127.0.0.1:6070 | FH12: 127.0.0.1:6045 | FI12: 127.0.0.1:6081 | FJ12: 127.0.0.1:6057 | FK12: 127.0.0.1:6006 | FL12: 127.0.0.1:6020 | FM12: 127.0.0.1:6020 | FN12: 127.0.0.1:6065 | FO12: 127.0.0.1:6065 | FP12: 127.0.0.1:6077 | FQ12: 127.0.0.1:6118 | FR12: 127.0.0.1:6044 | FS12: 127.0.0.1:6085 | FT12: 127.0.0.1:6092 | FU12: 127.0.0.1:6042 | FV12: 127.0.0.1:6021 | FW12: 127.0.0.1:6120 | FX12: 127.0.0.1:6120 | FY12: 127.0.0.1:6106 | FZ12: 127.0.0.1:6102 | GA12: 127.0.0.1:6085 | GB12: 127.0.0.1:6108 | GC12: 127.0.0.1:6122 | GD12: 127.0.0.1:6057 | GE12: 127.0.0.1:6001 | GF12: 127.0.0.1:6001 | GG12: 127.0.0.1:6013 | GH12: 127.0.0.1:6103 | GI12: 127.0.0.1:6011 | GJ12: 127.0.0.1:6049 | GK12: 127.0.0.1:6092 | GL12: 127.0.0.1:6095 | GM12: 127.0.0.1:6083 | GN12: 127.0.0.1:6083 | GO12: 127.0.0.1:6039 | GP12: 127.0.0.1:6035 | GQ12: 127.0.0.1:6071 | GR12: 127.0.0.1:6076 | GS12: 127.0.0.1:6109 | GT12: 127.0.0.1:6070 | GU12: 127.0.0.1:6081 | GV12: 127.0.0.1:6001 | GW12: 127.0.0.1:6098 | GX12: 127.0.0.1:6040 | GY12: 127.0.0.1:6040 | GZ12: 127.0.0.1:6005 | HA12: 127.0.0.1:6019 | HB12: 127.0.0.1:6051 | HC12: 127.0.0.1:6020 | HD12: 127.0.0.1:6077 | HE12: 127.0.0.1:6120 | HF12: 127.0.0.1:6044 | HG12: 127.0.0.1:6001 | HH12: 127.0.0.1:6040 | HI12: 127.0.0.1:6053 | HJ12: 127.0.0.1:6019 | HK12: 127.0.0.1:6011 | HL12: 127.0.0.1:6092 | HM12: 127.0.0.1:6127 | HN12: 127.0.0.1:6074 | HO12: 127.0.0.1:6037 | HP12: 127.0.0.1:6106 | HQ12: 127.0.0.1:6001 | HR12: 127.0.0.1:6086 | HS12: 127.0.0.1:6101 | HT12: 127.0.0.1:6036 | HU12: 127.0.0.1:6000 | HV12: 127.0.0.1:6061 | HW12: 127.0.0.1:6023 | HX12: 127.0.0.1:6008 | HY12: 127.0.0.1:6008 | HZ12: 127.0.0.1:6056 | IA12: 127.0.0.1:6114 | IB12: 127.0.0.1:6038 | IC12: 127.0.0.1:6104 | ID12: 127.0.0.1:6003 | IE12: 127.0.0.1:6019 | IF12: 127.0.0.1:6092 | IG12: 127.0.0.1:6092 | IH12: 127.0.0.1:6080 | II12: 127.0.0.1:6080 | IJ12: 127.0.0.1:6024 | IK12: 127.0.0.1:6024 | IL12: 127.0.0.1:6108 | IM12: 127.0.0.1:6071 | IN12: 127.0.0.1:6071 | IO12: 127.0.0.1:6057 | IP12: 127.0.0.1:6061 | IQ12: 127.0.0.1:6061 | IR12: 127.0.0.1:6055 | IS12: 127.0.0.1:6017 | IT12: 127.0.0.1:6017 | IU12: 127.0.0.1:6067 | IV12: 127.0.0.1:6051 | IW12: 127.0.0.1:6120 | IX12: 127.0.0.1:6011 | IY12: 127.0.0.1:6075 | IZ12: 127.0.0.1:6086 | JA12: 127.0.0.1:6086 | JB12: 127.0.0.1:6095 | JC12: 127.0.0.1:6039 | JD12: 127.0.0.1:6036 | JE12: 127.0.0.1:6109 | JF12: 127.0.0.1:6091 | JG12: 127.0.0.1:6045 | JH12: 127.0.0.1:6085 | JI12: 127.0.0.1:6078 | JJ12: 127.0.0.1:6078 | JK12: 127.0.0.1:6025 | JL12: 127.0.0.1:6037 | JM12: 127.0.0.1:6011 | JN12: 127.0.0.1:6011 | JO12: 127.0.0.1:6097 | JP12: 127.0.0.1:6048 | JQ12: 127.0.0.1:6122 | JR12: 127.0.0.1:6007 | JS12: 127.0.0.1:6007 | JT12: 127.0.0.1:6009 | JU12: 127.0.0.1:6110 | JV12: 127.0.0.1:6100 | JW12: 127.0.0.1:6100 | JX12: 127.0.0.1:6072 | JY12: 127.0.0.1:6072 | JZ12: 127.0.0.1:6021 | KA12: 127.0.0.1:6125 | KB12: 127.0.0.1:6015 | KC12: 127.0.0.1:6092 | KD12: 127.0.0.1:6024 | KE12: 127.0.0.1:6031 | KF12: 127.0.0.1:6071 | KG12: 127.0.0.1:6004 | KH12: 127.0.0.1:6078 | KI12: 127.0.0.1:6111 | KJ12: 127.0.0.1:6111 | KK12: 127.0.0.1:6007 | KL12: 127.0.0.1:6042 | KM12: 127.0.0.1:6120 | KN12: 127.0.0.1:6036 | KO12: 127.0.0.1:6069 | KP12: 127.0.0.1:6022 | KQ12: 127.0.0.1:6022 | KR12: 127.0.0.1:6049 | KS12: 127.0.0.1:6006 | KT12: 127.0.0.1:6006 | KU12: 127.0.0.1:6042 | KV12: 127.0.0.1:6042 | KW12: 127.0.0.1:6089 | KX12: 127.0.0.1:6120 | KY12: 127.0.0.1:6104 | KZ12: 127.0.0.1:6071 | LA12: 127.0.0.1:6025 | LB12: 127.0.0.1:6025 | LC12: 127.0.0.1:6111 | LD12: 127.0.0.1:6009 | LE12: 127.0.0.1:6020 | LF12: 127.0.0.1:6082 | LG12: 127.0.0.1:6106 | LH12: 127.0.0.1:6106 | LI12: 127.0.0.1:6050 | LJ12: 127.0.0.1:6050 | LK12: 127.0.0.1:6087 | LL12: 127.0.0.1:6087 | LM12: 127.0.0.1:6044 | LN12: 127.0.0.1:6044 | LO12: 127.0.0.1:6066 | LP12: 127.0.0.1:6011 | LQ12: 127.0.0.1:6101 | LR12: 127.0.0.1:6000 | LS12: 127.0.0.1:6000 | LT12: 127.0.0.1:6027 | LU12: 127.0.0.1:6057 | LV12: 127.0.0.1:6059 | LW12: # FOUND
A13: =IF(COUNTIF(E13:ALS13, "*FOUND*") > 0, "", "F") | B13: =IF(COUNTA(F13:AO13)>0, COUNTA(F13:AO13), "") -> 36 | C13: Node(128) | D13: 10 | E13: 127.0.0.1:6000 - 127.0.0.1:6018 | F13: 127.0.0.1:6000 | G13: 127.0.0.1:6109 | H13: 127.0.0.1:6085 | I13: 127.0.0.1:6012 | J13: 127.0.0.1:6012 | K13: 127.0.0.1:6098 | L13: 127.0.0.1:6112 | M13: 127.0.0.1:6112 | N13: 127.0.0.1:6086 | O13: 127.0.0.1:6083 | P13: 127.0.0.1:6052 | Q13: 127.0.0.1:6052 | R13: 127.0.0.1:6061 | S13: 127.0.0.1:6017 | T13: 127.0.0.1:6116 | U13: 127.0.0.1:6100 | V13: 127.0.0.1:6021 | W13: 127.0.0.1:6021 | X13: 127.0.0.1:6094 | Y13: 127.0.0.1:6124 | Z13: 127.0.0.1:6044 | AA13: 127.0.0.1:6079 | AB13: 127.0.0.1:6107 | AC13: 127.0.0.1:6125 | AD13: 127.0.0.1:6031 | AE13: 127.0.0.1:6025 | AF13: 127.0.0.1:6007 | AG13: 127.0.0.1:6084 | AH13: 127.0.0.1:6106 | AI13: 127.0.0.1:6087 | AJ13: 127.0.0.1:6079 | AK13: 127.0.0.1:6085 | AL13: 127.0.0.1:6119 | AM13: 127.0.0.1:6003 | AN13: 127.0.0.1:6003 | AO13: 127.0.0.1:6092 | AP13: 127.0.0.1:6108 | AQ13: 127.0.0.1:6078 | AR13: 127.0.0.1:6007 | AS13: 127.0.0.1:6040 | AT13: 127.0.0.1:6028 | AU13: 127.0.0.1:6019 | AV13: 127.0.0.1:6019 | AW13: 127.0.0.1:6126 | AX13: 127.0.0.1:6092 | AY13: 127.0.0.1:6122 | AZ13: 127.0.0.1:6105 | BA13: 127.0.0.1:6040 | BB13: 127.0.0.1:6075 | BC13: 127.0.0.1:6083 | BD13: 127.0.0.1:6061 | BE13: 127.0.0.1:6100 | BF13: 127.0.0.1:6016 | BG13: 127.0.0.1:6106 | BH13: 127.0.0.1:6044 | BI13: 127.0.0.1:6030 | BJ13: 127.0.0.1:6030 | BK13: 127.0.0.1:6011 | BL13: 127.0.0.1:6048 | BM13: 127.0.0.1:6083 | BN13: 127.0.0.1:6017 | BO13: 127.0.0.1:6110 | BP13: 127.0.0.1:6072 | BQ13: 127.0.0.1:6094 | BR13: 127.0.0.1:6119 | BS13: 127.0.0.1:6119 | BT13: 127.0.0.1:6096 | BU13: 127.0.0.1:6037 | BV13: 127.0.0.1:6114 | BW13: 127.0.0.1:6063 | BX13: 127.0.0.1:6102 | BY13: 127.0.0.1:6092 | BZ13: 127.0.0.1:6071 | CA13: 127.0.0.1:6009 | CB13: 127.0.0.1:6009 | CC13: 127.0.0.1:6006 | CD13: 127.0.0.1:6089 | CE13: 127.0.0.1:6089 | CF13: 127.0.0.1:6105 | CG13: 127.0.0.1:6052 | CH13: 127.0.0.1:6054 | CI13: 127.0.0.1:6119 | CJ13: 127.0.0.1:6019 | CK13: 127.0.0.1:6041 | CL13: 127.0.0.1:6035 | CM13: 127.0.0.1:6035 | CN13: 127.0.0.1:6076 | CO13: 127.0.0.1:6076 | CP13: 127.0.0.1:6059 | CQ13: 127.0.0.1:6004 | CR13: 127.0.0.1:6007 | CS13: 127.0.0.1:6017 | CT13: 127.0.0.1:6072 | CU13: 127.0.0.1:6034 | CV13: 127.0.0.1:6081 | CW13: 127.0.0.1:6115 | CX13: 127.0.0.1:6079 | CY13: 127.0.0.1:6013 | CZ13: 127.0.0.1:6113 | DA13: 127.0.0.1:6011 | DB13: 127.0.0.1:6027 | DC13: 127.0.0.1:6061 | DD13: 127.0.0.1:6115 | DE13: 127.0.0.1:6085 | DF13: 127.0.0.1:6085 | DG13: 127.0.0.1:6015 | DH13: 127.0.0.1:6122 | DI13: 127.0.0.1:6052 | DJ13: 127.0.0.1:6017 | DK13: 127.0.0.1:6034 | DL13: 127.0.0.1:6034 | DM13: 127.0.0.1:6124 | DN13: 127.0.0.1:6081 | DO13: 127.0.0.1:6081 | DP13: 127.0.0.1:6085 | DQ13: 127.0.0.1:6003 | DR13: 127.0.0.1:6071 | DS13: 127.0.0.1:6001 | DT13: 127.0.0.1:6061 | DU13: 127.0.0.1:6018 | DV13: # FOUND
A14: =IF(COUNTIF(E14:ALS14, "*FOUND*") > 0, "", "F") | B14: =IF(COUNTA(F14:AO14)>0, COUNTA(F14:AO14), "") -> 35 | C14: Node(128) | D14: 11 | E14: 127.0.0.1:6000 - 127.0.0.1:6037 | F14: 127.0.0.1:6000 | G14: 127.0.0.1:6107 | H14: 127.0.0.1:6015 | I14: 127.0.0.1:6025 | J14: 127.0.0.1:6105 | K14: 127.0.0.1:6034 | L14: 127.0.0.1:6115 | M14: 127.0.0.1:6115 | N14: 127.0.0.1:6119 | O14: 127.0.0.1:6035 | P14: 127.0.0.1:6059 | Q14: 127.0.0.1:6018 | R14: 127.0.0.1:6120 | S14: 127.0.0.1:6105 | T14: 127.0.0.1:6106 | U14: 127.0.0.1:6068 | V14: 127.0.0.1:6030 | W14: 127.0.0.1:6048 | X14: 127.0.0.1:6048 | Y14: 127.0.0.1:6036 | Z14: 127.0.0.1:6063 | AA14: 127.0.0.1:6081 | AB14: 127.0.0.1:6003 | AC14: 127.0.0.1:6007 | AD14: 127.0.0.1:6047 | AE14: 127.0.0.1:6047 | AF14: 127.0.0.1:6051 | AG14: 127.0.0.1:6044 | AH14: 127.0.0.1:6011 | AI14: 127.0.0.1:6049 | AJ14: 127.0.0.1:6110 | AK14: 127.0.0.1:6034 | AL14: 127.0.0.1:6119 | AM14: 127.0.0.1:6037 | AN14: # FOUND
A15: =IF(COUNTIF(E15:ALS15, "*FOUND*") > 0, "", "F") | B15: =IF(COUNTA(F15:AO15)>0, COUNTA(F15:AO15), "") -> 19 | C15: Node(128) | D15: 12 | E15: 127.0.0.1:6000 - 127.0.0.1:6047 | F15: 127.0.0.1:6000 | G15: 127.0.0.1:6022 | H15: 127.0.0.1:6038 | I15: 127.0.0.1:6060 | J15: 127.0.0.1:6085 | K15: 127.0.0.1:6092 | L15: 127.0.0.1:6004 | M15: 127.0.0.1:6009 | N15: 127.0.0.1:6042 | O15: 127.0.0.1:6105 | P15: 127.0.0.1:6105 | Q15: 127.0.0.1:6084 | R15: 127.0.0.1:6084 | S15: 127.0.0.1:6121 | T15: 127.0.0.1:6034 | U15: 127.0.0.1:6041 | V15: 127.0.0.1:6059 | W15: 127.0.0.1:6047 | X15: # FOUND
A16: =IF(COUNTIF(E16:ALS16, "*FOUND*") > 0, "", "F") | B16: =IF(COUNTA(F16:AO16)>0, COUNTA(F16:AO16), "") -> 36 | C16: Node(128) | D16: 13 | E16: 127.0.0.1:6000 - 127.0.0.1:6051 | F16: 127.0.0.1:6000 | G16: 127.0.0.1:6081 | H16: 127.0.0.1:6092 | I16: 127.0.0.1:6042 | J16: 127.0.0.1:6001 | K16: 127.0.0.1:6115 | L16: 127.0.0.1:6019 | M16: 127.0.0.1:6076 | N16: 127.0.0.1:6037 | O16: 127.0.0.1:6047 | P16: 127.0.0.1:6118 | Q16: 127.0.0.1:6030 | R16: 127.0.0.1:6026 | S16: 127.0.0.1:6049 | T16: 127.0.0.1:6049 | U16: 127.0.0.1:6038 | V16: 127.0.0.1:6085 | W16: 127.0.0.1:6108 | X16: 127.0.0.1:6089 | Y16: 127.0.0.1:6084 | Z16: 127.0.0.1:6001 | AA16: 127.0.0.1:6066 | AB16: 127.0.0.1:6101 | AC16: 127.0.0.1:6107 | AD16: 127.0.0.1:6078 | AE16: 127.0.0.1:6089 | AF16: 127.0.0.1:6001 | AG16: 127.0.0.1:6001 | AH16: 127.0.0.1:6013 | AI16: 127.0.0.1:6088 | AJ16: 127.0.0.1:6126 | AK16: 127.0.0.1:6126 | AL16: 127.0.0.1:6041 | AM16: 127.0.0.1:6020 | AN16: 127.0.0.1:6118 | AO16: 127.0.0.1:6101 | AP16: 127.0.0.1:6045 | AQ16: 127.0.0.1:6108 | AR16: 127.0.0.1:6095 | AS16: 127.0.0.1:6052 | AT16: 127.0.0.1:6034 | AU16: 127.0.0.1:6076 | AV16: 127.0.0.1:6020 | AW16: 127.0.0.1:6120 | AX16: 127.0.0.1:6120 | AY16: 127.0.0.1:6106 | AZ16: 127.0.0.1:6011 | BA16: 127.0.0.1:6092 | BB16: 127.0.0.1:6095 | BC16: 127.0.0.1:6061 | BD16: 127.0.0.1:6023 | BE16: 127.0.0.1:6056 | BF16: 127.0.0.1:6070 | BG16: 127.0.0.1:6092 | BH16: 127.0.0.1:6127 | BI16: 127.0.0.1:6076 | BJ16: 127.0.0.1:6044 | BK16: 127.0.0.1:6101 | BL16: 127.0.0.1:6108 | BM16: 127.0.0.1:6074 | BN16: 127.0.0.1:6048 | BO16: 127.0.0.1:6010 | BP16: 127.0.0.1:6090 | BQ16: 127.0.0.1:6056 | BR16: 127.0.0.1:6043 | BS16: 127.0.0.1:6104 | BT16: 127.0.0.1:6105 | BU16: 127.0.0.1:6001 | BV16: 127.0.0.1:6098 | BW16: 127.0.0.1:6083 | BX16: 127.0.0.1:6094 | BY16: 127.0.0.1:6035 | BZ16: 127.0.0.1:6106 | CA16: 127.0.0.1:6099 | CB16: 127.0.0.1:6109 | CC16: 127.0.0.1:6004 | CD16: 127.0.0.1:6042 | CE16: 127.0.0.1:6012 | CF16: 127.0.0.1:6103 | CG16: 127.0.0.1:6103 | CH16: 127.0.0.1:6113 | CI16: 127.0.0.1:6113 | CJ16: 127.0.0.1:6040 | CK16: 127.0.0.1:6112 | CL16: 127.0.0.1:6095 | CM16: 127.0.0.1:6054 | CN16: 127.0.0.1:6026 | CO16: 127.0.0.1:6104 | CP16: 127.0.0.1:6034 | CQ16: 127.0.0.1:6044 | CR16: 127.0.0.1:6109 | CS16: 127.0.0.1:6061 | CT16: 127.0.0.1:6061 | CU16: 127.0.0.1:6055 | CV16: 127.0.0.1:6115 | CW16: 127.0.0.1:6127 | CX16: 127.0.0.1:6018 | CY16: 127.0.0.1:6107 | CZ16: 127.0.0.1:6054 | DA16: 127.0.0.1:6054 | DB16: 127.0.0.1:6017 | DC16: 127.0.0.1:6047 | DD16: 127.0.0.1:6044 | DE16: 127.0.0.1:6085 | DF16: 127.0.0.1:6078 | DG16: 127.0.0.1:6098 | DH16: 127.0.0.1:6017 | DI16: 127.0.0.1:6022 | DJ16: 127.0.0.1:6125 | DK16: 127.0.0.1:6089 | DL16: 127.0.0.1:6103 | DM16: 127.0.0.1:6040 | DN16: 127.0.0.1:6095 | DO16: 127.0.0.1:6094 | DP16: 127.0.0.1:6120 | DQ16: 127.0.0.1:6044 | DR16: 127.0.0.1:6001 | DS16: 127.0.0.1:6040 | DT16: 127.0.0.1:6052 | DU16: 127.0.0.1:6076 | DV16: 127.0.0.1:6109 | DW16: 127.0.0.1:6109 | DX16: 127.0.0.1:6023 | DY16: 127.0.0.1:6107 | DZ16: 127.0.0.1:6107 | EA16: 127.0.0.1:6026 | EB16: 127.0.0.1:6015 | EC16: 127.0.0.1:6103 | ED16: 127.0.0.1:6028 | EE16: 127.0.0.1:6011 | EF16: 127.0.0.1:6075 | EG16: 127.0.0.1:6061 | EH16: 127.0.0.1:6054 | EI16: 127.0.0.1:6116 | EJ16: 127.0.0.1:6094 | EK16: 127.0.0.1:6104 | EL16: 127.0.0.1:6104 | EM16: 127.0.0.1:6063 | EN16: 127.0.0.1:6085 | EO16: 127.0.0.1:6012 | EP16: 127.0.0.1:6113 | EQ16: 127.0.0.1:6005 | ER16: 127.0.0.1:6011 | ES16: 127.0.0.1:6011 | ET16: 127.0.0.1:6097 | EU16: 127.0.0.1:6027 | EV16: 127.0.0.1:6027 | EW16: 127.0.0.1:6109 | EX16: 127.0.0.1:6056 | EY16: 127.0.0.1:6085 | EZ16: 127.0.0.1:6119 | FA16: 127.0.0.1:6011 | FB16: 127.0.0.1:6101 | FC16: 127.0.0.1:6095 | FD16: 127.0.0.1:6074 | FE16: 127.0.0.1:6031 | FF16: 127.0.0.1:6089 | FG16: 127.0.0.1:6039 | FH16: 127.0.0.1:6039 | FI16: 127.0.0.1:6062 | FJ16: 127.0.0.1:6035 | FK16: 127.0.0.1:6010 | FL16: 127.0.0.1:6070 | FM16: 127.0.0.1:6009 | FN16: 127.0.0.1:6105 | FO16: 127.0.0.1:6040 | FP16: 127.0.0.1:6017 | FQ16: 127.0.0.1:6017 | FR16: 127.0.0.1:6067 | FS16: 127.0.0.1:6067 | FT16: 127.0.0.1:6116 | FU16: 127.0.0.1:6034 | FV16: 127.0.0.1:6081 | FW16: 127.0.0.1:6057 | FX16: 127.0.0.1:6057 | FY16: 127.0.0.1:6004 | FZ16: 127.0.0.1:6013 | GA16: 127.0.0.1:6095 | GB16: 127.0.0.1:6048 | GC16: 127.0.0.1:6027 | GD16: 127.0.0.1:6090 | GE16: 127.0.0.1:6107 | GF16: 127.0.0.1:6064 | GG16: 127.0.0.1:6049 | GH16: 127.0.0.1:6045 | GI16: 127.0.0.1:6042 | GJ16: 127.0.0.1:6095 | GK16: 127.0.0.1:6095 | GL16: 127.0.0.1:6032 | GM16: 127.0.0.1:6048 | GN16: 127.0.0.1:6064 | GO16: 127.0.0.1:6104 | GP16: 127.0.0.1:6060 | GQ16: 127.0.0.1:6092 | GR16: 127.0.0.1:6092 | GS16: 127.0.0.1:6080 | GT16: 127.0.0.1:6108 | GU16: 127.0.0.1:6108 | GV16: 127.0.0.1:6031 | GW16: 127.0.0.1:6083 | GX16: 127.0.0.1:6035 | GY16: 127.0.0.1:6071 | GZ16: 127.0.0.1:6061 | HA16: 127.0.0.1:6017 | HB16: 127.0.0.1:6116 | HC16: 127.0.0.1:6126 | HD16: 127.0.0.1:6127 | HE16: 127.0.0.1:6120 | HF16: 127.0.0.1:6011 | HG16: 127.0.0.1:6048 | HH16: 127.0.0.1:6104 | HI16: 127.0.0.1:6102 | HJ16: 127.0.0.1:6071 | HK16: 127.0.0.1:6076 | HL16: 127.0.0.1:6057 | HM16: 127.0.0.1:6078 | HN16: 127.0.0.1:6017 | HO16: 127.0.0.1:6110 | HP16: 127.0.0.1:6115 | HQ16: 127.0.0.1:6018 | HR16: 127.0.0.1:6078 | HS16: 127.0.0.1:6037 | HT16: 127.0.0.1:6020 | HU16: 127.0.0.1:6106 | HV16: 127.0.0.1:6102 | HW16: 127.0.0.1:6001 | HX16: 127.0.0.1:6086 | HY16: 127.0.0.1:6052 | HZ16: 127.0.0.1:6099 | IA16: 127.0.0.1:6107 | IB16: 127.0.0.1:6114 | IC16: 127.0.0.1:6003 | ID16: 127.0.0.1:6040 | IE16: 127.0.0.1:6019 | IF16: 127.0.0.1:6051 | IG16: # FOUND
